Workbook

Sheet 안내
A1: BCMS 프로세스 연결 품질 — 문항은행 V3 (객체층·관계층·품질층)
A2: 박사논문 프로젝트 · 근거: Arias-Aranda et al.(2026) / Białas(2010) + 외부 학술 문헌 후보 12건(서지만 확인)
A4: V3 핵심 변경 | B4: V2의 "반영·확인·갱신"을 폐기하고, 첨부 문서(연구자 제시)의 3층 모형을 따랐다. 객체층(프로세스 22개) → 관계층(관계동사 11개) → 품질층(정합성·추적성·증빙성·책임성·최신성·환류폐쇄성 6개 차원). 문항은 "객체쌍 + 관계동사 + 품질조건" 구조다.
A5: 표기 규칙 | B5: 파란 열 = 논문 인용(Arias·Białas는 PDF 원문과 자동 대조 완료) · 빨간 열 = 연구자 의견(해석·보완·가정·문항화). 외부 학술 문헌은 서지만 확인했으며 원문 문장은 확인하지 못했다(학술근거 시트).
A6: 품질 차원의 근거 강도 | B6: 두 논문 안에서의 근거(T1): 환류폐쇄성 강 · 정합성·증빙성·책임성·최신성 중 · 추적성 없음. 외부 문헌(T2)은 모든 차원에 후보가 있으나 원문 확인이 필요하다. 상세는 품질차원 시트.
A7: 증거유형 | B7: 연결의 증거유형: E1 직접 26개 / E2 일부 보완 2개 / E3 가정 3개. 품질 차원의 근거 등급(T1/T2/T3)과는 별개다.
A8: 시트 구성 | B8: 정의서 · 품질차원 · 학술근거 · 인용근거 · 연결 · 적용매트릭스 · 관계동사 · 보류연결 · 객체 · 트리플 · 관계매트릭스 · 온톨로지맵 · 문항 · 보유·응답자정보 · 응답입력 · 연결점수 · 차원점수 · 점수요약 · 검증
A9: 사용 순서 | B9: ① 품질차원·학술근거 시트에서 근거 확인(학술근거 시트 노란 칸에 원문 확인 결과 기입) → ② 연결 시트에서 연구자 의견 검토 → ③ 문항 시트에서 전문가 6인 적합도(1~4) 입력 → ④ 응답입력 7행부터 설문 응답 입력 → ⑤ 연결점수·차원점수·점수요약·검증 확인
A10: 입력 칸 | B10: 노란 바탕 + 파란 글씨 = 직접 입력. 응답입력 6행은 예시이며 집계에서 제외(집계는 7~56행).
A11: 응답 척도 | B11: 1 전혀 그렇지 않다 · 2 그렇지 않다 · 3 보통이다 · 4 그렇다 · 5 매우 그렇다 · 9 해당 없음/모르겠음(결측 처리)
A12: 문항 수 | B12: 연결 문항 163개(연결 31개 × 정합성·추적성·증빙성·책임성·최신성 5개 + 환류 연결 8개 × 환류폐쇄성 1개) + 종합 7 + 검증 9 = 179문항. 응답자 1인이 모두 답하기는 어려우므로 영역별 분할 배포를 권장한다.
A13: 중요한 한계 | B13: 연결 31개는 전문가 검증 전 가설이다. 6개 차원과 "연결 품질" 용어는 연구자가 제시한 초기 가설이며 두 논문에 없다. 외부 문헌의 원문 문장은 이 환경에서 열람할 수 없어 확인하지 못했다.
A14: 검증 기록 | B14: Arias·Białas 인용문 72/72, 객체 22/22가 PDF 원문과 일치(검증일 2026-10-09). 외부 문헌 12건은 서지만 확인(원문 대조 0건).

Sheet 정의서
A1: 정의서 — 용어별 정의, 유형(인용 정의 / 연구자 정의), 근거 인용
A2: 유형이 "연구자 정의"인 항목은 두 논문에 없는 연구자의 판단이며, 박사논문에서 연구자가 직접 확정해야 하는 부분
A4: ID | B4: 용어 | C4: 유형 | D4: 정의 | E4: 근거 인용 ID | F4: 근거 인용 원문(첫 번째) | G4: 근거·한계 설명
A5: D01 | B5: 프로세스(객체) | C5: 인용 정의 + 연구자 범위 설정 | D5: 입력을 출력으로 전환하는, 상호 관련되거나 상호작용하는 활동의 응집된 집합. 본 연구의 객체는 Arias Table 5의 22개 BCMS 프로세스이며, BCMS 계획은 프로젝트로 분류되어 제외한다. | E5: A42 / A01 / A48 | F5: =IFERROR(INDEX(인용근거!$E$5:$E$76,MATCH(LEFT(E5,3),인용근거!$A$5:$A$76,0)),"") -> In essence, a process represents a cohesive set of interrelated or interacting activities to transform inputs into outputs | G5: 객체 22개 선정 = Arias Table 5(인용). BCMS 계획을 제외한 것도 Arias의 분류(A48)를 따른 것.
A6: D02 | B6: 산출물(artefact) | C6: 인용 개념 + 연구자 정의 | D6: [연구자 정의] 프로세스가 만들어 다른 프로세스가 사용하는 문서·기록·보고·결정. Białas는 slot이 채워진 개체가 핵심 BCM 산출물(주로 문서)을 나타낸다고 쓴다. | E6: B07 | F6: =IFERROR(INDEX(인용근거!$E$5:$E$76,MATCH(LEFT(E6,3),인용근거!$A$5:$A$76,0)),"") -> The individuals with filled-in slots represent the key BCM artefacts, mostly documents, of the BCMO related knowledge base. | G6: 용어는 Białas에서 차용, 정의 문장은 연구자가 작성.
A7: D03 | B7: 연결(link) | C7: 연구자 정의 | D7: 프로세스 S의 산출물·결과·자원이 프로세스 T의 입력·기준·실행·개정에 쓰이도록 Arias가 서술한 방향성 있는 프로세스 쌍(S→T) 1개. 한 연결은 하나의 출발(S)과 하나의 도착(T)을 가진다(집단 노드 CORE 제외). 연결의 의미는 관계동사로 표현한다. | E7: A02 / A03 / A04 / B04 / B05 | F7: =IFERROR(INDEX(인용근거!$E$5:$E$76,MATCH(LEFT(E7,3),인용근거!$A$5:$A$76,0)),"") -> A process reference model should delineate the interconnections among the processes outlined within it. | G7: 연결이라는 단위의 정의는 연구자 정의. 입력·출력·상호작용·상호 연결이 중요하다는 점은 인용.
A8: D04 | B8: 연결 품질(linkage quality) | C8: 연구자 정의(구성개념) | D8: 한 연결(S→T)이 조직의 실제 운영에서 얼마나 잘 작동하는가. 정합성·추적성·증빙성·책임성·최신성·환류폐쇄성 6개 차원으로 측정한다. 환류폐쇄성은 환류 연결 8개에만 적용한다. 연결의 점수는 적용되는 차원 문항의 평균이다. | E8: A01 / A02 / A04 / B01 / A07 / A05 | F8: =IFERROR(INDEX(인용근거!$E$5:$E$76,MATCH(LEFT(E8,3),인용근거!$A$5:$A$76,0)),"") -> Activities utilizing resources must be managed to convert inputs into outputs through a series of interconnected or interacting activities, also called processes | G8: 용어와 6개 차원 구성은 연구자가 제시한 초기 가설(첨부 문서)이며 두 논문에 없다. 프로세스 간 상호 연결·상호작용이 BCMS의 핵심이라는 점(A01, A02, A04, B01, A07)과 체크리스트만으로는 지속 운영이 보장되지 않는다는 점(A05)을 정의의 이유로 인용했다.
A9: D05 | B9: 연계성(조직 수준) | C9: 연구자 정의 | D9: 조직의 연결 31개의 품질을 종합한 지수(연결 점수의 평균). 첨부 문서가 "연결성"이라 부른 개념과 같은 것으로 보며, 용어("연계성"/"연결성") 통일은 연구자가 정한다. | E9: (없음) | F9: (해당 인용 없음) | G9: 용어 선택은 연구자 결정 사항.
A10: D06 | B10: 3층 모형(객체층·관계층·품질층) | C10: 연구자 설계(첨부 문서) | D10: 객체층 = 무엇과 무엇을 연결하는가(프로세스 22개와 그 산출물). 관계층 = 어떤 방식으로 연결되는가(관계동사 11개). 품질층 = 그 연결이 얼마나 잘 작동하는가(6개 차원). 문항은 "객체쌍 + 관계동사 + 품질조건" 구조로 쓴다. | E10: B04 / B05 / B06 | F10: =IFERROR(INDEX(인용근거!$E$5:$E$76,MATCH(LEFT(E10,3),인용근거!$A$5:$A$76,0)),"") -> i.e. relationships between an individual member of the given class (the object) and other individuals | G10: 3층 구분은 첨부 문서의 제안이다. Białas가 object slot(관계)과 data slot(속성)을 구분한 방식이 구조적 근거다.
A11: D07 | B11: 관계동사 | C11: 연구자 정의 | D11: 연결의 의미를 나타내는 동사(입력된다·근거가 된다·도출·이행된다·시험·검증된다·수행을 촉발한다·개정·갱신한다·환류된다·포함한다·제공한다·승인한다·전달된다). Arias의 서술문에서 동사를 추출했다. 첨부 문서의 동사 중 "일치한다·추적된다·기록·증빙된다"는 품질층 차원(정합성·추적성·증빙성)과 겹쳐 품질층으로 옮겼다. | E11: A11 / A12 / A14 / A16 / A23 / A25 / A29 / A30 | F11: =IFERROR(INDEX(인용근거!$E$5:$E$76,MATCH(LEFT(E11,3),인용근거!$A$5:$A$76,0)),"") -> These requirements inform processes such as business impact assessment and criticality analysis, risk assessment, internal audits, and supply chain management. | G11: 동사 분류와 이름은 연구자 정의. 원문 동사는 관계동사 시트에 영문 표현으로 병기.
A12: D08 | B12: 정합성 | C12: 연구자 정의 (첨부 문서) | D12: 선행 산출물과 후행 의사결정이 모순 없이 일치하는 정도. | E12: A33 / A14 / A16 / A12 | F12: =IFERROR(INDEX(인용근거!$E$5:$E$76,MATCH(LEFT(E12,3),인용근거!$A$5:$A$76,0)),"") -> The business continuity governance process, in particular, ensures that the BCMS matches the goals and requirements of the stakeholders responsible for oversight. | G12: 두 논문에 "일관성"을 직접 다룬 문장은 없고 "부합·근거·도출" 서술이 간접 근거. 외부 후보: S03, S05, S06 (원문 미확인).
A13: D09 | B13: 추적성 | C13: 연구자 정의 (첨부 문서) | D13: 후행 결과에서 선행 근거를 역추적할 수 있는 정도. | E13: (없음) | F13: (해당 인용 없음) | G13: 두 논문에 직접 근거 없음(원문 검색 확인). 외부 후보: S01, S02 (원문 미확인).
A14: D10 | B14: 증빙성 | C14: 연구자 정의 (첨부 문서) | D14: 연결을 입증하는 문서·기록·승인이 존재하는 정도. | E14: B17 / A41 / A13 / A37 | F14: =IFERROR(INDEX(인용근거!$E$5:$E$76,MATCH(LEFT(E14,3),인용근거!$A$5:$A$76,0)),"") -> results and records (used as evidences during BCMS certification) | G14: Białas가 기록을 "증거"로 쓴다고 서술(B17). 외부 후보: S11, S12 (표준, 원문 미확인).
A15: D11 | B15: 책임성 | C15: 연구자 정의 (첨부 문서) | D15: 연결의 검토·승인·변경 책임이 명확한 정도. | E15: A49 / A50 / A10 | F15: =IFERROR(INDEX(인용근거!$E$5:$E$76,MATCH(LEFT(E15,3),인용근거!$A$5:$A$76,0)),"") -> This means that the business continuity manager is accountable for the whole process. | G15: Arias의 책임은 프로세스 단위. 연결 단위 책임은 연구자의 확장. 외부 후보: S07.
A16: D12 | B16: 최신성 | C16: 연구자 정의 (첨부 문서) | D16: 변경된 정보가 관련 프로세스와 문서에 적시에 반영되는 정도. | E16: A41 / A51 / A52 / A53 / A28 / A27 | F16: =IFERROR(INDEX(인용근거!$E$5:$E$76,MATCH(LEFT(E16,3),인용근거!$A$5:$A$76,0)),"") -> The process of controlling documented information involves identifying, creating, updating, and controlling information essential for the effectiveness of the BCMS. | G16: "적시"라는 표현은 논문에 없음. 외부 후보: S03, S04, S05 (원문 미확인).
A17: D13 | B17: 환류폐쇄성 | C17: 연구자 정의 (첨부 문서) | D17: 훈련·평가·사고 결과가 개선과 재수정까지 완료되는 정도. 환류 연결 8개(L16, L18, L19, L20, L23, L24, L25, L26)에만 적용. | E17: A23 / A25 / A46 / A29 / A53 / A54 / B18 | F17: =IFERROR(INDEX(인용근거!$E$5:$E$76,MATCH(LEFT(E17,3),인용근거!$A$5:$A$76,0)),"") -> The process of exercising BC plans and procedures ensures that BC strategies and solutions and their corresponding BC plans and procedures, including warning and communication procedures, are tested regularly to validate their effectiveness and prompt any necessary adjustments or enhancements. | G17: 환류 연결의 선정 기준(훈련·평가·사고·변경 결과가 되돌아가는 연결)은 연구자 분류. 외부 후보: S08.
A18: D14 | B18: 증거유형 E1/E2/E3 | C18: 연구자 정의 | D18: E1=원문이 S→T 연결을 직접 서술(인용만으로 연결의 존재와 방향이 성립). E2=원문이 연결을 서술하나 출발 또는 도착을 연구자가 특정·보완. E3=원문에 연결 서술이 없고 연구자 가정 또는 Białas 유추에 의존. 각 연결에 인용문과 연구자 의견을 분리해 기록한다. | E18: (없음) | F18: (해당 인용 없음) | G18: 연결의 증거유형. 품질 차원의 근거 등급(T1/T2/T3)과 다르다.
A19: D15 | B19: 품질 차원 근거 등급 T1/T2/T3 | C19: 연구자 정의 | D19: T1=Arias·Białas 원문에서 문장 단위로 검증한 인용. T2=외부 학술 문헌(서지만 확인, 원문 문장은 연구자가 확인해야 함). T3=연구자 정의. | E19: (없음) | F19: (해당 인용 없음) | G19: 외부 문헌은 이 세션에서 열람하지 못했다.
A20: D16 | B20: 연결 영역 ①~⑤ | C20: 연구자 분류 | D20: 연결의 도착 프로세스가 수행하는 업무 흐름에 따라 묶은 분류(① 요구·분석, ② 전략·계획·이행, ③ 대응·복구·훈련, ④ 평가·개선·변경, ⑤ 거버넌스·이해관계자). | E20: (없음) | F20: (해당 인용 없음) | G20: Arias의 PDCA 열(Table 5)과는 별개. PDCA는 객체 시트에 별도 표기.
A21: D17 | B21: 집단 노드 CORE | C21: 연구자 정의 | D21: Arias가 "nearly all BCMS processes"처럼 프로세스를 열거하지 않고 가리킨 집단을 하나의 가상 노드로 표현한 것. 객체 22개에 포함되지 않는다. | E21: A30 / A18 | F21: =IFERROR(INDEX(인용근거!$E$5:$E$76,MATCH(LEFT(E21,3),인용근거!$A$5:$A$76,0)),"") -> The outcomes of nearly all BCMS processes are communicated centrally to stakeholders external to the BCMS as part of the consultation and communication process. | G21: 노드 자체는 연구자가 만든 것.
A22: D18 | B22: competency question | C22: 인용 정의 + 연구자 적용 | D22: 온톨로지 관련 지식베이스가 답할 수 있는 온톨로지 영역의 질문. 그 답이 온톨로지의 범위를 정의한다. 본 연구에서는 연결마다 품질 차원별 문항(5~6개)이 이 질문에 답한다. | E22: B02 / B03 | F22: =IFERROR(INDEX(인용근거!$E$5:$E$76,MATCH(LEFT(E22,3),인용근거!$A$5:$A$76,0)),"") -> The ontology domain questions that the ontology related knowledge base is able to answer are called competency questions | G22: 정의는 Białas 인용, 문항으로의 적용은 연구자 설계.
A23: D19 | B23: ProcessLink 객체화 | C23: 연구자 설계 | D23: 연결 자체를 하나의 개체로 보고 6개 품질 점수를 그 개체의 속성(data slot)으로 두는 설계. Białas가 object slot을 관계로, data slot을 속성으로 구분한 방식을 응용했다. | E23: B04 / B06 | F23: =IFERROR(INDEX(인용근거!$E$5:$E$76,MATCH(LEFT(E23,3),인용근거!$A$5:$A$76,0)),"") -> i.e. relationships between an individual member of the given class (the object) and other individuals | G23: Białas는 이런 객체화를 하지 않았다.
A24: D20 | B24: 형성적 지수 | C24: 연구자 설계 | D24: 연결 품질을 6개 차원의 조합으로 보는 구성. 각 차원은 문항 여러 개(반영적 지표)로 재고, 차원들을 합쳐 연결 품질을 만든다. 초기 가중치는 동일하게 두고 예비조사 후 조정한다. | E24: (없음) | F24: (해당 인용 없음) | G24: 방법 근거 후보: S09, S10 (서지만 확인, 원문 미확인).
A25: D21 | B25: 응답 9(해당 없음/모르겠음) | C25: 연구자 정의 | D25: 프로세스가 없거나 응답자가 알 수 없어 응답할 수 없는 경우. 점수 계산에서 결측으로 처리하며 "연결이 약함"과 구분한다. | E25: (없음) | F25: (해당 인용 없음)
A26: D22 | B26: 합의 판정(80%·20%) | C26: 인용 + 연구자 적용 | D26: 범주 1(80% 이상 채택), 범주 2(20~80% 토론), 범주 3(20% 미만 기각)의 3단계 판정. 본 연구는 전문가 맹검 재분류 일치율과 연결 타당도 판정에 같은 틀을 준용한다. | E26: A43 / A44 / A45 | F26: =IFERROR(INDEX(인용근거!$E$5:$E$76,MATCH(LEFT(E26,3),인용근거!$A$5:$A$76,0)),"") -> According to [32,33], the 80% threshold for consensus is commonly used and generally perceived as fair. | G26: Arias는 프로세스의 핵심 여부에 적용했고, 문항·연결에 적용하는 것은 연구자의 준용.
A27: D23 | B27: I-CVI 기준(0.78) | C27: 연구자 선택(관례) | D27: 전문가 6~10인 패널에서 적합도 3~4점 비율이 0.78 이상이면 채택하는 관례 기준. | E27: (없음) | F27: (해당 인용 없음) | G27: 두 논문에 근거 없음. 일반적 관례를 연구자가 선택.
A28: D24 | B28: Białas 차용 범위 | C28: 연구자 정의 | D28: 차용=방법(competency question, object slot의 domain/range, data slot, 개체=산출물, 검증 방식). 비차용=클래스 목록·관계 이름(BS 25999 기반). Białas는 BCMO가 프로토타입이며 실제 데이터 검증이 더 필요하다고 밝힌다. | E28: B15 / B14 / B02 / B04 / B05 / B06 / B08 | F28: =IFERROR(INDEX(인용근거!$E$5:$E$76,MATCH(LEFT(E28,3),인용근거!$A$5:$A$76,0)),"") -> compliant with the BS 25999 standard

Sheet 품질차원
A1: 품질층 6개 차원 — 정의와 근거 (T1 두 논문 원문 / T2 외부 문헌 후보 / T3 연구자 정의)
A2: 첨부 문서(연구자 제시)의 6차원을 초기 가설로 사용. 근거 강도는 두 논문 안에서의 직접성을 뜻한다.
A4: 순서 | B4: 코드 | C4: 차원 | D4: 영문 | E4: 첨부 문서의 정의 (연구자 제시) | F4: 본 연구의 조작적 정의 (연구자) | G4: 문항 틀 | H4: 적용 연결 수 | I4: T1 인용 ID (원문 대조 완료) | J4: T1 대표 인용 원문 | K4: T1 근거 강도 | L4: T1 근거 설명 | M4: T2 외부 문헌 후보 ID | N4: T2 외부 문헌 설명 | O4: 다른 차원과의 겹침 (연구자 우려)
A5: 1 | B5: CO | C5: 정합성 | D5: Consistency | E5: 선행 산출물과 후행 의사결정이 모순 없이 일치하는가 | F5: 연결된 두 프로세스의 산출물과 결정(S의 산출물과 T의 내용)이 서로 모순 없이 일치하는 정도 | G5: (연결 문장: S의 산출물이 T에 … 될 때), 두 내용이 서로 모순 없이 일치한다. | H5: =SUM(적용매트릭스!B5:B35) -> 31 | I5: A33 / A14 / A16 / A12 | J5: =IFERROR(INDEX(인용근거!$E$5:$E$76,MATCH("A33",인용근거!$A$5:$A$76,0)),"두 논문에 직접 근거 없음") -> The business continuity governance process, in particular, ensures that the BCMS matches the goals and requirements of the stakeholders responsible for oversight. | K5: 중 | L5: 두 논문에는 "일관성/모순"이라는 말을 직접 쓴 문장이 없다. 후행 결정이 선행 산출물에 "부합(matches)·근거(foundation)·도출(derived)"되어야 한다는 서술이 근거다(A33, A12, A14, A16). | M5: S03 / S05 / S06 / S04 | N5: 데이터 품질·요구사항 일관성 문헌에서 일관성은 확립된 개념이다. 다만 원문 정의 문장은 이 세션에서 확인하지 못했다. | O5: 증빙성·추적성과 함께 "기록·근거"를 다루므로 요인분석에서 구분되는지 확인 필요
A6: 2 | B6: TR | C6: 추적성 | D6: Traceability | E6: 후행 결과에서 선행 근거를 역추적할 수 있는가 | F6: 후행 결과(T의 내용)에서 근거가 된 선행 산출물(S의 산출물)을 거슬러 찾아 확인할 수 있는 정도 | G6: (T의 내용)에서 근거가 된 (S의 산출물)을 거슬러 찾아 확인할 수 있다. | H6: =SUM(적용매트릭스!C5:C35) -> 31 | I6: (없음) (약한 간접: A13, B11) | J6: =IFERROR(INDEX(인용근거!$E$5:$E$76,MATCH("A13",인용근거!$A$5:$A$76,0)),"두 논문에 직접 근거 없음") -> The final result is a documented statement accompanied by a rationale outlining the organization's business continuity requirements. | K6: 없음 | L6: 두 논문에는 추적(traceability)을 직접 다룬 문장이 없다(원문 검색으로 확인). 약한 간접 근거로 BIA 결과가 "근거가 첨부된 문서화된 진술"이라는 서술(A13)과, 지식베이스에서 BIA 보고서를 관련 사안으로 질의·검색하는 Białas의 예(B11)가 있을 뿐이다. | M6: S01 / S02 | N6: 요구사항 추적성은 소프트웨어공학에서 잘 정립된 개념이다. 이 차원의 학술 근거는 두 논문이 아니라 외부 문헌에 의존한다. | O6: 증빙성(기록 존재)이 있어야 추적성이 가능하므로 두 차원의 상관이 높을 수 있음
A7: 3 | B7: EV | C7: 증빙성 | D7: Evidence | E7: 연결을 입증하는 문서·기록·승인이 존재하는가 | F7: 연결이 실제로 이루어졌음을 입증하는 문서·기록·승인(검토 기록, 회의록, 버전 이력 등)이 남아 있는 정도 | G7: (연결 문장), 그 사실을 입증하는 문서·기록·승인(검토 기록, 회의록, 버전 이력 등)이 남아 있다. | H7: =SUM(적용매트릭스!D5:D35) -> 31 | I7: B17 / A41 / A13 / A37 | J7: =IFERROR(INDEX(인용근거!$E$5:$E$76,MATCH("B17",인용근거!$A$5:$A$76,0)),"두 논문에 직접 근거 없음") -> results and records (used as evidences during BCMS certification) | K7: 중 | L7: Białas는 훈련의 결과와 기록이 BCMS 인증 때 "증거(evidences)"로 쓰인다고 쓴다(B17). Arias는 BIA 결과를 근거가 첨부된 문서화된 진술로, 경영진 승인을 확보하는 절차로 서술한다(A13, A37). 다만 "연결의 증빙"을 직접 말한 문장은 아니다. | M7: S11 / S12 | N7: 감사 증거(audit evidence)는 경영시스템 표준의 확립된 개념이다. 단 표준 원문은 이 세션에서 확인하지 못했고 정의 문장은 2차 사이트가 인용한 것만 보았다. | O7: 추적성·정합성과의 구분 확인 필요
A8: 4 | B8: AC | C8: 책임성 | D8: Accountability | E8: 연결의 검토·승인·변경 책임이 명확한가 | F8: 연결의 검토·승인·변경에 대한 책임자(또는 부서)가 정해져 있는 정도 | G8: (연결 문장), 그 연결의 검토·승인·변경에 대한 책임자(또는 부서)가 정해져 있다. | H8: =SUM(적용매트릭스!E5:E35) -> 31 | I8: A49 / A50 / A10 | J8: =IFERROR(INDEX(인용근거!$E$5:$E$76,MATCH("A49",인용근거!$A$5:$A$76,0)),"두 논문에 직접 근거 없음") -> This means that the business continuity manager is accountable for the whole process. | K8: 중 | L8: Arias는 BC 관리자가 프로세스 전체에 책임(accountable)을 지고 설계에 책임(responsible)을 진다고 쓴다(A49, A50, A10). 단 책임의 대상은 "프로세스"이지 "프로세스 간 연결"이 아니다. 연결 단위의 책임은 연구자의 확장이다. | M8: S07 / S12 | N8: 책임성 개념은 행정·거버넌스 문헌에서 정립되어 있다(S07). 연결 단위로 적용하는 것은 연구자의 확장이다. | O8: 다른 5개 차원과 개념적으로 가장 독립적일 것으로 예상(연구자 가정)
A9: 5 | B9: TM | C9: 최신성 | D9: Timeliness | E9: 변경된 정보가 관련 프로세스와 문서에 적시에 반영되는가 | F9: 선행 산출물이 바뀌었을 때 관련 프로세스와 문서에 정해진 기간 안에 반영되는 정도 | G9: (S의 산출물)이 바뀌면, (T의 내용)에 정해진 기간 안에 반영된다. | H9: =SUM(적용매트릭스!F5:F35) -> 31 | I9: A41 / A51 / A52 / A53 / A28 / A27 | J9: =IFERROR(INDEX(인용근거!$E$5:$E$76,MATCH("A41",인용근거!$A$5:$A$76,0)),"두 논문에 직접 근거 없음") -> The process of controlling documented information involves identifying, creating, updating, and controlling information essential for the effectiveness of the BCMS. | K9: 중 | L9: Arias는 문서화된 정보 통제가 정보의 갱신(updating)을 포함하고(A41), 승인·범위 정의 같은 산출물이 적합성에 대한 정기적 점검을 필요로 하며(A51), 승인 갱신이 거버넌스에 통합되어 있고(A52), 변경관리가 문서 변경과 리스크평가 재개를 산출한다고(A28, A27) 서술한다. "적시(timely)"라는 말은 쓰지 않았다. | M9: S03 / S04 / S05 | N9: 데이터 품질 문헌의 최신성·적시성(timeliness/currency)이 근거 후보다. 원문 정의는 이 세션에서 확인하지 못했다. | O9: V2의 "갱신" 개념과 가장 가깝다
A10: 6 | B10: FC | C10: 환류폐쇄성 | D10: Closed-loop completion | E10: 훈련·평가·사고 결과가 개선과 재수정까지 완료되는가 | F10: 훈련·평가·사고의 결과가 개선·재수정 조치로 이어지고 완료까지 확인되는 정도 (환류 연결 8개에만 적용) | G10: (결과가 나오는 사건), (개선·재수정 범위)까지 조치가 이어져 완료가 확인된다. — 환류 연결 8개에만 적용 | H10: =SUM(적용매트릭스!G5:G35) -> 8 | I10: A23 / A25 / A46 / A29 / A53 / A54 / B18 | J10: =IFERROR(INDEX(인용근거!$E$5:$E$76,MATCH("A23",인용근거!$A$5:$A$76,0)),"두 논문에 직접 근거 없음") -> The process of exercising BC plans and procedures ensures that BC strategies and solutions and their corresponding BC plans and procedures, including warning and communication procedures, are tested regularly to validate their effectiveness and prompt any necessary adjustments or enhancements. | K10: 강 | L10: 연습은 필요한 조정·개선을 촉구하고(A23), 평가·감사·공급망 결과는 개선에 쓰이며 지속적 개선 프로세스에서 실현되고(A25, A46), 변경의 결과는 변경을 개시한 프로세스로 돌아간다(A29). 점검 결과를 개선으로 잇는 구조는 Białas의 PDCA slot에도 있다(B18). "완료까지 확인"이라는 표현은 연구자의 것이다. | M10: S08 | N10: 오류를 탐지·수정하는 조직학습(single/double loop)이 이론적 배경 후보다. 원문은 이 세션에서 열람하지 못했다. | O10: 책임성·최신성과 일부 겹칠 수 있음. 환류 연결 8개에만 적용되므로 비교 시 주의

Sheet 학술근거
A1: 외부 학술 근거 후보 12건 — 서지는 확인, 원문 문장은 미확인
A2: 네트워크 정책(egress 차단)으로 원문을 열람하지 못했다. 연구자가 원문에서 정의·문장을 확인해 노란 칸에 쪽 번호와 원문을 기입하면 근거가 확정된다.
A4: ID | B4: 유형 | C4: 서지(APA 형식) | D4: 연도 | E4: 품질 차원 | F4: 요지 (검색 결과 요약 기준, 인용 아님) | G4: 서지 확인 | H4: 원문 확인 상태 | I4: DOI / URL | J4: 원문 쪽 번호 (연구자 기입) | K4: 원문 문장 (연구자 기입) | L4: 확인 완료 (Y/N)
A5: S01 | B5: 학술논문(학회) | C5: Gotel, O. C. Z., & Finkelstein, A. C. W. (1994). An analysis of the requirements traceability problem. In Proc. 1st Int. Conf. on Requirements Engineering (ICRE), pp. 94–101. IEEE Computer Society Press. | D5: 1994 | E5: 추적성 | F5: 요구사항 추적성 문제의 성격을 분석하고 pre-RS/post-RS 추적성으로 구분한다(검색 결과 요약 기준). | G5: 서지 확인됨(웹 검색, 2026-10-09) | H5: 원문 미열람 — 이 세션의 네트워크 정책으로 접근 차단. 인용 문장은 확인되지 않음 | I5: doi:10.1109/ICRE.1994.292398 / https://discovery.ucl.ac.uk/749/
A6: S02 | B6: 학술논문(학회) | C6: Cleland-Huang, J., Gotel, O. C. Z., Huffman Hayes, J., Mäder, P., & Zisman, A. (2014). Software traceability: Trends and future directions. In Proc. Future of Software Engineering (FOSE 2014), pp. 55–69. ACM. | D6: 2014 | E6: 추적성 | F6: 소프트웨어 추적성의 연구 현황과 향후 과제를 개관한다(검색 결과 요약 기준). | G6: 서지 확인됨(웹 검색, 2026-10-09) | H6: 원문 미열람 — 이 세션의 네트워크 정책으로 접근 차단. 인용 문장은 확인되지 않음 | I6: doi:10.1145/2593882.2593891
A7: S03 | B7: 학술논문 | C7: Wang, R. Y., & Strong, D. M. (1996). Beyond accuracy: What data quality means to data consumers. Journal of Management Information Systems, 12(4), 5–33. | D7: 1996 | E7: 정합성, 최신성 | F7: 데이터 소비자 관점의 데이터 품질 차원을 2단계 설문과 분류 연구로 도출한 위계적 틀을 제시한다(검색 결과 요약 기준). 시의성·표현 일관성 등 차원 정의는 원문에서 확인해야 한다. | G7: 서지 확인됨(웹 검색, 2026-10-09) | H7: 원문 미열람 — 이 세션의 네트워크 정책으로 접근 차단. 인용 문장은 확인되지 않음 | I7: http://www.jstor.org/stable/40398176
A8: S04 | B8: 학술논문 | C8: Pipino, L. L., Lee, Y. W., & Wang, R. Y. (2002). Data quality assessment. Communications of the ACM, 45(4), 211–218. | D8: 2002 | E8: 정합성, 최신성 | F8: 데이터 품질 평가(측정)를 다룬다. 초록·본문은 이 세션에서 확인하지 못했다(서지만 확인). | G8: 서지 확인됨(웹 검색, 2026-10-09) | H8: 원문 미열람 — 이 세션의 네트워크 정책으로 접근 차단. 인용 문장은 확인되지 않음 | I8: doi:10.1145/505248.506010
A9: S05 | B9: 학술논문(서베이) | C9: Batini, C., Cappiello, C., Francalanci, C., & Maurino, A. (2009). Methodologies for data quality assessment and improvement. ACM Computing Surveys, 41(3), 1–52. | D9: 2009 | E9: 정합성, 최신성 | F9: 데이터 품질 평가·개선 방법론을 단계·기법·차원별로 비교한다(검색 결과 요약 기준). 일관성·최신성 정의는 2차 문헌이 인용하나 2009 원문 문장은 확인하지 못했다. | G9: 서지 확인됨(웹 검색, 2026-10-09) | H9: 원문 미열람 — 이 세션의 네트워크 정책으로 접근 차단. 인용 문장은 확인되지 않음 | I9: (서지만)
A10: S06 | B10: 학술논문 | C10: Zowghi, D., & Gervasi, V. (2003). On the interplay between consistency, completeness, and correctness in requirements evolution. Information and Software Technology, 45(14), 993–1009. | D10: 2003 | E10: 정합성 | F10: 요구사항 진화에서 일관성·완전성·정확성의 관계와 검증 점검을 다룬다(검색 결과 요약 기준). 2004년 정오표(erratum)가 있다. | G10: 서지 확인됨(웹 검색, 2026-10-09) | H10: 원문 미열람 — 이 세션의 네트워크 정책으로 접근 차단. 인용 문장은 확인되지 않음 | I10: https://opus.cloud1.lib.uts.edu.au/handle/10453/4025
A11: S07 | B11: 학술논문 | C11: Bovens, M. (2007). Analysing and assessing accountability: A conceptual framework. European Law Journal, 13(4), 447–468. | D11: 2007 | E11: 책임성 | F11: 책임성을 행위자와 포럼 사이의 관계(설명 의무, 질문·판단, 결과 부담)로 좁게 개념화하고 분석·평가 틀을 제시한다(검색 결과 요약 기준). | G11: 서지 확인됨(웹 검색, 2026-10-09) | H11: 원문 미열람 — 이 세션의 네트워크 정책으로 접근 차단. 인용 문장은 확인되지 않음 | I11: doi:10.1111/j.1468-0386.2007.00378.x / https://dspace.library.uu.nl/handle/1874/35005
A12: S08 | B12: 학술·실무 논문 | C12: Argyris, C. (1977). Double loop learning in organizations. Harvard Business Review, 55(5), 115–125. | D12: 1977 | E12: 환류폐쇄성 | F12: 조직학습을 오류의 탐지와 수정으로 보고 single-loop와 double-loop를 구분한다(2차 요약 기준; 원문 미열람). | G12: 서지 확인됨(웹 검색, 2026-10-09) | H12: 원문 미열람 — 이 세션의 네트워크 정책으로 접근 차단. 인용 문장은 확인되지 않음 | I12: (서지만)
A13: S09 | B13: 학술논문(방법) | C13: Diamantopoulos, A., & Winklhofer, H. M. (2001). Index construction with formative indicators: An alternative to scale development. Journal of Marketing Research, 38(2), 269–277. | D13: 2001 | E13: 방법(구성·검증) | F13: 형성적 지표로 지수를 구성하는 방법을 다룬다. 연결 품질을 6개 차원의 합으로 구성할 때의 방법 근거 후보(검색 결과 요약 기준). | G13: 서지 확인됨(웹 검색, 2026-10-09) | H13: 원문 미열람 — 이 세션의 네트워크 정책으로 접근 차단. 인용 문장은 확인되지 않음 | I13: doi:10.1509/jmkr.38.2.269.18845
A14: S10 | B14: 학술논문(방법) | C14: MacKenzie, S. B., Podsakoff, P. M., & Podsakoff, N. P. (2011). Construct measurement and validation procedures in MIS and behavioral research: Integrating new and existing techniques. MIS Quarterly, 35(2), 293–334. | D14: 2011 | E14: 방법(구성·검증) | F14: 개념 정의, 측정모형 명시, 타당화 기법을 형성적·반영적 지표 구분과 함께 정리한다(검색 결과 요약 기준). 문항 개발·검증 절차의 근거 후보. | G14: 서지 확인됨(웹 검색, 2026-10-09) | H14: 원문 미열람 — 이 세션의 네트워크 정책으로 접근 차단. 인용 문장은 확인되지 않음 | I14: (서지만)
A15: S11 | B15: 표준 | C15: ISO 19011:2018. Guidelines for auditing management systems. International Organization for Standardization. | D15: 2018 | E15: 증빙성 | F15: "audit evidence"를 감사 기준과 관련되고 검증 가능한 기록·사실 진술·기타 정보로 정의한다고 2차 사이트가 인용한다(표준 원문 미확인). | G15: 서지 확인됨(웹 검색, 2026-10-09) | H15: 원문 미열람 — 이 세션의 네트워크 정책으로 접근 차단. 인용 문장은 확인되지 않음 | I15: (서지만)
A16: S12 | B16: 표준 | C16: ISO 22301:2019. Security and resilience — Business continuity management systems — Requirements. International Organization for Standardization. | D16: 2019 | E16: 증빙성, 책임성 | F16: Arias가 인용한 조항(4.1, 4.2.2, 4.4, 7.4, 8.2–8.4)만 Arias 본문으로 확인했다. 역할·책임, 문서화된 정보, 시정조치·개선 조항의 내용은 표준 원문에서 확인해야 한다. | G16: 서지 확인됨(웹 검색, 2026-10-09) | H16: 원문 미열람 — 이 세션의 네트워크 정책으로 접근 차단. 인용 문장은 확인되지 않음 | I16: (서지만)

Sheet 인용근거
A1: 인용 근거 라이브러리 — Arias·Białas 원문과 자동 대조한 인용문 72개
A2: 쪽 = PDF 쪽 번호(Arias는 저널 쪽 번호와 동일). 한국어 번역은 연구자 번역(참고용)이며 대조 대상이 아님.
A4: 인용ID | B4: 출처 | C4: PDF 쪽 | D4: 절 | E4: 원문(영어, verbatim) | F4: 한국어 번역(연구자 번역·참고) | G4: 사용처 | H4: 원문 대조
A5: A01 | B5: Arias | C5: 4 | D5: §2.1 | E5: Activities utilizing resources must be managed to convert inputs into outputs through a series of interconnected or interacting activities, also called processes | F5: 자원을 사용하는 활동은 입력을 출력으로 전환하는, 상호 연결되거나 상호작용하는 일련의 활동, 즉 프로세스를 통해 관리되어야 한다. | G5: 연계성 정의의 근거(프로세스 = 상호 연결·상호작용 활동) | H5: 일치 (2026-10-09)
A6: A02 | B6: Arias | C6: 5 | D6: §2.1 (ISO/IEC 33004 기준 4) | E6: A process reference model should delineate the interconnections among the processes outlined within it. | F6: 프로세스 참조모델은 그 안에 기술된 프로세스들 사이의 상호 연결을 명시해야 한다. | G6: 연계성 정의의 근거(프로세스 간 상호 연결 명시 요구) | H6: 일치 (2026-10-09)
A7: A03 | B7: Arias | C7: 3 | D7: §1 | E7: A detailed reference model outlining BCMS processes—including inputs, outputs, interfaces, and interactions at the activity level—facilitates optimal coordination of these processes. | F7: BCMS 프로세스를 활동 수준의 입력·출력·인터페이스·상호작용까지 상세히 기술한 참조모델은 이들 프로세스의 최적 조정을 촉진한다. | G7: 연계성 정의의 근거(입력·출력·인터페이스) | H7: 일치 (2026-10-09)
A8: A04 | B8: Arias | C8: 6 | D8: §2.2 (ISO 22301 Clause 4.4) | E8: taking into account their order, interactions, inputs, outputs, resources, and assigned roles | F8: (BCMS 프로세스를 정의·이행·유지할 때) 프로세스의 순서, 상호작용, 입력, 출력, 자원, 부여된 역할을 고려한다. | G8: 연계성 정의의 근거(ISO 22301 4.4) | H8: 일치 (2026-10-09)
A9: A05 | B9: Arias | C9: 2 | D9: §1 | E9: Organizations often struggle with performing a checklist approach regarding the BCMS requirements because it does not necessarily lead to a sustainable operated management system. | F9: 조직은 BCMS 요구사항에 대해 체크리스트 방식을 수행하는 데 종종 어려움을 겪는데, 이는 지속 가능하게 운영되는 경영시스템으로 반드시 이어지지 않기 때문이다. | G9: 연결 유지 정도를 측정하는 이유(체크리스트의 한계) | H9: 일치 (2026-10-09)
A10: A06 | B10: Arias | C10: 3-4 | D10: §1 | E10: including process descriptions (process profiles) and process flow charts, though the latter are omitted here to maintain the scope of the paper | F10: (참조모델 결과물에는) 프로세스 설명(프로세스 프로파일)과 프로세스 흐름도가 포함되나, 후자는 논문 범위 유지를 위해 여기서는 생략한다. | G10: 연결 목록이 이 논문에서 완전하지 않을 수 있는 근거 | H10: 일치 (2026-10-09)
A11: A07 | B11: Arias | C11: 18 | D11: §5 | E11: A key finding of this pilot initiative is the reinforcement of the systemic nature of the BCMS, emphasizing the interplay between processes and the roles within the BCMS framework. | F11: 이 시범사업의 핵심 발견은 BCMS의 체계적 성격이 강화되었다는 점이며, BCMS 틀 안에서 프로세스와 역할 간의 상호작용이 강조된다. | G11: 연계성이 BCMS 운영의 핵심 특성이라는 근거 | H11: 일치 (2026-10-09)
A12: A08 | B12: Arias | C12: 17 | D12: §5 | E12: An unmodified application of the BCMS process reference model is inadequate; customization of BCMS processes according to the organization's specific needs is imperative. | F12: BCMS 프로세스 참조모델을 수정 없이 적용하는 것은 부적절하며, 조직의 요구에 맞춘 BCMS 프로세스의 맞춤화가 필수적이다. | G12: 연결 목록의 조직별 조정 필요성 | H12: 일치 (2026-10-09)
A13: A09 | B13: Arias | C13: 10 | D13: Figure 4 | E13: Regularity – interrelated and interacting tasks are repeated on a regular basis. | F13: 규칙성 – 상호 관련되고 상호작용하는 과업이 정기적으로 반복된다. | G13: 종합 문항 G06 근거 | H13: 일치 (2026-10-09)
A14: A10 | B14: Arias | C14: 10 | D14: Figure 4 | E14: Accountability/responsibility – business continuity manager is the process owner or process manager and the process is a core competency of the BCMS. | F14: 책임성 – 업무연속성 관리자가 프로세스 소유자 또는 관리자이며 해당 프로세스는 BCMS의 핵심 역량이다. | G14: 종합 문항 G04 근거 | H14: 일치 (2026-10-09)
A15: A11 | B15: Arias | C15: 15 | D15: §4.3 | E15: These requirements inform processes such as business impact assessment and criticality analysis, risk assessment, internal audits, and supply chain management. | F15: 이 요구사항들은 BIA·중요도 분석, 리스크평가, 내부감사, 공급망관리와 같은 프로세스에 정보를 제공한다. | G15: L01, L02, L04, L05 | H15: 일치 (2026-10-09)
... A76: B18 | B76: Białas | C76: 4 | D76: §2.8 (Fig.1 설명) | E76: the monitorReview_C slot filled with BCMS_3Check_4 individual, and the maintImprove_A slot filled with BCMS_4Act_1 individual | F76: monitorReview_C slot은 BCMS_3Check_4 개체로, maintImprove_A slot은 BCMS_4Act_1 개체로 채워진다. | G76: 환류폐쇄성 차원(점검→개선 구조) | H76: 일치 (2026-10-09)

Sheet 연결
A1: 연결 31개 — 인용 근거(파랑)와 연구자 의견(빨강)을 분리 · 연결근거 매트릭스
A2: E1 직접 / E2 부분(연구자 보완) / E3 가정. 주 인용 원문은 인용근거 시트에서 자동으로 가져옴.
A4: ID | B4: 영역 | C4: 연결(S→T) | D4: 출발 S | E4: 도착 T | F4: 관계동사 ID | G4: 관계동사 | H4: 증거유형 | I4: 집단 | J4: 환류 연결 | K4: 주 인용 ID | L4: 주 인용 원문(PDF 대조 완료) | M4: 보조 인용 ID | N4: 인용이 확립하는 사실 | O4: 연구자 의견: 해석·보완·가정 | P4: 연구자 의견: 품질 차원 적용 | Q4: Białas 대응 | R4: 검증 필요 사항 | S4: 문항 수 | T4: 기대 문항 수 | U4: 점검
A5: L01 | B5: ① 요구·분석 | C5: REQ 요구사항관리 → BIA BIA·중요도 분석 | D5: REQ | E5: BIA | F5: V01 | G5: =IFERROR(INDEX(관계동사!$B$5:$B$15,MATCH(F5,관계동사!$A$5:$A$15,0)),"") -> 입력된다·활용된다 | H5: E1 | K5: A11 | L5: =IFERROR(INDEX(인용근거!$E$5:$E$76,MATCH(LEFT(K5,3),인용근거!$A$5:$A$76,0)),"원문에 S→T 연결 서술 없음") -> These requirements inform processes such as business impact assessment and criticality analysis, risk assessment, internal audits, and supply chain management. | M5: (없음) | N5: 요구사항관리가 식별한 법규·규제·계약 요구사항이 BIA·중요도 분석 프로세스에 "정보를 제공(inform)"한다. | O5: "inform"을 "S의 산출물이 T의 입력·기준이 된다(informs)"로 해석. A11은 4개 프로세스를 한 문장으로 열거하므로 L01·L02·L04·L05는 이 문장에서 연구자가 분리한 연결. | P5: 5개 차원 적용(환류폐쇄성은 환류 연결에만 적용) | Q5: 해당 없음 | R5: 전문가 패널 연결 타당도 평가(요구사항이 BIA에 실제로 입력되는가) | S5: =COUNTIF(문항!$D$5:$D$183,A5) -> 5 | T5: =SUM(적용매트릭스!B5:G5) -> 5 | U5: =IF(S5=T5,"OK","확인") -> OK
A6: L02 | B6: ① 요구·분석 | C6: REQ 요구사항관리 → RA 리스크평가 | D6: REQ | E6: RA | F6: V01 | G6: =IFERROR(INDEX(관계동사!$B$5:$B$15,MATCH(F6,관계동사!$A$5:$A$15,0)),"") -> 입력된다·활용된다 | H6: E1 | K6: A11 | L6: =IFERROR(INDEX(인용근거!$E$5:$E$76,MATCH(LEFT(K6,3),인용근거!$A$5:$A$76,0)),"원문에 S→T 연결 서술 없음") -> These requirements inform processes such as business impact assessment and criticality analysis, risk assessment, internal audits, and supply chain management. | M6: (없음) | N6: 요구사항관리의 결과가 리스크평가 프로세스에 정보를 제공한다. | O6: 인용문 분리 사유는 L01과 동일. | P6: 5개 차원 적용(환류폐쇄성은 환류 연결에만 적용) | Q6: 해당 없음 | R6: 전문가 패널 연결 타당도 평가 | S6: =COUNTIF(문항!$D$5:$D$183,A6) -> 5 | T6: =SUM(적용매트릭스!B6:G6) -> 5 | U6: =IF(S6=T6,"OK","확인") -> OK
A7: L03 | B7: ① 요구·분석 | C7: BIA BIA·중요도 분석 → RA 리스크평가 | D7: BIA | E7: RA | F7: V02 | G7: =IFERROR(INDEX(관계동사!$B$5:$B$15,MATCH(F7,관계동사!$A$5:$A$15,0)),"") -> 근거가 된다 | H7: E1 | K7: A12 | L7: =IFERROR(INDEX(인용근거!$E$5:$E$76,MATCH(LEFT(K7,3),인용근거!$A$5:$A$76,0)),"원문에 S→T 연결 서술 없음") -> The risk assessment process, which focuses on identifying potential disruptions, relies on the outcomes of the business impact assessment and criticality analysis as its foundation. | M7: A13 | N7: 리스크평가는 BIA·중요도 분석의 결과를 기반(foundation)으로 삼는다. BIA의 최종 결과는 근거가 첨부된 문서화된 진술(업무연속성 요구사항)이다. | O7: "relies on ... as its foundation"을 informs(입력·기준)로 해석. | P7: 5개 차원 적용(환류폐쇄성은 환류 연결에만 적용) | Q7: 해당 없음 | R7: 전문가 패널 연결 타당도 평가 | S7: =COUNTIF(문항!$D$5:$D$183,A7) -> 5 | T7: =SUM(적용매트릭스!B7:G7) -> 5 | U7: =IF(S7=T7,"OK","확인") -> OK
A8: L04 | B8: ① 요구·분석 | C8: REQ 요구사항관리 → AUD 내부감사 | D8: REQ | E8: AUD | F8: V01 | G8: =IFERROR(INDEX(관계동사!$B$5:$B$15,MATCH(F8,관계동사!$A$5:$A$15,0)),"") -> 입력된다·활용된다 | H8: E1 | K8: A11 | L8: =IFERROR(INDEX(인용근거!$E$5:$E$76,MATCH(LEFT(K8,3),인용근거!$A$5:$A$76,0)),"원문에 S→T 연결 서술 없음") -> These requirements inform processes such as business impact assessment and criticality analysis, risk assessment, internal audits, and supply chain management. | M8: (없음) | N8: 요구사항관리의 결과가 내부감사 프로세스에 정보를 제공한다. | O8: 인용문 분리 사유는 L01과 동일. 내부감사 기준에 요구사항이 포함된다는 구체적 형태는 연구자의 지표화. | P8: 5개 차원 적용(환류폐쇄성은 환류 연결에만 적용) | Q8: 해당 없음 | R8: 전문가 패널 연결 타당도 평가 | S8: =COUNTIF(문항!$D$5:$D$183,A8) -> 5 | T8: =SUM(적용매트릭스!B8:G8) -> 5 | U8: =IF(S8=T8,"OK","확인") -> OK
A9: L05 | B9: ① 요구·분석 | C9: REQ 요구사항관리 → SUP 공급망관리 | D9: REQ | E9: SUP | F9: V01 | G9: =IFERROR(INDEX(관계동사!$B$5:$B$15,MATCH(F9,관계동사!$A$5:$A$15,0)),"") -> 입력된다·활용된다 | H9: E1 | K9: A11 | L9: =IFERROR(INDEX(인용근거!$E$5:$E$76,MATCH(LEFT(K9,3),인용근거!$A$5:$A$76,0)),"원문에 S→T 연결 서술 없음") -> These requirements inform processes such as business impact assessment and criticality analysis, risk assessment, internal audits, and supply chain management. | M9: A39 | N9: 요구사항관리의 결과가 공급망관리 프로세스에 정보를 제공한다. 외주 서비스는 업무연속성 관점에서 평가·분석·통제되어야 한다. | O9: 인용문 분리 사유는 L01과 동일. "공급업체 선정·계약 조건에 BC 요구사항 포함"은 A39(외주 서비스 통제)를 바탕으로 한 연구자의 지표화. | P9: 5개 차원 적용(환류폐쇄성은 환류 연결에만 적용) | Q9: 해당 없음 | R9: 전문가 패널 연결 타당도 평가 | S9: =COUNTIF(문항!$D$5:$D$183,A9) -> 5 | T9: =SUM(적용매트릭스!B9:G9) -> 5 | U9: =IF(S9=T9,"OK","확인") -> OK
A10: L06 | B10: ② 전략·계획·이행 | C10: BIA BIA·중요도 분석 → STR BC 전략·솔루션 결정·선정 | D10: BIA | E10: STR | F10: V02 | G10: =IFERROR(INDEX(관계동사!$B$5:$B$15,MATCH(F10,관계동사!$A$5:$A$15,0)),"") -> 근거가 된다 | H10: E1 | K10: A14 | L10: =IFERROR(INDEX(인용근거!$E$5:$E$76,MATCH(LEFT(K10,3),인용근거!$A$5:$A$76,0)),"원문에 S→T 연결 서술 없음") -> After the completion of the business impact assessment and criticality analysis process, the approved business continuity requirements guide the determination and selection of suitable BC strategies and solutions | M10: A13 / A37 | N10: BIA·중요도 분석이 완료된 후, 승인된 업무연속성 요구사항이 BC 전략·솔루션의 결정·선정을 안내(guide)한다. BIA 결과는 경영진 승인을 거친다. | O10: "guide"를 informs(입력·기준)로 해석. | P10: 5개 차원 적용(환류폐쇄성은 환류 연결에만 적용) | Q10: 해당 없음 | R10: 전문가 패널 연결 타당도 평가 | S10: =COUNTIF(문항!$D$5:$D$183,A10) -> 5 | T10: =SUM(적용매트릭스!B10:G10) -> 5 | U10: =IF(S10=T10,"OK","확인") -> OK
A11: L07 | B11: ② 전략·계획·이행 | C11: STR BC 전략·솔루션 결정·선정 → IMP 솔루션 이행관리 | D11: STR | E11: IMP | F11: V03 | G11: =IFERROR(INDEX(관계동사!$B$5:$B$15,MATCH(F11,관계동사!$A$5:$A$15,0)),"") -> 도출·이행된다 | H11: E1 | K11: A15 | L11: =IFERROR(INDEX(인용근거!$E$5:$E$76,MATCH(LEFT(K11,3),인용근거!$A$5:$A$76,0)),"원문에 S→T 연결 서술 없음") -> This process ensures that the BC strategies, solutions, and necessary changes are executed as planned. | M11: A36 | N11: 솔루션 이행관리 프로세스는 BC 전략·솔루션과 필요한 변경이 계획대로 실행되도록 보장하며, 이를 개시하고 검증한다. | O11: 인용문의 주어는 이행관리이고 대상은 전략·솔루션이므로 "STR이 IMP에서 구체화·실행된다"(STR→IMP)로 방향을 해석. A36은 이행관리가 전략·솔루션을 "verifying"한다고 서술하며, 이는 정합성·증빙성 문항에서 "확인하는 행위"를 구체화할 때 참고했다. | P11: 5개 차원 적용(환류폐쇄성은 환류 연결에만 적용) | Q11: 해당 없음 | R11: 전문가 패널 연결 타당도 평가 | S11: =COUNTIF(문항!$D$5:$D$183,A11) -> 5 | T11: =SUM(적용매트릭스!B11:G11) -> 5 | U11: =IF(S11=T11,"OK","확인") -> OK
A12: L08 | B12: ② 전략·계획·이행 | C12: STR BC 전략·솔루션 결정·선정 → PLAN BC 계획·절차 개발 | D12: STR | E12: PLAN | F12: V03 | G12: =IFERROR(INDEX(관계동사!$B$5:$B$15,MATCH(F12,관계동사!$A$5:$A$15,0)),"") -> 도출·이행된다 | H12: E1 | K12: A16 | L12: =IFERROR(INDEX(인용근거!$E$5:$E$76,MATCH(LEFT(K12,3),인용근거!$A$5:$A$76,0)),"원문에 S→T 연결 서술 없음") -> Corresponding BC plans and procedures, derived from the identified BC strategies and solutions, are developed within the process of developing BC plans and procedures. | M12: (없음) | N12: BC 계획·절차는 식별된 BC 전략·솔루션에서 도출(derived)되어 개발된다. | O12: "derived from"을 elaboratedInto(S의 내용이 T로 구체화됨)로 해석. | P12: 5개 차원 적용(환류폐쇄성은 환류 연결에만 적용) | Q12: 해당 없음 | R12: 전문가 패널 연결 타당도 평가 | S12: =COUNTIF(문항!$D$5:$D$183,A12) -> 5 | T12: =SUM(적용매트릭스!B12:G12) -> 5 | U12: =IF(S12=T12,"OK","확인") -> OK
A13: L09 | B13: ② 전략·계획·이행 | C13: RA 리스크평가 → PLAN BC 계획·절차 개발 | D13: RA | E13: PLAN | F13: V01 | G13: =IFERROR(INDEX(관계동사!$B$5:$B$15,MATCH(F13,관계동사!$A$5:$A$15,0)),"") -> 입력된다·활용된다 | H13: E1 | K13: A17 | L13: =IFERROR(INDEX(인용근거!$E$5:$E$76,MATCH(LEFT(K13,3),인용근거!$A$5:$A$76,0)),"원문에 S→T 연결 서술 없음") -> Furthermore, it includes risks associated with proposed changes, providing essential input for both communication activities and the development of business continuity plans and procedures. | M13: (없음) | N13: 리스크평가는 업무연속성 계획·절차 개발에 필수적인 입력(essential input)을 제공한다. | O13: A17의 주어 "it"이 리스크평가 프로세스임은 앞 문장의 주어에서 연구자가 확인한 지시 관계. | P13: 5개 차원 적용(환류폐쇄성은 환류 연결에만 적용) | Q13: 해당 없음 | R13: 전문가 패널 연결 타당도 평가 | S13: =COUNTIF(문항!$D$5:$D$183,A13) -> 5 | T13: =SUM(적용매트릭스!B13:G13) -> 5 | U13: =IF(S13=T13,"OK","확인") -> OK
A14: L10 | B14: ② 전략·계획·이행 | C14: RES 자원관리 → IMP 솔루션 이행관리 | D14: RES | E14: IMP | F14: V09 | G14: =IFERROR(INDEX(관계동사!$B$5:$B$15,MATCH(F14,관계동사!$A$5:$A$15,0)),"") -> 제공한다 | H14: E2 | K14: A18 | L14: =IFERROR(INDEX(인용근거!$E$5:$E$76,MATCH(LEFT(K14,3),인용근거!$A$5:$A$76,0)),"원문에 S→T 연결 서술 없음") -> Outputs from this process include documented resources for implementing and running selected strategies, as well as resources for operating core BCMS processes, along with reports on resource utilization for BCMS core processes and the customer relationship management process | M14: A38 / B16 | N14: 자원관리의 산출물에는 선정된 전략의 이행·운영을 위한 문서화된 자원이 포함된다. 전략 실행에 필요한 자원은 자원관리에서 식별·배정·모니터링된다. | O14: [연구자 보완] 인용문은 "selected strategies의 implementing and running"을 위한 자원이라고만 쓰며 도착 프로세스를 특정하지 않는다. 이를 솔루션 이행관리(IMP)로 특정한 것은 연구자 해석(운영(running)은 IMP 외 프로세스일 수도 있음). | P14: 5개 차원 적용(환류폐쇄성은 환류 연결에만 적용) | Q14: Białas는 supportedByResource slot으로 BCMS를 지원하는 자원 개체를 둔다(B16). 프로세스 간 연결은 아님. | R14: 전문가 패널에서 도착 프로세스(IMP)가 적절한지 평가. 부적절하면 도착을 "핵심 프로세스 전반"으로 변경 | S14: =COUNTIF(문항!$D$5:$D$183,A14) -> 5 | T14: =SUM(적용매트릭스!B14:G14) -> 5 | U14: =IF(S14=T14,"OK","확인") -> OK
A15: L11 | B15: ② 전략·계획·이행 | C15: BIA BIA·중요도 분석 → RES 자원관리 | D15: BIA | E15: RES | F15: V01 | G15: =IFERROR(INDEX(관계동사!$B$5:$B$15,MATCH(F15,관계동사!$A$5:$A$15,0)),"") -> 입력된다·활용된다 | H15: E3 | K15: (없음) | L15: =IFERROR(INDEX(인용근거!$E$5:$E$76,MATCH(LEFT(K15,3),인용근거!$A$5:$A$76,0)),"원문에 S→T 연결 서술 없음") -> 원문에 S→T 연결 서술 없음 | M15: B10 / B11 / A38 | N15: Białas는 BIA 보고서를 "서비스 재개에 필요한 자원"으로 질의하는 예를 보여 준다. Arias는 자원관리가 전략·BCMS 프로세스 실행에 필요한 자원을 식별한다고만 서술한다. | O15: [연구자 가정] BIA가 파악한 복구 필요 자원이 자원관리 계획에 투입된다는 연결은 Arias에 서술이 없다. Białas의 예는 프로세스 간 연결이 아니라 BIA 보고서 내부 속성(자원 항목)을 질의하는 수준이므로 유추 근거에 그친다. | P15: 5개 차원 적용(환류폐쇄성은 환류 연결에만 적용) | Q15: Białas §2.8 Fig.4 설명(B10, B11): BIAreport의 resour4Resumption 속성 | R15: 전문가 합의 필수. 합의 80% 미만이면 삭제(Arias A44 판정 틀 준용) | S15: =COUNTIF(문항!$D$5:$D$183,A15) -> 5 | T15: =SUM(적용매트릭스!B15:G15) -> 5 | U15: =IF(S15=T15,"OK","확인") -> OK
A16: L12 | B16: ③ 대응·복구·훈련 | C16: PLAN BC 계획·절차 개발 → INC 사고·비상 대응 | D16: PLAN | E16: INC | F16: V03 | G16: =IFERROR(INDEX(관계동사!$B$5:$B$15,MATCH(F16,관계동사!$A$5:$A$15,0)),"") -> 도출·이행된다 | H16: E2 | K16: A19 | L16: =IFERROR(INDEX(인용근거!$E$5:$E$76,MATCH(LEFT(K16,3),인용근거!$A$5:$A$76,0)),"원문에 S→T 연결 서술 없음") -> The activation of certain BC strategies and solutions is triggered when required, typically in response to a disruptive event, through the execution of BC plans and procedures. | M16: A20 | N16: BC 전략·솔루션의 가동은 중단 사건에 대응하여 BC 계획·절차의 실행을 통해 개시된다. 경보·커뮤니케이션은 조직의 BC 계획·절차 안에서 대응을 조정한다. | O16: [연구자 보완] 인용문은 "BC 계획·절차가 중단 사건 대응 시 실행된다"고 쓰지만 도착 프로세스를 "사고·비상 대응"으로 명시하지 않는다. 사고·비상 대응이 "중단 사건 관리의 포괄적 접근"을 정의한다는 같은 쪽 서술과 결합해 PLAN→INC로 해석. | P16: 5개 차원 적용(환류폐쇄성은 환류 연결에만 적용) | Q16: 해당 없음 | R16: 전문가 패널 연결 타당도 평가 | S16: =COUNTIF(문항!$D$5:$D$183,A16) -> 5 | T16: =SUM(적용매트릭스!B16:G16) -> 5 | U16: =IF(S16=T16,"OK","확인") -> OK
... A19: L15 | B19: ③ 대응·복구·훈련 | C19: PLAN BC 계획·절차 개발 → EXE BC 계획·절차 훈련·연습 | D19: PLAN | E19: EXE | F19: V04 | G19: =IFERROR(INDEX(관계동사!$B$5:$B$15,MATCH(F19,관계동사!$A$5:$A$15,0)),"") -> 시험·검증된다 | H19: E1 | K19: A23 | L19: =IFERROR(INDEX(인용근거!$E$5:$E$76,MATCH(LEFT(K19,3),인용근거!$A$5:$A$76,0)),"원문에 S→T 연결 서술 없음") -> The process of exercising BC plans and procedures ensures that BC strategies and solutions and their corresponding BC plans and procedures, including warning and communication procedures, are tested regularly to validate their effectiveness and prompt any necessary adjustments or enhancements. | M19: (없음) | N19: BC 전략·솔루션과 BC 계획·절차(경보·커뮤니케이션 절차 포함)는 정기적으로 시험되어 유효성이 검증된다. | O19: "tested regularly to validate their effectiveness"를 testedBy(S가 T에 의해 시험됨)로 해석. 훈련·연습 시나리오 설계 방식은 연구자의 지표화. | P19: 5개 차원 적용(환류폐쇄성은 환류 연결에만 적용) | Q19: 해당 없음 | R19: 전문가 패널 연결 타당도 평가 | S19: =COUNTIF(문항!$D$5:$D$183,A19) -> 5 | T19: =SUM(적용매트릭스!B19:G19) -> 5 | U19: =IF(S19=T19,"OK","확인") -> OK
A20: L16 | B20: ③ 대응·복구·훈련 | C20: EXE BC 계획·절차 훈련·연습 → PLAN BC 계획·절차 개발 | D20: EXE | E20: PLAN | F20: V06 | G20: =IFERROR(INDEX(관계동사!$B$5:$B$15,MATCH(F20,관계동사!$A$5:$A$15,0)),"") -> 개정·갱신한다 | H20: E1 | J20: Y | K20: A23 | L20: =IFERROR(INDEX(인용근거!$E$5:$E$76,MATCH(LEFT(K20,3),인용근거!$A$5:$A$76,0)),"원문에 S→T 연결 서술 없음") -> The process of exercising BC plans and procedures ensures that BC strategies and solutions and their corresponding BC plans and procedures, including warning and communication procedures, are tested regularly to validate their effectiveness and prompt any necessary adjustments or enhancements. | M20: (없음) | N20: 연습은 필요한 조정·개선(adjustments or enhancements)을 촉구(prompt)한다. | O20: 조정 대상은 인용문상 "전략·솔루션·계획·절차" 모두이나 본 연결은 BC 계획·절차로 한정(연구자 한정). 방향 해석(EXE의 결과가 PLAN을 개정)은 연구자 해석. | P20: 환류 연결: 6개 차원 모두 적용(환류폐쇄성 포함) | Q20: 해당 없음 | R20: 전문가 패널 연결 타당도 평가 | S20: =COUNTIF(문항!$D$5:$D$183,A20) -> 6 | T20: =SUM(적용매트릭스!B20:G20) -> 6 | U20: =IF(S20=T20,"OK","확인") -> OK
A21: L17 | B21: ③ 대응·복구·훈련 | C21: PLAN BC 계획·절차 개발 → AWR 인식·역량·교육 | D21: PLAN | E21: AWR | F21: V01 | G21: =IFERROR(INDEX(관계동사!$B$5:$B$15,MATCH(F21,관계동사!$A$5:$A$15,0)),"") -> 입력된다·활용된다 | H21: E3 | K21: (없음) | L21: =IFERROR(INDEX(인용근거!$E$5:$E$76,MATCH(LEFT(K21,3),인용근거!$A$5:$A$76,0)),"원문에 S→T 연결 서술 없음") -> 원문에 S→T 연결 서술 없음 | M21: A24 / B12 | N21: Arias는 인식·훈련·교육 프로그램이 인력의 인식과 역량을 키운다고만 서술하며 계획·절차와의 연결은 서술하지 않는다. Białas는 훈련 활동에 "필요(needs)"를 별도 항목으로 둔다. | O21: [연구자 가정] 교육 내용이 BC 계획·절차(역할 포함)에서 도출·반영된다는 연결은 두 논문에 직접 근거가 없다. 인력이 계획과 자기 역할을 알아야 계획이 실행된다는 연구자 판단에 기초한다. | P21: 5개 차원 적용(환류폐쇄성은 환류 연결에만 적용) | Q21: Białas §2.8 Fig.3 설명(B12): 훈련의 needs, programs, results, records | R21: 전문가 합의 필수. 합의 80% 미만이면 삭제 | S21: =COUNTIF(문항!$D$5:$D$183,A21) -> 5 | T21: =SUM(적용매트릭스!B21:G21) -> 5 | U21: =IF(S21=T21,"OK","확인") -> OK
A22: L18 | B22: ④ 평가·개선·변경 | C22: PERF 성과평가 → CI 지속적 개선 | D22: PERF | E22: CI | F22: V07 | G22: =IFERROR(INDEX(관계동사!$B$5:$B$15,MATCH(F22,관계동사!$A$5:$A$15,0)),"") -> 환류된다 | H22: E1 | J22: Y | K22: A25 | L22: =IFERROR(INDEX(인용근거!$E$5:$E$76,MATCH(LEFT(K22,3),인용근거!$A$5:$A$76,0)),"원문에 S→T 연결 서술 없음") -> Results from the performance evaluation process, the internal audit process, and the supply chain management process are used to improve the effectiveness, efficiency, suitability, and adequacy of the BCMS and the strategies, solutions, plans, and procedures. | M22: A46 | N22: 성과평가의 결과는 BCMS 및 전략·솔루션·계획·절차의 효과성·효율성·적합성·충분성을 개선하는 데 사용되며, 이는 지속적 개선 프로세스에서 실현된다. | O22: A25는 3개 출처를 한 문장에 열거하므로 L18·L19·L20은 연구자가 분리한 연결. | P22: 환류 연결: 6개 차원 모두 적용(환류폐쇄성 포함) | Q22: 해당 없음 | R22: 전문가 패널 연결 타당도 평가 | S22: =COUNTIF(문항!$D$5:$D$183,A22) -> 6 | T22: =SUM(적용매트릭스!B22:G22) -> 6 | U22: =IF(S22=T22,"OK","확인") -> OK
A23: L19 | B23: ④ 평가·개선·변경 | C23: AUD 내부감사 → CI 지속적 개선 | D23: AUD | E23: CI | F23: V07 | G23: =IFERROR(INDEX(관계동사!$B$5:$B$15,MATCH(F23,관계동사!$A$5:$A$15,0)),"") -> 환류된다 | H23: E1 | J23: Y | K23: A25 | L23: =IFERROR(INDEX(인용근거!$E$5:$E$76,MATCH(LEFT(K23,3),인용근거!$A$5:$A$76,0)),"원문에 S→T 연결 서술 없음") -> Results from the performance evaluation process, the internal audit process, and the supply chain management process are used to improve the effectiveness, efficiency, suitability, and adequacy of the BCMS and the strategies, solutions, plans, and procedures. | M23: A46 | N23: 내부감사의 결과는 BCMS 개선에 사용되며, 지속적 개선 프로세스에서 실현된다. | O23: 분리 사유는 L18과 동일. | P23: 환류 연결: 6개 차원 모두 적용(환류폐쇄성 포함) | Q23: 해당 없음 | R23: 전문가 패널 연결 타당도 평가 | S23: =COUNTIF(문항!$D$5:$D$183,A23) -> 6 | T23: =SUM(적용매트릭스!B23:G23) -> 6 | U23: =IF(S23=T23,"OK","확인") -> OK
A24: L20 | B24: ④ 평가·개선·변경 | C24: SUP 공급망관리 → CI 지속적 개선 | D24: SUP | E24: CI | F24: V07 | G24: =IFERROR(INDEX(관계동사!$B$5:$B$15,MATCH(F24,관계동사!$A$5:$A$15,0)),"") -> 환류된다 | H24: E1 | J24: Y | K24: A25 | L24: =IFERROR(INDEX(인용근거!$E$5:$E$76,MATCH(LEFT(K24,3),인용근거!$A$5:$A$76,0)),"원문에 S→T 연결 서술 없음") -> Results from the performance evaluation process, the internal audit process, and the supply chain management process are used to improve the effectiveness, efficiency, suitability, and adequacy of the BCMS and the strategies, solutions, plans, and procedures. | M24: A46 | N24: 공급망관리의 결과는 BCMS 개선에 사용되며, 지속적 개선 프로세스에서 실현된다. | O24: 분리 사유는 L18과 동일. | P24: 환류 연결: 6개 차원 모두 적용(환류폐쇄성 포함) | Q24: 해당 없음 | R24: 전문가 패널 연결 타당도 평가 | S24: =COUNTIF(문항!$D$5:$D$183,A24) -> 6 | T24: =SUM(적용매트릭스!B24:G24) -> 6 | U24: =IF(S24=T24,"OK","확인") -> OK
A25: L21 | B25: ④ 평가·개선·변경 | C25: CHG BC 변경관리 → RA 리스크평가 | D25: CHG | E25: RA | F25: V05 | G25: =IFERROR(INDEX(관계동사!$B$5:$B$15,MATCH(F25,관계동사!$A$5:$A$15,0)),"") -> 수행을 촉발한다 | H25: E1 | K25: A27 | L25: =IFERROR(INDEX(인용근거!$E$5:$E$76,MATCH(LEFT(K25,3),인용근거!$A$5:$A$76,0)),"원문에 S→T 연결 서술 없음") -> Initiation of risk assessment in response to significant proposed or occurring changes; and | M25: A26 | N25: BC 변경관리의 산출물에는 중대한 제안·발생 변경에 대응한 리스크평가의 개시, 그리고 리스크평가와 오가는 제안·필요 변경 및 변경 결과가 포함된다. | O25: A26의 "for and from"은 양방향 흐름을 시사하나 본 연결은 CHG→RA 방향만 채택하고 반대 방향은 보류연결 H02에 기록(연구자 판단). | P25: 5개 차원 적용(환류폐쇄성은 환류 연결에만 적용) | Q25: 해당 없음 | R25: 전문가 패널 연결 타당도 평가 | S25: =COUNTIF(문항!$D$5:$D$183,A25) -> 5 | T25: =SUM(적용매트릭스!B25:G25) -> 5 | U25: =IF(S25=T25,"OK","확인") -> OK
A26: L22 | B26: ④ 평가·개선·변경 | C26: CHG BC 변경관리 → DOC 문서화된 정보 통제 | D26: CHG | E26: DOC | F26: V06 | G26: =IFERROR(INDEX(관계동사!$B$5:$B$15,MATCH(F26,관계동사!$A$5:$A$15,0)),"") -> 개정·갱신한다 | H26: E1 | K26: A28 | L26: =IFERROR(INDEX(인용근거!$E$5:$E$76,MATCH(LEFT(K26,3),인용근거!$A$5:$A$76,0)),"원문에 S→T 연결 서술 없음") -> Necessary changes (for the process of controlling documented information); | M26: A41 | N26: BC 변경관리의 산출물에는 문서화된 정보 통제 프로세스를 위한 필요한 변경이 포함된다. 문서화된 정보 통제는 정보의 식별·작성·갱신·통제를 포함한다. | O26: A41의 "updating"은 최신성 차원의 정의를 고안할 때 참고했으며, 최신성의 정의 자체는 연구자 정의. | P26: 5개 차원 적용(환류폐쇄성은 환류 연결에만 적용) | Q26: 해당 없음 | R26: 전문가 패널 연결 타당도 평가 | S26: =COUNTIF(문항!$D$5:$D$183,A26) -> 5 | T26: =SUM(적용매트릭스!B26:G26) -> 5 | U26: =IF(S26=T26,"OK","확인") -> OK
A27: L23 | B27: ④ 평가·개선·변경 | C27: INC 사고·비상 대응 → CHG BC 변경관리 | D27: INC | E27: CHG | F27: V05 | G27: =IFERROR(INDEX(관계동사!$B$5:$B$15,MATCH(F27,관계동사!$A$5:$A$15,0)),"") -> 수행을 촉발한다 | H27: E1 | J27: Y | K27: A29 | L27: =IFERROR(INDEX(인용근거!$E$5:$E$76,MATCH(LEFT(K27,3),인용근거!$A$5:$A$76,0)),"원문에 S→T 연결 서술 없음") -> The results of changes to the incident and emergency handling process or the process of exercising BC plans and procedures—as those processes initiated them. | M27: (없음) | N27: 사고·비상 대응이 개시한 변경의 결과가 변경관리의 산출물에 포함된다("as those processes initiated them"). | O27: "initiated"를 triggers(S의 사건·결과가 T의 수행을 개시)로 해석. A29는 INC·EXE와 변경 결과 방향을 한 문장에 담으므로 L23~L26은 연구자가 분리한 4개 연결. | P27: 환류 연결: 6개 차원 모두 적용(환류폐쇄성 포함) | Q27: 해당 없음 | R27: 전문가 패널 연결 타당도 평가 | S27: =COUNTIF(문항!$D$5:$D$183,A27) -> 6 | T27: =SUM(적용매트릭스!B27:G27) -> 6 | U27: =IF(S27=T27,"OK","확인") -> OK
A28: L24 | B28: ④ 평가·개선·변경 | C28: EXE BC 계획·절차 훈련·연습 → CHG BC 변경관리 | D28: EXE | E28: CHG | F28: V05 | G28: =IFERROR(INDEX(관계동사!$B$5:$B$15,MATCH(F28,관계동사!$A$5:$A$15,0)),"") -> 수행을 촉발한다 | H28: E1 | J28: Y | K28: A29 | L28: =IFERROR(INDEX(인용근거!$E$5:$E$76,MATCH(LEFT(K28,3),인용근거!$A$5:$A$76,0)),"원문에 S→T 연결 서술 없음") -> The results of changes to the incident and emergency handling process or the process of exercising BC plans and procedures—as those processes initiated them. | M28: (없음) | N28: 훈련·연습이 개시한 변경의 결과가 변경관리의 산출물에 포함된다. | O28: 분리 사유는 L23과 동일. | P28: 환류 연결: 6개 차원 모두 적용(환류폐쇄성 포함) | Q28: 해당 없음 | R28: 전문가 패널 연결 타당도 평가 | S28: =COUNTIF(문항!$D$5:$D$183,A28) -> 6 | T28: =SUM(적용매트릭스!B28:G28) -> 6 | U28: =IF(S28=T28,"OK","확인") -> OK
A29: L25 | B29: ④ 평가·개선·변경 | C29: CHG BC 변경관리 → INC 사고·비상 대응 | D29: CHG | E29: INC | F29: V07 | G29: =IFERROR(INDEX(관계동사!$B$5:$B$15,MATCH(F29,관계동사!$A$5:$A$15,0)),"") -> 환류된다 | H29: E1 | J29: Y | K29: A29 | L29: =IFERROR(INDEX(인용근거!$E$5:$E$76,MATCH(LEFT(K29,3),인용근거!$A$5:$A$76,0)),"원문에 S→T 연결 서술 없음") -> The results of changes to the incident and emergency handling process or the process of exercising BC plans and procedures—as those processes initiated them. | M29: (없음) | N29: 변경의 결과가 사고·비상 대응 프로세스로 돌아간다("The results of changes to the incident and emergency handling process"). | O29: 분리 사유는 L23과 동일. "results of changes to"를 updates(변경이 T의 내용을 개정)로 해석. | P29: 환류 연결: 6개 차원 모두 적용(환류폐쇄성 포함) | Q29: 해당 없음 | R29: 전문가 패널 연결 타당도 평가 | S29: =COUNTIF(문항!$D$5:$D$183,A29) -> 6 | T29: =SUM(적용매트릭스!B29:G29) -> 6 | U29: =IF(S29=T29,"OK","확인") -> OK
A30: L26 | B30: ④ 평가·개선·변경 | C30: CHG BC 변경관리 → EXE BC 계획·절차 훈련·연습 | D30: CHG | E30: EXE | F30: V07 | G30: =IFERROR(INDEX(관계동사!$B$5:$B$15,MATCH(F30,관계동사!$A$5:$A$15,0)),"") -> 환류된다 | H30: E1 | J30: Y | K30: A29 | L30: =IFERROR(INDEX(인용근거!$E$5:$E$76,MATCH(LEFT(K30,3),인용근거!$A$5:$A$76,0)),"원문에 S→T 연결 서술 없음") -> The results of changes to the incident and emergency handling process or the process of exercising BC plans and procedures—as those processes initiated them. | M30: (없음) | N30: 변경의 결과가 BC 계획·절차 훈련·연습 프로세스로 돌아간다. | O30: 분리 사유는 L23과 동일. | P30: 환류 연결: 6개 차원 모두 적용(환류폐쇄성 포함) | Q30: 해당 없음 | R30: 전문가 패널 연결 타당도 평가 | S30: =COUNTIF(문항!$D$5:$D$183,A30) -> 6 | T30: =SUM(적용매트릭스!B30:G30) -> 6 | U30: =IF(S30=T30,"OK","확인") -> OK
A31: L27 | B31: ⑤ 거버넌스·이해관계자 | C31: 핵심 BCMS 프로세스 전반(집단) → COM 협의·커뮤니케이션 | D31: CORE | E31: COM | F31: V11 | G31: =IFERROR(INDEX(관계동사!$B$5:$B$15,MATCH(F31,관계동사!$A$5:$A$15,0)),"") -> 전달된다 | H31: E1 | I31: 집단 | K31: A30 | L31: =IFERROR(INDEX(인용근거!$E$5:$E$76,MATCH(LEFT(K31,3),인용근거!$A$5:$A$76,0)),"원문에 S→T 연결 서술 없음") -> The outcomes of nearly all BCMS processes are communicated centrally to stakeholders external to the BCMS as part of the consultation and communication process. | M31: A40 | N31: 거의 모든 BCMS 프로세스의 결과가 협의·커뮤니케이션 프로세스를 통해 BCMS 외부 이해관계자에게 중앙에서 전달된다. | O31: [연구자 판단] "nearly all BCMS processes"는 프로세스를 열거하지 않으므로 출발점을 집단 노드 CORE("핵심 BCMS 프로세스 전반")로 처리했다. CORE는 Arias의 객체가 아니라 연구자가 만든 가상 노드이다. | P31: 5개 차원 적용(환류폐쇄성은 환류 연결에만 적용) | Q31: 해당 없음 | R31: 전문가 패널에서 집단 출발점 처리의 적절성 평가 | S31: =COUNTIF(문항!$D$5:$D$183,A31) -> 5 | T31: =SUM(적용매트릭스!B31:G31) -> 5 | U31: =IF(S31=T31,"OK","확인") -> OK
A32: L28 | B32: ⑤ 거버넌스·이해관계자 | C32: COM 협의·커뮤니케이션 → GOV BC 거버넌스 | D32: COM | E32: GOV | F32: V01 | G32: =IFERROR(INDEX(관계동사!$B$5:$B$15,MATCH(F32,관계동사!$A$5:$A$15,0)),"") -> 입력된다·활용된다 | H32: E1 | K32: A31 | L32: =IFERROR(INDEX(인용근거!$E$5:$E$76,MATCH(LEFT(K32,3),인용근거!$A$5:$A$76,0)),"원문에 S→T 연결 서술 없음") -> These reports and identified requirements serve as inputs for the BC governance process. | M32: A47 | N32: 협의·커뮤니케이션의 보고와 식별된 요구사항은 BC 거버넌스 프로세스의 입력으로 쓰인다. | O32: "These reports"는 앞 문장(리스크와 BC 관리 보고의 커뮤니케이션)을 가리킨다고 연구자가 확인(A47). | P32: 5개 차원 적용(환류폐쇄성은 환류 연결에만 적용) | Q32: 해당 없음 | R32: 전문가 패널 연결 타당도 평가 | S32: =COUNTIF(문항!$D$5:$D$183,A32) -> 5 | T32: =SUM(적용매트릭스!B32:G32) -> 5 | U32: =IF(S32=T32,"OK","확인") -> OK
A33: L29 | B33: ⑤ 거버넌스·이해관계자 | C33: GOV BC 거버넌스 → POL BC 정책관리 | D33: GOV | E33: POL | F33: V03 | G33: =IFERROR(INDEX(관계동사!$B$5:$B$15,MATCH(F33,관계동사!$A$5:$A$15,0)),"") -> 도출·이행된다 | H33: E3 | K33: (없음) | L33: =IFERROR(INDEX(인용근거!$E$5:$E$76,MATCH(LEFT(K33,3),인용근거!$A$5:$A$76,0)),"원문에 S→T 연결 서술 없음") -> 원문에 S→T 연결 서술 없음 | M33: A33 / A34 / A35 / B13 | N33: Arias는 거버넌스(BCMS가 이해관계자의 목표·요구에 부합하도록 보장)와 정책관리(정책의 개발·유지·보존, 접근·이해 보장)를 각각 서술할 뿐 두 프로세스의 관계는 서술하지 않는다. Białas는 목표(objectives)와 정책(policy)을 "Plan" 단계의 병렬 항목으로 나열한다. | O33: [연구자 가정] 정책이 경영진이 정한 BC 목표·방향에서 도출된다는 연결은 두 논문에 근거가 없다(이를 뒷받침하는 인용이 두 논문에 없음). 또한 Białas에서는 정책과 목표가 형제 항목이므로 Białas는 이 연결을 지지하지 않는다. | P33: 5개 차원 적용(환류폐쇄성은 환류 연결에만 적용) | Q33: Białas §2.8 Fig.2 설명(B13): 목표와 정책이 같은 Plan 단계의 병렬 항목 | R33: 전문가 합의 필수. 합의 80% 미만이면 삭제 | S33: =COUNTIF(문항!$D$5:$D$183,A33) -> 5 | T33: =SUM(적용매트릭스!B33:G33) -> 5 | U33: =IF(S33=T33,"OK","확인") -> OK
A34: L30 | B34: ⑤ 거버넌스·이해관계자 | C34: RES 자원관리 → 핵심 BCMS 프로세스 전반(집단) | D34: RES | E34: CORE | F34: V09 | G34: =IFERROR(INDEX(관계동사!$B$5:$B$15,MATCH(F34,관계동사!$A$5:$A$15,0)),"") -> 제공한다 | H34: E1 | I34: 집단 | K34: A18 | L34: =IFERROR(INDEX(인용근거!$E$5:$E$76,MATCH(LEFT(K34,3),인용근거!$A$5:$A$76,0)),"원문에 S→T 연결 서술 없음") -> Outputs from this process include documented resources for implementing and running selected strategies, as well as resources for operating core BCMS processes, along with reports on resource utilization for BCMS core processes and the customer relationship management process | M34: A38 | N34: 자원관리의 산출물에는 핵심 BCMS 프로세스 운영을 위한 자원과 BCMS 핵심 프로세스에 대한 자원 사용 보고가 포함된다. | O34: [연구자 판단] 도착이 "핵심 BCMS 프로세스(복수)"이므로 집단 노드 CORE를 사용(L27과 동일 사유). | P34: 5개 차원 적용(환류폐쇄성은 환류 연결에만 적용) | Q34: 해당 없음 | R34: 전문가 패널에서 집단 도착점 처리의 적절성 평가 | S34: =COUNTIF(문항!$D$5:$D$183,A34) -> 5 | T34: =SUM(적용매트릭스!B34:G34) -> 5 | U34: =IF(S34=T34,"OK","확인") -> OK
A35: L31 | B35: ⑤ 거버넌스·이해관계자 | C35: RES 자원관리 → CRM 고객관계관리 | D35: RES | E35: CRM | F35: V09 | G35: =IFERROR(INDEX(관계동사!$B$5:$B$15,MATCH(F35,관계동사!$A$5:$A$15,0)),"") -> 제공한다 | H35: E1 | K35: A18 | L35: =IFERROR(INDEX(인용근거!$E$5:$E$76,MATCH(LEFT(K35,3),인용근거!$A$5:$A$76,0)),"원문에 S→T 연결 서술 없음") -> Outputs from this process include documented resources for implementing and running selected strategies, as well as resources for operating core BCMS processes, along with reports on resource utilization for BCMS core processes and the customer relationship management process | M35: A32 | N35: 자원관리의 산출물에는 고객관계관리 프로세스에 대한 자원 사용 보고가 포함된다. 고객관계관리는 고객 만족의 운영적 관리와 BC 투자 가치의 지속적 입증을 수행한다. | O35: 고객관계관리를 "고객 만족·BC 투자 가치 입증"으로 부르는 것은 CRM의 기능을 서술한 A32를 바탕으로 한 연구자의 지표화이며, 인용문이 "자원 보고가 가치 입증에 쓰인다"고 직접 말하는 것은 아니다. | P35: 5개 차원 적용(환류폐쇄성은 환류 연결에만 적용) | Q35: 해당 없음 | R35: 전문가 패널 연결 타당도 평가 | S35: =COUNTIF(문항!$D$5:$D$183,A35) -> 5 | T35: =SUM(적용매트릭스!B35:G35) -> 5 | U35: =IF(S35=T35,"OK","확인") -> OK

Sheet 적용매트릭스
A1: 연결 × 품질 차원 적용 매트릭스 (1 = 해당 차원 문항 있음)
A2: 정합성·추적성·증빙성·책임성·최신성은 전 연결에 적용, 환류폐쇄성은 환류 연결 8개에만 적용(연구자 분류). 이 표가 문항 수를 결정한다.
A4: 연결 ID | B4: 정합성 | C4: 추적성 | D4: 증빙성 | E4: 책임성 | F4: 최신성 | G4: 환류폐쇄성 | H4: 합계 | I4: 연결(S→T)
A5: L01 | B5: 1 | C5: 1 | D5: 1 | E5: 1 | F5: 1 | G5: 0 | H5: =SUM(B5:G5) -> 5 | I5: REQ → BIA
A6: L02 | B6: 1 | C6: 1 | D6: 1 | E6: 1 | F6: 1 | G6: 0 | H6: =SUM(B6:G6) -> 5 | I6: REQ → RA
A7: L03 | B7: 1 | C7: 1 | D7: 1 | E7: 1 | F7: 1 | G7: 0 | H7: =SUM(B7:G7) -> 5 | I7: BIA → RA
A8: L04 | B8: 1 | C8: 1 | D8: 1 | E8: 1 | F8: 1 | G8: 0 | H8: =SUM(B8:G8) -> 5 | I8: REQ → AUD
A9: L05 | B9: 1 | C9: 1 | D9: 1 | E9: 1 | F9: 1 | G9: 0 | H9: =SUM(B9:G9) -> 5 | I9: REQ → SUP
A10: L06 | B10: 1 | C10: 1 | D10: 1 | E10: 1 | F10: 1 | G10: 0 | H10: =SUM(B10:G10) -> 5 | I10: BIA → STR
A11: L07 | B11: 1 | C11: 1 | D11: 1 | E11: 1 | F11: 1 | G11: 0 | H11: =SUM(B11:G11) -> 5 | I11: STR → IMP
A12: L08 | B12: 1 | C12: 1 | D12: 1 | E12: 1 | F12: 1 | G12: 0 | H12: =SUM(B12:G12) -> 5 | I12: STR → PLAN
A13: L09 | B13: 1 | C13: 1 | D13: 1 | E13: 1 | F13: 1 | G13: 0 | H13: =SUM(B13:G13) -> 5 | I13: RA → PLAN
A14: L10 | B14: 1 | C14: 1 | D14: 1 | E14: 1 | F14: 1 | G14: 0 | H14: =SUM(B14:G14) -> 5 | I14: RES → IMP
A15: L11 | B15: 1 | C15: 1 | D15: 1 | E15: 1 | F15: 1 | G15: 0 | H15: =SUM(B15:G15) -> 5 | I15: BIA → RES
A16: L12 | B16: 1 | C16: 1 | D16: 1 | E16: 1 | F16: 1 | G16: 0 | H16: =SUM(B16:G16) -> 5 | I16: PLAN → INC
... A35: L31 | B35: 1 | C35: 1 | D35: 1 | E35: 1 | F35: 1 | G35: 0 | H35: =SUM(B35:G35) -> 5 | I35: RES → CRM
A36: 합계 | B36: =SUM(B5:B35) -> 31 | C36: =SUM(C5:C35) -> 31 | D36: =SUM(D5:D35) -> 31 | E36: =SUM(E5:E35) -> 31 | F36: =SUM(F5:F35) -> 31 | G36: =SUM(G5:G35) -> 8 | H36: =SUM(H5:H35) -> 163

Sheet 관계동사
A1: 관계층 — 관계동사 11개 (연구자 정의, Arias 서술문에서 동사 추출)
A2: 첨부 문서의 동사 중 일치·추적·증빙은 품질층 차원과 겹쳐 품질층으로 옮겼다. V10(승인한다)은 문헌에서 확인되나 이번 연결 31개에는 쓰지 않았다.
A4: ID | B4: 관계동사 | C4: 영문 predicate | D4: 의미 (S→T) | E4: 판정 질문 | F4: Arias 원문 동사 (영문 표현) | G4: 근거 인용 ID | H4: 첨부 문서 동사와의 대응 | I4: 사용 연결 | J4: 사용 수
A5: V01 | B5: 입력된다·활용된다 | C5: isInputTo | D5: S의 산출물이 T의 입력·기준으로 쓰인다 | E5: T를 수행할 때 S의 산출물이 입력으로 쓰이는가? | F5: inform / essential input / serve as inputs | G5: A11 / A17 / A31 | H5: 첨부 문서의 "입력된다/활용된다" | I5: L01, L02, L04, L05, L09, L11, L17, L28 | J5: =COUNTIF(연결!$F$5:$F$35,A5) -> 8
A6: V02 | B6: 근거가 된다 | C6: isBasisFor | D6: S의 결과가 T의 결정·선정의 근거(기준)가 된다 | E6: T의 결정이 S의 결과를 근거로 하는가? | F6: relies on … as its foundation / guide the determination and selection | G6: A12 / A14 | H6: 첨부 문서의 "근거가 된다"(일부 "제약한다") | I6: L03, L06 | J6: =COUNTIF(연결!$F$5:$F$35,A6) -> 2
A7: V03 | B7: 도출·이행된다 | C7: isElaboratedInto | D7: S의 내용이 T로 구체화·도출되거나 T에서 실행된다 | E7: T의 내용이 S에서 도출되거나 S를 실행하는가? | F7: derived from / executed as planned / through the execution of | G7: A16 / A15 / A19 | H7: (Arias에서 추가한 동사) | I7: L07, L08, L12, L29 | J7: =COUNTIF(연결!$F$5:$F$35,A7) -> 4
A8: V04 | B8: 시험·검증된다 | C8: isVerifiedBy | D8: S가 T에서 시험·검증된다 | E8: T가 S의 유효성을 시험·평가하는가? | F8: tested regularly to validate their effectiveness | G8: A23 | H8: 첨부 문서의 "검증한다" | I8: L15 | J8: =COUNTIF(연결!$F$5:$F$35,A8) -> 1
A9: V05 | B9: 수행을 촉발한다 | C9: triggers | D9: S의 사건·결과가 T의 수행을 개시시킨다 | E9: S가 일어나면 T가 시작되는가? | F9: initiation of / as those processes initiated them | G9: A27 / A29 | H9: 첨부 문서의 "변경을 촉발한다" | I9: L21, L23, L24 | J9: =COUNTIF(연결!$F$5:$F$35,A9) -> 3
A10: V06 | B10: 개정·갱신한다 | C10: revises | D10: S의 결과·승인된 변경이 T의 내용을 개정·갱신한다 | E10: S의 결과가 T의 문서·절차를 바꾸는가? | F10: prompt any necessary adjustments / necessary changes (for DOC) / updating | G10: A23 / A28 / A41 | H10: 첨부 문서의 "개정·갱신한다" | I10: L16, L22 | J10: =COUNTIF(연결!$F$5:$F$35,A10) -> 2
A11: V07 | B11: 환류된다 | C11: feedsBackTo | D11: S의 결과가 T(개선·재수정)로 되돌아간다 | E11: S의 결과가 개선·재수정 대상(T)으로 되돌아가는가? | F11: are used to improve / results of changes … as those processes initiated them | G11: A25 / A46 / A29 | H11: 첨부 문서의 "환류된다" | I11: L18, L19, L20, L25, L26 | J11: =COUNTIF(연결!$F$5:$F$35,A11) -> 5
A12: V08 | B12: 포함한다 | C12: hasSubprocess | D12: T는 S의 하위 프로세스로서 S 안에서 수행된다 | E12: T가 S의 일부로서 S 안에서 수행되는가? | F12: includes two primary subprocesses | G12: A21 | H12: (Arias에서 추가한 동사) | I12: L13, L14 | J12: =COUNTIF(연결!$F$5:$F$35,A12) -> 2
A13: V09 | B13: 제공한다 | C13: supplies | D13: S가 T에 자원 또는 자원 관련 보고를 제공한다 | E13: T가 S로부터 자원 또는 자원 사용 보고를 받는가? | F13: outputs … include documented resources / reports on resource utilization | G13: A18 | H13: (Arias에서 추가한 동사) | I13: L10, L30, L31 | J13: =COUNTIF(연결!$F$5:$F$35,A13) -> 3
A14: V10 | B14: 승인한다 | C14: approves | D14: S가 T의 결과를 승인한다 | E14: S가 T의 결과를 승인하는가? | F14: securing of executive approval of the BIA findings | G14: A37 | H14: 첨부 문서의 "승인한다" — 이번 연결 31개에는 사용하지 않음 | I14: (미사용) | J14: =COUNTIF(연결!$F$5:$F$35,A14) -> 0
A15: V11 | B15: 전달된다 | C15: isCommunicatedTo | D15: S의 결과가 T로 전달·보고된다 | E15: S의 결과가 T(이해관계자 등)에게 전달되는가? | F15: are communicated centrally to stakeholders | G15: A30 | H15: (Arias에서 추가한 동사) | I15: L27 | J15: =COUNTIF(연결!$F$5:$F$35,A15) -> 1

Sheet 보류연결
A1: 보류·제외한 후보 연결 — 채택하지 않은 이유
A2: 연구자 결정란에 포함/제외를 직접 기록(노란 칸)
A4: ID | B4: 출발 | C4: 도착 | D4: 후보 내용 | E4: 채택하지 않은 이유(인용 근거 부재) | F4: 권고 | G4: 연구자 결정
A5: H01 | B5: INC | C5: PLAN | D5: 사고 대응 경험을 BC 계획·절차 개정에 반영 | E5: Arias에는 연습(EXE)→계획(L16)만 서술되고 사고 대응→계획 환류는 서술이 없음. 사고 결과는 변경관리(L23)를 거쳐 반영되는 경로만 근거가 있음. | F5: 연구자 결정 필요
A6: H02 | B6: RA | C6: CHG | D6: 리스크평가 결과를 변경 판단에 사용 | E6: A26의 "for and from the risk assessment process"는 양방향을 시사하나 방향이 문장에서 분리되지 않음. 현재는 CHG→RA(L21)만 채택. | F6: 연구자 결정 필요
A7: H03 | B7: EXE | C7: AWR | D7: 연습 결과를 교육 내용에 반영 | E7: 두 논문에 서술 없음. L17(PLAN→AWR)과 중복 가능성. | F7: 제외 권고
A8: H04 | B8: GOV | C8: CRM | D8: 거버넌스와 고객관계관리의 관계 | E8: A32는 두 프로세스를 "In addition to"로 병렬 서술할 뿐 연결을 서술하지 않음. | F8: 제외 권고
A9: H05 | B9: CI | C9: PERF | D9: 개선 결과를 성과평가 지표에 반영 | E9: A25는 성과평가→개선 방향만 서술. 개선 후 지표 갱신은 서술 없음. | F9: 제외 권고
A10: H06 | B10: DOC | C10: 전 프로세스 | D10: 문서화된 정보 통제가 모든 프로세스를 지원 | E10: A41은 정보 통제의 내용만 서술하고 프로세스별 연결은 CHG→DOC(L22)만 서술. | F10: 제외 권고

Sheet 객체
A1: 객체층 — Arias Table 5의 22개 BCMS 프로세스
A2: 범주·PDCA·재난관리주기: Table 5(p.14) / 전문가 지명률: Table 2–4(pp.11–13, 전문가 39명) / 대표 산출물: 연구자 제안
A4: ID | B4: 프로세스(한글) | C4: Arias 원문 이름 | D4: 범주 | E4: PDCA | F4: 재난관리주기 | G4: 전문가 지명률(%) | H4: Arias 합의 구분(80/20) | I4: 대표 산출물(연구자 제안) | J4: 관련 연결 수
A5: GOV | B5: BC 거버넌스 | C5: Business continuity governance process | D5: 관리 | E5: - | F5: - | G5: 90 | H5: =IF(G5>=80,"범주 1 (채택)",IF(G5>=20,"범주 2 (토론)","범주 3 (기각)")) -> 범주 1 (채택) | I5: 경영진 검토 결과 | J5: =COUNTIF(연결!$D$5:$D$35,A5)+COUNTIF(연결!$E$5:$E$35,A5) -> 2
A6: POL | B6: BC 정책관리 | C6: Business continuity policy management process | D6: 핵심 | E6: Plan | F6: Mitigation | G6: 87 | H6: =IF(G6>=80,"범주 1 (채택)",IF(G6>=20,"범주 2 (토론)","범주 3 (기각)")) -> 범주 1 (채택) | I6: BC 정책 | J6: =COUNTIF(연결!$D$5:$D$35,A6)+COUNTIF(연결!$E$5:$E$35,A6) -> 1
A7: REQ | B7: 요구사항관리 | C7: Requirements management process | D7: 핵심 | E7: Plan | F7: Mitigation | G7: 74 | H7: =IF(G7>=80,"범주 1 (채택)",IF(G7>=20,"범주 2 (토론)","범주 3 (기각)")) -> 범주 2 (토론) | I7: 법규·계약 요구사항 목록 | J7: =COUNTIF(연결!$D$5:$D$35,A7)+COUNTIF(연결!$E$5:$E$35,A7) -> 4
A8: BIA | B8: BIA·중요도 분석 | C8: Business impact assessment and criticality analysis process | D8: 핵심 | E8: Plan | F8: Mitigation | G8: 100 | H8: =IF(G8>=80,"범주 1 (채택)",IF(G8>=20,"범주 2 (토론)","범주 3 (기각)")) -> 범주 1 (채택) | I8: BIA 결과(문서화된 업무연속성 요구사항) | J8: =COUNTIF(연결!$D$5:$D$35,A8)+COUNTIF(연결!$E$5:$E$35,A8) -> 4
A9: RA | B9: 리스크평가 | C9: Risk assessment process (for risks of disruption) | D9: 핵심 | E9: Plan | F9: Mitigation | G9: 90 | H9: =IF(G9>=80,"범주 1 (채택)",IF(G9>=20,"범주 2 (토론)","범주 3 (기각)")) -> 범주 1 (채택) | I9: 리스크 카탈로그 | J9: =COUNTIF(연결!$D$5:$D$35,A9)+COUNTIF(연결!$E$5:$E$35,A9) -> 4
A10: STR | B10: BC 전략·솔루션 결정·선정 | C10: Process of determining and selecting BC strategies and solutions | D10: 핵심 | E10: Plan | F10: Mitigation | G10: 74 | H10: =IF(G10>=80,"범주 1 (채택)",IF(G10>=20,"범주 2 (토론)","범주 3 (기각)")) -> 범주 2 (토론) | I10: 선정된 BC 전략·솔루션 | J10: =COUNTIF(연결!$D$5:$D$35,A10)+COUNTIF(연결!$E$5:$E$35,A10) -> 3
A11: PLAN | B11: BC 계획·절차 개발 | C11: Process of developing BC plans and procedures | D11: 핵심 | E11: Plan | F11: Mitigation | G11: 69 | H11: =IF(G11>=80,"범주 1 (채택)",IF(G11>=20,"범주 2 (토론)","범주 3 (기각)")) -> 범주 2 (토론) | I11: BC 계획·절차 | J11: =COUNTIF(연결!$D$5:$D$35,A11)+COUNTIF(연결!$E$5:$E$35,A11) -> 6
A12: IMP | B12: 솔루션 이행관리 | C12: Solution implementation management process | D12: 핵심 | E12: Do | F12: Preparedness | G12: 69 | H12: =IF(G12>=80,"범주 1 (채택)",IF(G12>=20,"범주 2 (토론)","범주 3 (기각)")) -> 범주 2 (토론) | I12: 구현된 솔루션 | J12: =COUNTIF(연결!$D$5:$D$35,A12)+COUNTIF(연결!$E$5:$E$35,A12) -> 2
A13: INC | B13: 사고·비상 대응 | C13: Incident and emergency handling process | D13: 핵심 | E13: Do | F13: Response | G13: 100 | H13: =IF(G13>=80,"범주 1 (채택)",IF(G13>=20,"범주 2 (토론)","범주 3 (기각)")) -> 범주 1 (채택) | I13: 사고 대응 기록 | J13: =COUNTIF(연결!$D$5:$D$35,A13)+COUNTIF(연결!$E$5:$E$35,A13) -> 5
A14: EXE | B14: BC 계획·절차 훈련·연습 | C14: Process of exercising BC plans and procedures | D14: 핵심 | E14: Do | F14: Preparedness | G14: 100 | H14: =IF(G14>=80,"범주 1 (채택)",IF(G14>=20,"범주 2 (토론)","범주 3 (기각)")) -> 범주 1 (채택) | I14: 연습 결과 | J14: =COUNTIF(연결!$D$5:$D$35,A14)+COUNTIF(연결!$E$5:$E$35,A14) -> 4
A15: AWR | B15: 인식·역량·교육 | C15: Awareness, competence, and training process | D15: 핵심 | E15: Do | F15: Preparedness | G15: 95 | H15: =IF(G15>=80,"범주 1 (채택)",IF(G15>=20,"범주 2 (토론)","범주 3 (기각)")) -> 범주 1 (채택) | I15: 교육 프로그램·기록 | J15: =COUNTIF(연결!$D$5:$D$35,A15)+COUNTIF(연결!$E$5:$E$35,A15) -> 1
A16: SUP | B16: 공급망관리 | C16: Supply chain management process | D16: 핵심 | E16: Do | F16: Preparedness | G16: 90 | H16: =IF(G16>=80,"범주 1 (채택)",IF(G16>=20,"범주 2 (토론)","범주 3 (기각)")) -> 범주 1 (채택) | I16: 공급업체 평가 결과 | J16: =COUNTIF(연결!$D$5:$D$35,A16)+COUNTIF(연결!$E$5:$E$35,A16) -> 2
