Workbook

Sheet 안내
A1: BCMS 프로세스 간 연계성 — 문항은행 V2 (인용 근거와 연구자 의견 분리판)
A2: 박사논문 프로젝트 · 근거: Arias-Aranda et al.(2026) Appl. Sci. 16, 3219 / Białas(2010) Ontological approach to the BCMS development
A4: V2 핵심 변경 | B4: ① 모든 근거는 PDF 원문과 자동 대조한 영문 인용문(쪽 번호 포함)으로 제시. ② 인용이 말하는 것과 연구자 해석·가정을 열로 분리. ③ 연구자 의견에 해당하는 용어는 [정의서]에서 정의. ④ 증거유형을 E1/E2/E3으로 재분류(V1은 일부 과대평가). ⑤ 연결을 출발→도착 한 쌍으로 쪼갬(25→31개).
A5: 표기 규칙 | B5: 파란 바탕 열 = 논문 인용(원문 대조 완료) · 빨간 바탕 열 = 연구자 의견(해석·가정·지표화). 연구자 번역(한국어)은 참고용이며 원문 대조 대상이 아님.
A6: 증거유형 | B6: E1 = 원문이 S→T 연결을 직접 서술 · E2 = 원문이 연결을 서술하나 출발/도착 일부를 연구자가 특정·보완 · E3 = 원문에 연결 서술 없음(연구자 가정 또는 Białas 유추). 집계: E1 26개 / E2 2개 / E3 3개.
A7: 시트 구성 | B7: 정의서 · 인용근거(64) · 연결(31) · 관계유형(7) · 보류연결 · 객체(22) · 트리플 · 관계매트릭스 · 온톨로지맵 · 문항(108) · 보유·응답자정보 · 응답입력 · 연결점수 · 점수요약 · 검증
A8: 사용 순서 | B8: ① 정의서·연결 시트 검토(연구자 의견 열에 동의 여부 판단) → ② 문항 시트에서 전문가 6인 적합도(1~4) 입력, I-CVI·판정 자동 계산 → ③ 설문 응답을 응답입력 7행부터 입력 → ④ 연결점수·점수요약·검증 확인
A9: 입력 칸 | B9: 노란 바탕 + 파란 글씨 = 직접 입력. 응답입력 6행은 예시이며 집계에서 제외(집계는 7~56행).
A10: 응답 척도 | B10: 1 전혀 그렇지 않다 · 2 그렇지 않다 · 3 보통이다 · 4 그렇다 · 5 매우 그렇다 · 9 해당 없음/모르겠음(결측 처리)
A11: Białas 차용 범위 | B11: 방법만 차용(competency question, object slot의 domain/range, data slot, 검증 방식). 클래스 목록과 관계 이름은 BS 25999 기반이라 쓰지 않음.
A12: 중요한 한계 | B12: Arias는 프로세스가 핵심인지를 검증했을 뿐 프로세스 간 연결은 검증하지 않았음. 연결 31개는 전문가 검증 전 가설. R·V·U 구분, 관계유형 이름, 영역 분류, 집단 노드 CORE는 두 논문에 없는 연구자 설계.
A13: 검증 기록 | B13: 인용문 64/64 및 객체 22/22가 PDF 원문과 일치(검증일 2026-10-06). 재검증: scripts/verify_quotes.py

Sheet 정의서
A1: 정의서 — 용어별 정의, 유형(인용 정의 / 연구자 정의), 근거 인용
A2: 유형이 "연구자 정의"인 항목은 두 논문에 없는 연구자의 판단이며, 박사논문에서 연구자가 직접 확정해야 하는 부분
A4: ID | B4: 용어 | C4: 유형 | D4: 정의 | E4: 근거 인용 ID | F4: 근거 인용 원문(첫 번째) | G4: 근거·한계 설명
A5: D01 | B5: 프로세스(객체) | C5: 인용 정의 + 연구자 범위 설정 | D5: 입력을 출력으로 전환하는, 상호 관련되거나 상호작용하는 활동의 응집된 집합. 본 연구의 객체는 Arias Table 5의 22개 BCMS 프로세스이며, BCMS 계획은 프로젝트로 분류되어 제외한다. | E5: A42 / A01 / A48 | F5: =IFERROR(INDEX(인용근거!$E$5:$E$68,MATCH(LEFT(E5,3),인용근거!$A$5:$A$68,0)),"") -> In essence, a process represents a cohesive set of interrelated or interacting activities to transform inputs into outputs | G5: 객체 22개 선정 = Arias Table 5(인용). 객체에서 BCMS 계획을 뺀 것도 Arias의 분류(A48)를 따른 것.
A6: D02 | B6: 산출물(artefact) | C6: 인용 개념 + 연구자 정의 | D6: [연구자 정의] 프로세스가 만들어 다른 프로세스가 사용하는 문서·기록·보고·결정. Białas는 slot이 채워진 개체가 핵심 BCM 산출물(주로 문서)을 나타낸다고 쓴다. | E6: B07 | F6: =IFERROR(INDEX(인용근거!$E$5:$E$68,MATCH(LEFT(E6,3),인용근거!$A$5:$A$68,0)),"") -> The individuals with filled-in slots represent the key BCM artefacts, mostly documents, of the BCMO related knowledge base. | G6: 용어는 Białas에서 차용, 정의 문장은 연구자가 작성.
A7: D03 | B7: 연결(link) | C7: 연구자 정의 | D7: 프로세스 S의 산출물·결과·자원이 프로세스 T의 입력·기준·실행·개정에 쓰이도록 Arias가 서술한 방향성 있는 프로세스 쌍(S→T) 1개. 한 연결은 정확히 하나의 출발(S)과 하나의 도착(T)을 가진다(집단 노드 CORE 제외). Białas의 object-type slot(domain→range)에 대응시킨다. | E7: A02 / A03 / A04 / B04 / B05 | F7: =IFERROR(INDEX(인용근거!$E$5:$E$68,MATCH(LEFT(E7,3),인용근거!$A$5:$A$68,0)),"") -> A process reference model should delineate the interconnections among the processes outlined within it. | G7: 연결이라는 단위의 정의는 연구자 정의. 입력·출력·상호작용·상호 연결이 중요하다는 점은 인용.
A8: D04 | B8: 연계성(linkage) | C8: 연구자 정의(구성개념) | D8: BCMS 프로세스 간 연결이 조직의 실제 운영에서 반영(R)되고, 그 반영이 확인(V)되며, 출발 또는 도착 프로세스가 바뀔 때 갱신(U)되는 정도. 한 연결의 점수는 R·V·U 문항 평균, 조직의 연계성 지수는 연결 점수의 평균이다. | E8: A01 / A02 / A04 / B01 / A07 / A05 | F8: =IFERROR(INDEX(인용근거!$E$5:$E$68,MATCH(LEFT(E8,3),인용근거!$A$5:$A$68,0)),"") -> Activities utilizing resources must be managed to convert inputs into outputs through a series of interconnected or interacting activities, also called processes | G8: "연계성"이라는 용어와 R·V·U 구성은 두 논문에 없는 연구자 정의. 프로세스 간 상호 연결·상호작용이 BCMS의 핵심이라는 점(A01, A02, A04, B01, A07)과 체크리스트만으로는 지속 운영이 보장되지 않는다는 점(A05)이 정의의 이유.
A9: D05 | B9: 반영(R, reflected) | C9: 연구자 정의 | D9: T의 계획·기준·산출물·결정에 S의 산출물이 실제로 사용되었다는 증거(문서 인용, 항목 포함, 절차상 입력)가 있는 상태. | E9: (없음) | F9: (해당 인용 없음) | G9: 두 논문에 해당 구분 없음.
A10: D06 | B10: 확인(V, verified) | C10: 연구자 정의 | D10: S→T 반영이 누락·불일치 없이 이루어졌는지를 점검·검토·승인·대조하는 절차를 수행하고 기록하는 상태. | E10: A36 / A23 | F10: =IFERROR(INDEX(인용근거!$E$5:$E$68,MATCH(LEFT(E10,3),인용근거!$A$5:$A$68,0)),"") -> The solution implementation management process involves initiating and verifying BC strategies, solutions, and changes that may result thereof. | G10: Arias는 이행관리가 전략을 "verifying"하고(A36), 연습이 계획의 유효성을 "validate"한다고(A23) 서술한다. 이는 확인 행위의 예시로 참고했을 뿐 R/V/U 3상태 구분은 연구자 정의.
A11: D07 | B11: 갱신(U, updated) | C11: 연구자 정의 | D11: S의 산출물 또는 T가 바뀔 때, 상대 프로세스를 재검토하고 필요하면 개정하는 절차가 수행되는 상태. 문항에서는 "다시 검토하고 고친다" 형태로 표현한다. | E11: A41 | F11: =IFERROR(INDEX(인용근거!$E$5:$E$68,MATCH(LEFT(E11,3),인용근거!$A$5:$A$68,0)),"") -> The process of controlling documented information involves identifying, creating, updating, and controlling information essential for the effectiveness of the BCMS. | G11: Arias의 문서화된 정보 통제가 정보의 "updating"을 포함한다(A41)는 점을 참고. 갱신의 정의는 연구자 정의.
A12: D08 | B12: 관계유형(relation type) | C12: 연구자 정의 | D12: 연결의 의미를 7가지로 분류한 것(informs, elaboratedInto, testedBy, updates, triggers, contains, supplies). 정의와 판정 질문은 [관계유형] 시트에 있다. | E12: B04 | F12: =IFERROR(INDEX(인용근거!$E$5:$E$68,MATCH(LEFT(E12,3),인용근거!$A$5:$A$68,0)),"") -> i.e. relationships between an individual member of the given class (the object) and other individuals | G12: Białas의 관계 이름(hasBCplan 등)은 구성 관계 위주여서 쓰지 않았고, 7개 이름은 연구자가 붙임.
A13: D09 | B13: 증거유형 E1/E2/E3 | C13: 연구자 정의 | D13: E1=원문이 S→T 연결을 직접 서술(인용만으로 연결의 존재와 방향이 성립). E2=원문이 연결을 서술하나 출발 또는 도착 프로세스를 연구자가 특정·보완해야 함. E3=원문에 연결 서술이 없고 연구자 가정 또는 Białas의 유추에 의존. 각 연결에 인용문과 연구자 의견을 분리해 기록한다. | E13: (없음) | F13: (해당 인용 없음) | G13: 등급 기준은 연구자 정의.
A14: D10 | B14: 연결 영역 ①~⑤ | C14: 연구자 분류 | D14: 연결의 도착 프로세스가 수행하는 업무 흐름에 따라 묶은 분류(① 요구·분석, ② 전략·계획·이행, ③ 대응·복구·훈련, ④ 평가·개선·변경, ⑤ 거버넌스·이해관계자). | E14: (없음) | F14: (해당 인용 없음) | G14: Arias의 PDCA 열(Table 5)과는 별개의 연구자 분류. PDCA는 객체 시트에 별도 표기.
A15: D11 | B15: 집단 노드 CORE | C15: 연구자 정의 | D15: Arias가 "nearly all BCMS processes"처럼 프로세스를 열거하지 않고 가리킨 집단을 하나의 가상 노드로 표현한 것. 객체 22개에 포함되지 않는다. | E15: A30 / A18 | F15: =IFERROR(INDEX(인용근거!$E$5:$E$68,MATCH(LEFT(E15,3),인용근거!$A$5:$A$68,0)),"") -> The outcomes of nearly all BCMS processes are communicated centrally to stakeholders external to the BCMS as part of the consultation and communication process. | G15: 노드 자체는 연구자가 만든 것.
A16: D12 | B16: competency question | C16: 인용 정의 + 연구자 적용 | D16: 온톨로지 관련 지식베이스가 답할 수 있는 온톨로지 영역의 질문. 그 답이 온톨로지의 범위를 정의한다. 본 연구에서는 연결마다 "이 연결이 조직에서 유지되는지 어떤 질문으로 확인하는가"를 문항 3개(R·V·U)로 구체화한다. | E16: B02 / B03 | F16: =IFERROR(INDEX(인용근거!$E$5:$E$68,MATCH(LEFT(E16,3),인용근거!$A$5:$A$68,0)),"") -> The ontology domain questions that the ontology related knowledge base is able to answer are called competency questions | G16: 정의는 Białas 인용, 문항으로의 적용은 연구자 설계.
A17: D13 | B17: ProcessLink 객체화 | C17: 연구자 설계 | D17: 연결 자체를 하나의 개체로 보고 R·V·U를 그 개체의 속성(data slot)으로 두는 설계. Białas가 object slot을 관계로, data slot을 속성으로 구분한 방식을 응용했다. | E17: B04 / B06 | F17: =IFERROR(INDEX(인용근거!$E$5:$E$68,MATCH(LEFT(E17,3),인용근거!$A$5:$A$68,0)),"") -> i.e. relationships between an individual member of the given class (the object) and other individuals | G17: Białas는 이런 객체화를 하지 않았다.
A18: D14 | B18: 응답 9(해당 없음/모르겠음) | C18: 연구자 정의 | D18: 프로세스가 없거나 응답자가 알 수 없어 응답할 수 없는 경우. 점수 계산에서 결측으로 처리하며 "연결이 약함"과 구분한다. | E18: (없음) | F18: (해당 인용 없음)
A19: D15 | B19: 합의 판정(80%·20%) | C19: 인용 + 연구자 적용 | D19: 범주 1(80% 이상 채택), 범주 2(20~80% 토론), 범주 3(20% 미만 기각)의 3단계 판정. 본 연구는 전문가 맹검 재분류 일치율과 연결 타당도 판정에 같은 틀을 준용한다. | E19: A43 / A44 / A45 | F19: =IFERROR(INDEX(인용근거!$E$5:$E$68,MATCH(LEFT(E19,3),인용근거!$A$5:$A$68,0)),"") -> According to [32,33], the 80% threshold for consensus is commonly used and generally perceived as fair. | G19: Arias는 프로세스의 핵심 여부에 적용했고, 문항·연결에 적용하는 것은 연구자의 준용.
A20: D16 | B20: I-CVI 기준(0.78) | C20: 연구자 선택(관례) | D20: 전문가 6~10인 패널에서 적합도 3~4점 비율이 0.78 이상이면 채택하는 관례 기준. | E20: (없음) | F20: (해당 인용 없음) | G20: 두 논문에 근거 없음. 일반적 관례를 연구자가 선택.
A21: D17 | B21: Białas 차용 범위 | C21: 연구자 정의 | D21: 차용=방법(competency question, object slot의 domain/range, data slot, 개체=산출물, 검증 방식). 비차용=클래스 목록·관계 이름(BS 25999 기반). Białas는 BCMO가 프로토타입이며 실제 데이터 검증이 더 필요하다고 밝힌다. | E21: B15 / B14 / B02 / B04 / B05 / B06 / B08 | F21: =IFERROR(INDEX(인용근거!$E$5:$E$68,MATCH(LEFT(E21,3),인용근거!$A$5:$A$68,0)),"") -> compliant with the BS 25999 standard

Sheet 인용근거
A1: 인용 근거 라이브러리 — PDF 원문과 자동 대조한 인용문 64개
A2: 쪽 = PDF 쪽 번호(Arias는 저널 쪽 번호와 동일). 한국어 번역은 연구자 번역(참고용)이며 대조 대상이 아님.
A4: 인용ID | B4: 출처 | C4: PDF 쪽 | D4: 절 | E4: 원문(영어, verbatim) | F4: 한국어 번역(연구자 번역·참고) | G4: 사용처 | H4: 원문 대조
A5: A01 | B5: Arias | C5: 4 | D5: §2.1 | E5: Activities utilizing resources must be managed to convert inputs into outputs through a series of interconnected or interacting activities, also called processes | F5: 자원을 사용하는 활동은 입력을 출력으로 전환하는, 상호 연결되거나 상호작용하는 일련의 활동, 즉 프로세스를 통해 관리되어야 한다. | G5: 연계성 정의의 근거(프로세스 = 상호 연결·상호작용 활동) | H5: 일치 (2026-10-06)
A6: A02 | B6: Arias | C6: 5 | D6: §2.1 (ISO/IEC 33004 기준 4) | E6: A process reference model should delineate the interconnections among the processes outlined within it. | F6: 프로세스 참조모델은 그 안에 기술된 프로세스들 사이의 상호 연결을 명시해야 한다. | G6: 연계성 정의의 근거(프로세스 간 상호 연결 명시 요구) | H6: 일치 (2026-10-06)
A7: A03 | B7: Arias | C7: 3 | D7: §1 | E7: A detailed reference model outlining BCMS processes—including inputs, outputs, interfaces, and interactions at the activity level—facilitates optimal coordination of these processes. | F7: BCMS 프로세스를 활동 수준의 입력·출력·인터페이스·상호작용까지 상세히 기술한 참조모델은 이들 프로세스의 최적 조정을 촉진한다. | G7: 연계성 정의의 근거(입력·출력·인터페이스) | H7: 일치 (2026-10-06)
A8: A04 | B8: Arias | C8: 6 | D8: §2.2 (ISO 22301 Clause 4.4) | E8: taking into account their order, interactions, inputs, outputs, resources, and assigned roles | F8: (BCMS 프로세스를 정의·이행·유지할 때) 프로세스의 순서, 상호작용, 입력, 출력, 자원, 부여된 역할을 고려한다. | G8: 연계성 정의의 근거(ISO 22301 4.4) | H8: 일치 (2026-10-06)
A9: A05 | B9: Arias | C9: 2 | D9: §1 | E9: Organizations often struggle with performing a checklist approach regarding the BCMS requirements because it does not necessarily lead to a sustainable operated management system. | F9: 조직은 BCMS 요구사항에 대해 체크리스트 방식을 수행하는 데 종종 어려움을 겪는데, 이는 지속 가능하게 운영되는 경영시스템으로 반드시 이어지지 않기 때문이다. | G9: 연결 유지 정도를 측정하는 이유(체크리스트의 한계) | H9: 일치 (2026-10-06)
A10: A06 | B10: Arias | C10: 3-4 | D10: §1 | E10: including process descriptions (process profiles) and process flow charts, though the latter are omitted here to maintain the scope of the paper | F10: (참조모델 결과물에는) 프로세스 설명(프로세스 프로파일)과 프로세스 흐름도가 포함되나, 후자는 논문 범위 유지를 위해 여기서는 생략한다. | G10: 연결 목록이 이 논문에서 완전하지 않을 수 있는 근거 | H10: 일치 (2026-10-06)
A11: A07 | B11: Arias | C11: 18 | D11: §5 | E11: A key finding of this pilot initiative is the reinforcement of the systemic nature of the BCMS, emphasizing the interplay between processes and the roles within the BCMS framework. | F11: 이 시범사업의 핵심 발견은 BCMS의 체계적 성격이 강화되었다는 점이며, BCMS 틀 안에서 프로세스와 역할 간의 상호작용이 강조된다. | G11: 연계성이 BCMS 운영의 핵심 특성이라는 근거 | H11: 일치 (2026-10-06)
A12: A08 | B12: Arias | C12: 17 | D12: §5 | E12: An unmodified application of the BCMS process reference model is inadequate; customization of BCMS processes according to the organization's specific needs is imperative. | F12: BCMS 프로세스 참조모델을 수정 없이 적용하는 것은 부적절하며, 조직의 요구에 맞춘 BCMS 프로세스의 맞춤화가 필수적이다. | G12: 연결 목록의 조직별 조정 필요성 | H12: 일치 (2026-10-06)
A13: A09 | B13: Arias | C13: 10 | D13: Figure 4 | E13: Regularity – interrelated and interacting tasks are repeated on a regular basis. | F13: 규칙성 – 상호 관련되고 상호작용하는 과업이 정기적으로 반복된다. | G13: 종합 문항 G06 근거 | H13: 일치 (2026-10-06)
A14: A10 | B14: Arias | C14: 10 | D14: Figure 4 | E14: Accountability/responsibility – business continuity manager is the process owner or process manager and the process is a core competency of the BCMS. | F14: 책임성 – 업무연속성 관리자가 프로세스 소유자 또는 관리자이며 해당 프로세스는 BCMS의 핵심 역량이다. | G14: 종합 문항 G04 근거 | H14: 일치 (2026-10-06)
A15: A11 | B15: Arias | C15: 15 | D15: §4.3 | E15: These requirements inform processes such as business impact assessment and criticality analysis, risk assessment, internal audits, and supply chain management. | F15: 이 요구사항들은 BIA·중요도 분석, 리스크평가, 내부감사, 공급망관리와 같은 프로세스에 정보를 제공한다. | G15: L01, L02, L04, L05 | H15: 일치 (2026-10-06)
... A68: B16 | B68: Białas | C68: 4 | D68: §2.8 (Fig.1 설명) | E68: supportedByResource slot contains three individuals of resources used to manage and maintain BCMS within this organization | F68: supportedByResource slot은 이 조직 안에서 BCMS를 관리·유지하는 데 쓰이는 세 개의 자원 개체를 담는다. | G68: L10(자원이 BCMS를 지원한다는 구조) | H68: 일치 (2026-10-06)

Sheet 연결
A1: 연결 31개 — 인용 근거(파랑)와 연구자 의견(빨강)을 분리
A2: E1 직접 / E2 부분(연구자 보완) / E3 가정. 주 인용 원문은 인용근거 시트에서 자동으로 가져옴.
A4: ID | B4: 영역 | C4: 연결(S→T) | D4: 출발 S | E4: 도착 T | F4: 관계유형 | G4: 증거유형 | H4: 집단 | I4: 주 인용 ID | J4: 주 인용 원문(PDF 대조 완료) | K4: 보조 인용 ID | L4: 인용이 확립하는 사실 | M4: 연구자 의견: 해석·보완·가정 | N4: 연구자 의견: 측정 지표화(R/V/U) | O4: Białas 대응 | P4: 검증 필요 사항 | Q4: 문항 수 | R4: 점검
A5: L01 | B5: ① 요구·분석 | C5: REQ 요구사항관리 → BIA BIA·중요도 분석 | D5: REQ | E5: BIA | F5: informs | G5: E1 | I5: A11 | J5: =IFERROR(INDEX(인용근거!$E$5:$E$68,MATCH(LEFT(I5,3),인용근거!$A$5:$A$68,0)),"원문에 S→T 연결 서술 없음") -> These requirements inform processes such as business impact assessment and criticality analysis, risk assessment, internal audits, and supply chain management. | K5: (없음) | L5: 요구사항관리가 식별한 법규·규제·계약 요구사항이 BIA·중요도 분석 프로세스에 "정보를 제공(inform)"한다. | M5: "inform"을 "S의 산출물이 T의 입력·기준이 된다(informs)"로 해석. A11은 4개 프로세스를 한 문장으로 열거하므로 L01·L02·L04·L05는 이 문장에서 연구자가 분리한 연결. | N5: 반영=BIA의 우선순위·복구목표 설정에 요구사항이 사용된 증거 / 확인=BIA 결과의 요구사항 누락 점검 / 갱신=요구사항 변경 시 BIA 재검토 | O5: 해당 없음 | P5: 전문가 패널 연결 타당도 평가(요구사항이 BIA에 실제로 입력되는가) | Q5: =COUNTIF(문항!$D$5:$D$112,A5) -> 3 | R5: =IF(Q5=3,"OK","확인") -> OK
A6: L02 | B6: ① 요구·분석 | C6: REQ 요구사항관리 → RA 리스크평가 | D6: REQ | E6: RA | F6: informs | G6: E1 | I6: A11 | J6: =IFERROR(INDEX(인용근거!$E$5:$E$68,MATCH(LEFT(I6,3),인용근거!$A$5:$A$68,0)),"원문에 S→T 연결 서술 없음") -> These requirements inform processes such as business impact assessment and criticality analysis, risk assessment, internal audits, and supply chain management. | K6: (없음) | L6: 요구사항관리의 결과가 리스크평가 프로세스에 정보를 제공한다. | M6: 인용문 분리 사유는 L01과 동일. | N6: 반영=리스크평가의 범위·기준에 요구사항 사용 / 확인=요구사항 고려 여부 점검 / 갱신=요구사항 변경 시 리스크평가 기준·결과 재검토 | O6: 해당 없음 | P6: 전문가 패널 연결 타당도 평가 | Q6: =COUNTIF(문항!$D$5:$D$112,A6) -> 3 | R6: =IF(Q6=3,"OK","확인") -> OK
A7: L03 | B7: ① 요구·분석 | C7: BIA BIA·중요도 분석 → RA 리스크평가 | D7: BIA | E7: RA | F7: informs | G7: E1 | I7: A12 | J7: =IFERROR(INDEX(인용근거!$E$5:$E$68,MATCH(LEFT(I7,3),인용근거!$A$5:$A$68,0)),"원문에 S→T 연결 서술 없음") -> The risk assessment process, which focuses on identifying potential disruptions, relies on the outcomes of the business impact assessment and criticality analysis as its foundation. | K7: A13 | L7: 리스크평가는 BIA·중요도 분석의 결과를 기반(foundation)으로 삼는다. BIA의 최종 결과는 근거가 첨부된 문서화된 진술(업무연속성 요구사항)이다. | M7: "relies on ... as its foundation"을 informs(입력·기준)로 해석. | N7: 반영=리스크평가가 BIA의 핵심 활동 우선순위에서 출발 / 확인=평가 대상과 BIA 결과의 대조 / 갱신=BIA 결과 변경 시 리스크 목록 재검토 | O7: 해당 없음 | P7: 전문가 패널 연결 타당도 평가 | Q7: =COUNTIF(문항!$D$5:$D$112,A7) -> 3 | R7: =IF(Q7=3,"OK","확인") -> OK
A8: L04 | B8: ① 요구·분석 | C8: REQ 요구사항관리 → AUD 내부감사 | D8: REQ | E8: AUD | F8: informs | G8: E1 | I8: A11 | J8: =IFERROR(INDEX(인용근거!$E$5:$E$68,MATCH(LEFT(I8,3),인용근거!$A$5:$A$68,0)),"원문에 S→T 연결 서술 없음") -> These requirements inform processes such as business impact assessment and criticality analysis, risk assessment, internal audits, and supply chain management. | K8: (없음) | L8: 요구사항관리의 결과가 내부감사 프로세스에 정보를 제공한다. | M8: 인용문 분리 사유는 L01과 동일. 내부감사 기준에 요구사항이 포함된다는 구체적 형태는 연구자의 지표화. | N8: 반영=감사 기준·점검표에 요구사항 포함 / 확인=항목별 충족 확인 기록 / 갱신=요구사항 변경 시 감사 기준 재검토 | O8: 해당 없음 | P8: 전문가 패널 연결 타당도 평가 | Q8: =COUNTIF(문항!$D$5:$D$112,A8) -> 3 | R8: =IF(Q8=3,"OK","확인") -> OK
A9: L05 | B9: ① 요구·분석 | C9: REQ 요구사항관리 → SUP 공급망관리 | D9: REQ | E9: SUP | F9: informs | G9: E1 | I9: A11 | J9: =IFERROR(INDEX(인용근거!$E$5:$E$68,MATCH(LEFT(I9,3),인용근거!$A$5:$A$68,0)),"원문에 S→T 연결 서술 없음") -> These requirements inform processes such as business impact assessment and criticality analysis, risk assessment, internal audits, and supply chain management. | K9: A39 | L9: 요구사항관리의 결과가 공급망관리 프로세스에 정보를 제공한다. 외주 서비스는 업무연속성 관점에서 평가·분석·통제되어야 한다. | M9: 인용문 분리 사유는 L01과 동일. "공급업체 선정·계약 조건에 BC 요구사항 포함"은 A39(외주 서비스 통제)를 바탕으로 한 연구자의 지표화. | N9: 반영=공급업체 선정·계약 조건에 BC 요구사항 포함 / 확인=공급업체의 요구사항 충족 평가 / 갱신=요구사항 변경 시 요건·평가 재검토 | O9: 해당 없음 | P9: 전문가 패널 연결 타당도 평가 | Q9: =COUNTIF(문항!$D$5:$D$112,A9) -> 3 | R9: =IF(Q9=3,"OK","확인") -> OK
A10: L06 | B10: ② 전략·계획·이행 | C10: BIA BIA·중요도 분석 → STR BC 전략·솔루션 결정·선정 | D10: BIA | E10: STR | F10: informs | G10: E1 | I10: A14 | J10: =IFERROR(INDEX(인용근거!$E$5:$E$68,MATCH(LEFT(I10,3),인용근거!$A$5:$A$68,0)),"원문에 S→T 연결 서술 없음") -> After the completion of the business impact assessment and criticality analysis process, the approved business continuity requirements guide the determination and selection of suitable BC strategies and solutions | K10: A13 / A37 | L10: BIA·중요도 분석이 완료된 후, 승인된 업무연속성 요구사항이 BC 전략·솔루션의 결정·선정을 안내(guide)한다. BIA 결과는 경영진 승인을 거친다. | M10: "guide"를 informs(입력·기준)로 해석. | N10: 반영=전략·솔루션 선정 근거로 BIA 결과 사용 / 확인=선택안이 복구목표를 충족하는지 검증 / 갱신=BIA 결과 변경 시 전략·솔루션 재검토 | O10: 해당 없음 | P10: 전문가 패널 연결 타당도 평가 | Q10: =COUNTIF(문항!$D$5:$D$112,A10) -> 3 | R10: =IF(Q10=3,"OK","확인") -> OK
A11: L07 | B11: ② 전략·계획·이행 | C11: STR BC 전략·솔루션 결정·선정 → IMP 솔루션 이행관리 | D11: STR | E11: IMP | F11: elaboratedInto | G11: E1 | I11: A15 | J11: =IFERROR(INDEX(인용근거!$E$5:$E$68,MATCH(LEFT(I11,3),인용근거!$A$5:$A$68,0)),"원문에 S→T 연결 서술 없음") -> This process ensures that the BC strategies, solutions, and necessary changes are executed as planned. | K11: A36 | L11: 솔루션 이행관리 프로세스는 BC 전략·솔루션과 필요한 변경이 계획대로 실행되도록 보장하며, 이를 개시하고 검증한다. | M11: 인용문의 주어는 이행관리이고 대상은 전략·솔루션이므로 "STR이 IMP에서 구체화·실행된다"(STR→IMP)로 방향을 해석. A36의 "verifying"은 확인(V) 상태를 고안할 때 참고했으나 V의 정의는 연구자 정의. | N11: 반영=전략·솔루션이 담당·일정·예산이 있는 이행 활동으로 구체화 / 확인=구현 점검 / 갱신=전략·솔루션 수정 시 이행 계획 재검토 | O11: 해당 없음 | P11: 전문가 패널 연결 타당도 평가 | Q11: =COUNTIF(문항!$D$5:$D$112,A11) -> 3 | R11: =IF(Q11=3,"OK","확인") -> OK
A12: L08 | B12: ② 전략·계획·이행 | C12: STR BC 전략·솔루션 결정·선정 → PLAN BC 계획·절차 개발 | D12: STR | E12: PLAN | F12: elaboratedInto | G12: E1 | I12: A16 | J12: =IFERROR(INDEX(인용근거!$E$5:$E$68,MATCH(LEFT(I12,3),인용근거!$A$5:$A$68,0)),"원문에 S→T 연결 서술 없음") -> Corresponding BC plans and procedures, derived from the identified BC strategies and solutions, are developed within the process of developing BC plans and procedures. | K12: (없음) | L12: BC 계획·절차는 식별된 BC 전략·솔루션에서 도출(derived)되어 개발된다. | M12: "derived from"을 elaboratedInto(S의 내용이 T로 구체화됨)로 해석. | N12: 반영=계획·절차에 전략·솔루션의 가동 방법 포함 / 확인=승인 전 일치성 검토 / 갱신=전략·솔루션 변경 시 계획·절차 개정 | O12: 해당 없음 | P12: 전문가 패널 연결 타당도 평가 | Q12: =COUNTIF(문항!$D$5:$D$112,A12) -> 3 | R12: =IF(Q12=3,"OK","확인") -> OK
A13: L09 | B13: ② 전략·계획·이행 | C13: RA 리스크평가 → PLAN BC 계획·절차 개발 | D13: RA | E13: PLAN | F13: informs | G13: E1 | I13: A17 | J13: =IFERROR(INDEX(인용근거!$E$5:$E$68,MATCH(LEFT(I13,3),인용근거!$A$5:$A$68,0)),"원문에 S→T 연결 서술 없음") -> Furthermore, it includes risks associated with proposed changes, providing essential input for both communication activities and the development of business continuity plans and procedures. | K13: (없음) | L13: 리스크평가는 업무연속성 계획·절차 개발에 필수적인 입력(essential input)을 제공한다. | M13: A17의 주어 "it"이 리스크평가 프로세스임은 앞 문장의 주어에서 연구자가 확인한 지시 관계. | N13: 반영=계획·절차에 식별된 위협 시나리오 반영 / 확인=리스크 목록과 대조 / 갱신=리스크 변경 시 계획·절차 재검토 | O13: 해당 없음 | P13: 전문가 패널 연결 타당도 평가 | Q13: =COUNTIF(문항!$D$5:$D$112,A13) -> 3 | R13: =IF(Q13=3,"OK","확인") -> OK
A14: L10 | B14: ② 전략·계획·이행 | C14: RES 자원관리 → IMP 솔루션 이행관리 | D14: RES | E14: IMP | F14: supplies | G14: E2 | I14: A18 | J14: =IFERROR(INDEX(인용근거!$E$5:$E$68,MATCH(LEFT(I14,3),인용근거!$A$5:$A$68,0)),"원문에 S→T 연결 서술 없음") -> Outputs from this process include documented resources for implementing and running selected strategies, as well as resources for operating core BCMS processes, along with reports on resource utilization for BCMS core processes and the customer relationship management process | K14: A38 / B16 | L14: 자원관리의 산출물에는 선정된 전략의 이행·운영을 위한 문서화된 자원이 포함된다. 전략 실행에 필요한 자원은 자원관리에서 식별·배정·모니터링된다. | M14: [연구자 보완] 인용문은 "selected strategies의 implementing and running"을 위한 자원이라고만 쓰며 도착 프로세스를 특정하지 않는다. 이를 솔루션 이행관리(IMP)로 특정한 것은 연구자 해석(운영(running)은 IMP 외 프로세스일 수도 있음). | N14: 반영=솔루션 구현·운영에 필요한 자원이 문서로 확보·배정 / 확인=자원 충분성 확인 / 갱신=솔루션 변경 시 자원 배정 재검토 | O14: Białas는 supportedByResource slot으로 BCMS를 지원하는 자원 개체를 둔다(B16). 프로세스 간 연결은 아님. | P14: 전문가 패널에서 도착 프로세스(IMP)가 적절한지 평가. 부적절하면 도착을 "핵심 프로세스 전반"으로 변경 | Q14: =COUNTIF(문항!$D$5:$D$112,A14) -> 3 | R14: =IF(Q14=3,"OK","확인") -> OK
A15: L11 | B15: ③ 대응·복구·훈련 | C15: BIA BIA·중요도 분석 → RES 자원관리 | D15: BIA | E15: RES | F15: informs | G15: E3 | I15: (없음) | J15: =IFERROR(INDEX(인용근거!$E$5:$E$68,MATCH(LEFT(I15,3),인용근거!$A$5:$A$68,0)),"원문에 S→T 연결 서술 없음") -> 원문에 S→T 연결 서술 없음 | K15: B10 / B11 / A38 | L15: Białas는 BIA 보고서를 "서비스 재개에 필요한 자원"으로 질의하는 예를 보여 준다. Arias는 자원관리가 전략·BCMS 프로세스 실행에 필요한 자원을 식별한다고만 서술한다. | M15: [연구자 가정] BIA가 파악한 복구 필요 자원이 자원관리 계획에 투입된다는 연결은 Arias에 서술이 없다. Białas의 예는 프로세스 간 연결이 아니라 BIA 보고서 내부 속성(자원 항목)을 질의하는 수준이므로 유추 근거에 그친다. | N15: 반영=BIA의 복구 필요 자원이 자원 계획에 포함 / 확인=자원이 복구목표 달성에 충분한지 확인 / 갱신=BIA·복구목표 변경 시 자원 배정 재검토 | O15: Białas §2.8 Fig.4 설명(B10, B11): BIAreport의 resour4Resumption 속성 | P15: 전문가 합의 필수. 합의 80% 미만이면 삭제(Arias A44 판정 틀 준용) | Q15: =COUNTIF(문항!$D$5:$D$112,A15) -> 3 | R15: =IF(Q15=3,"OK","확인") -> OK
A16: L12 | B16: ③ 대응·복구·훈련 | C16: PLAN BC 계획·절차 개발 → INC 사고·비상 대응 | D16: PLAN | E16: INC | F16: elaboratedInto | G16: E2 | I16: A19 | J16: =IFERROR(INDEX(인용근거!$E$5:$E$68,MATCH(LEFT(I16,3),인용근거!$A$5:$A$68,0)),"원문에 S→T 연결 서술 없음") -> The activation of certain BC strategies and solutions is triggered when required, typically in response to a disruptive event, through the execution of BC plans and procedures. | K16: A20 | L16: BC 전략·솔루션의 가동은 중단 사건에 대응하여 BC 계획·절차의 실행을 통해 개시된다. 경보·커뮤니케이션은 조직의 BC 계획·절차 안에서 대응을 조정한다. | M16: [연구자 보완] 인용문은 "BC 계획·절차가 중단 사건 대응 시 실행된다"고 쓰지만 도착 프로세스를 "사고·비상 대응"으로 명시하지 않는다. 사고·비상 대응이 "중단 사건 관리의 포괄적 접근"을 정의한다는 같은 쪽 서술과 결합해 PLAN→INC로 해석. | N16: 반영=사고 대응 체계(역할·가동 기준)가 계획에 따라 정해짐 / 확인=실제·모의 사고에서 계획대로 대응했는지 확인 / 갱신=계획 변경 시 사고대응 체계 재검토 | O16: 해당 없음 | P16: 전문가 패널 연결 타당도 평가 | Q16: =COUNTIF(문항!$D$5:$D$112,A16) -> 3 | R16: =IF(Q16=3,"OK","확인") -> OK
... A30: L26 | B30: ⑤ 거버넌스·이해관계자 | C30: CHG BC 변경관리 → EXE BC 계획·절차 훈련·연습 | D30: CHG | E30: EXE | F30: updates | G30: E1 | I30: A29 | J30: =IFERROR(INDEX(인용근거!$E$5:$E$68,MATCH(LEFT(I30,3),인용근거!$A$5:$A$68,0)),"원문에 S→T 연결 서술 없음") -> The results of changes to the incident and emergency handling process or the process of exercising BC plans and procedures—as those processes initiated them. | K30: (없음) | L30: 변경의 결과가 BC 계획·절차 훈련·연습 프로세스로 돌아간다. | M30: 분리 사유는 L23과 동일. | N30: 반영=승인된 변경이 연습 절차·시나리오에 반영 / 확인=반영 확인 / 갱신=변경 승인마다 연습 절차 재검토 | O30: 해당 없음 | P30: 전문가 패널 연결 타당도 평가 | Q30: =COUNTIF(문항!$D$5:$D$112,A30) -> 3 | R30: =IF(Q30=3,"OK","확인") -> OK
A31: L27 | B31: ⑤ 거버넌스·이해관계자 | C31: 핵심 BCMS 프로세스 전반(집단) → COM 협의·커뮤니케이션 | D31: CORE | E31: COM | F31: informs | G31: E1 | H31: 집단 | I31: A30 | J31: =IFERROR(INDEX(인용근거!$E$5:$E$68,MATCH(LEFT(I31,3),인용근거!$A$5:$A$68,0)),"원문에 S→T 연결 서술 없음") -> The outcomes of nearly all BCMS processes are communicated centrally to stakeholders external to the BCMS as part of the consultation and communication process. | K31: A40 | L31: 거의 모든 BCMS 프로세스의 결과가 협의·커뮤니케이션 프로세스를 통해 BCMS 외부 이해관계자에게 중앙에서 전달된다. | M31: [연구자 판단] "nearly all BCMS processes"는 프로세스를 열거하지 않으므로 출발점을 집단 노드 CORE("핵심 BCMS 프로세스 전반")로 처리했다. CORE는 Arias의 객체가 아니라 연구자가 만든 가상 노드이다. | N31: 반영=BCMS 주요 결과가 이해관계자 협의 채널로 전달 / 확인=이해·의견 접수 확인 / 갱신=결과가 크게 바뀌면 전달 내용 재검토 | O31: 해당 없음 | P31: 전문가 패널에서 집단 출발점 처리의 적절성 평가 | Q31: =COUNTIF(문항!$D$5:$D$112,A31) -> 3 | R31: =IF(Q31=3,"OK","확인") -> OK
A32: L28 | B32: ⑤ 거버넌스·이해관계자 | C32: COM 협의·커뮤니케이션 → GOV BC 거버넌스 | D32: COM | E32: GOV | F32: informs | G32: E1 | I32: A31 | J32: =IFERROR(INDEX(인용근거!$E$5:$E$68,MATCH(LEFT(I32,3),인용근거!$A$5:$A$68,0)),"원문에 S→T 연결 서술 없음") -> These reports and identified requirements serve as inputs for the BC governance process. | K32: A47 | L32: 협의·커뮤니케이션의 보고와 식별된 요구사항은 BC 거버넌스 프로세스의 입력으로 쓰인다. | M32: "These reports"는 앞 문장(리스크와 BC 관리 보고의 커뮤니케이션)을 가리킨다고 연구자가 확인(A47). | N32: 반영=보고·요구사항이 경영진 검토·의사결정의 입력 / 확인=경영진 검토·결정 기록 / 갱신=새 보고·요구사항 접수 시 검토 안건 재검토 | O32: 해당 없음 | P32: 전문가 패널 연결 타당도 평가 | Q32: =COUNTIF(문항!$D$5:$D$112,A32) -> 3 | R32: =IF(Q32=3,"OK","확인") -> OK
A33: L29 | B33: ⑤ 거버넌스·이해관계자 | C33: GOV BC 거버넌스 → POL BC 정책관리 | D33: GOV | E33: POL | F33: elaboratedInto | G33: E3 | I33: (없음) | J33: =IFERROR(INDEX(인용근거!$E$5:$E$68,MATCH(LEFT(I33,3),인용근거!$A$5:$A$68,0)),"원문에 S→T 연결 서술 없음") -> 원문에 S→T 연결 서술 없음 | K33: A33 / A34 / A35 / B13 | L33: Arias는 거버넌스(BCMS가 이해관계자의 목표·요구에 부합하도록 보장)와 정책관리(정책의 개발·유지·보존, 접근·이해 보장)를 각각 서술할 뿐 두 프로세스의 관계는 서술하지 않는다. Białas는 목표(objectives)와 정책(policy)을 "Plan" 단계의 병렬 항목으로 나열한다. | M33: [연구자 가정] 정책이 경영진이 정한 BC 목표·방향에서 도출된다는 연결은 두 논문에 근거가 없다(이를 뒷받침하는 인용이 두 논문에 없음). 또한 Białas에서는 정책과 목표가 형제 항목이므로 Białas는 이 연결을 지지하지 않는다. | N33: 반영=BC 정책이 경영진의 BC 목표·방향 반영 / 확인=승인 절차로 일치 확인 / 갱신=목표·방향 변경 시 정책 개정·공지 | O33: Białas §2.8 Fig.2 설명(B13): 목표와 정책이 같은 Plan 단계의 병렬 항목 | P33: 전문가 합의 필수. 합의 80% 미만이면 삭제 | Q33: =COUNTIF(문항!$D$5:$D$112,A33) -> 3 | R33: =IF(Q33=3,"OK","확인") -> OK
A34: L30 | B34: ⑤ 거버넌스·이해관계자 | C34: RES 자원관리 → 핵심 BCMS 프로세스 전반(집단) | D34: RES | E34: CORE | F34: supplies | G34: E1 | H34: 집단 | I34: A18 | J34: =IFERROR(INDEX(인용근거!$E$5:$E$68,MATCH(LEFT(I34,3),인용근거!$A$5:$A$68,0)),"원문에 S→T 연결 서술 없음") -> Outputs from this process include documented resources for implementing and running selected strategies, as well as resources for operating core BCMS processes, along with reports on resource utilization for BCMS core processes and the customer relationship management process | K34: A38 | L34: 자원관리의 산출물에는 핵심 BCMS 프로세스 운영을 위한 자원과 BCMS 핵심 프로세스에 대한 자원 사용 보고가 포함된다. | M34: [연구자 판단] 도착이 "핵심 BCMS 프로세스(복수)"이므로 집단 노드 CORE를 사용(L27과 동일 사유). | N34: 반영=핵심 프로세스에 자원 제공·사용 보고 / 확인=보고서로 사용 확인 / 갱신=사용 보고 결과에 따라 자원 배분 재검토 | O34: 해당 없음 | P34: 전문가 패널에서 집단 도착점 처리의 적절성 평가 | Q34: =COUNTIF(문항!$D$5:$D$112,A34) -> 3 | R34: =IF(Q34=3,"OK","확인") -> OK
A35: L31 | B35: ⑤ 거버넌스·이해관계자 | C35: RES 자원관리 → CRM 고객관계관리 | D35: RES | E35: CRM | F35: supplies | G35: E1 | I35: A18 | J35: =IFERROR(INDEX(인용근거!$E$5:$E$68,MATCH(LEFT(I35,3),인용근거!$A$5:$A$68,0)),"원문에 S→T 연결 서술 없음") -> Outputs from this process include documented resources for implementing and running selected strategies, as well as resources for operating core BCMS processes, along with reports on resource utilization for BCMS core processes and the customer relationship management process | K35: A32 | L35: 자원관리의 산출물에는 고객관계관리 프로세스에 대한 자원 사용 보고가 포함된다. 고객관계관리는 고객 만족의 운영적 관리와 BC 투자 가치의 지속적 입증을 수행한다. | M35: R 문항의 "BC 투자 가치 입증"은 CRM의 기능을 서술한 A32를 문항 문구에 반영한 연구자의 지표화이며, 인용문이 "자원 보고가 가치 입증에 쓰인다"고 직접 말하는 것은 아니다. | N35: 반영=자원 사용 보고가 고객관계관리에 제공·활용 / 확인=보고의 충분성 확인 / 갱신=사용 현황 변경 시 보고 재검토 | O35: 해당 없음 | P35: 전문가 패널 연결 타당도 평가 | Q35: =COUNTIF(문항!$D$5:$D$112,A35) -> 3 | R35: =IF(Q35=3,"OK","확인") -> OK

Sheet 관계유형
A1: 관계유형 7개 — 연구자 정의(S→T 방향으로 읽음)
A2: Białas의 관계 이름(hasBCplan 등)은 구성 관계 위주여서 쓰지 않고, 연결의 의미를 구분하기 위해 연구자가 정의했다.
A4: ID | B4: 관계유형 | C4: 정의(S→T) | D4: 판정 질문 | E4: 해당 연결
A5: RT01 | B5: informs | C5: S의 산출물이 T의 입력·기준·근거가 된다. | D5: T를 수행할 때 S의 산출물이 필요한가? | E5: L01~L06, L09, L11, L17, L18~L20, L27, L28
A6: RT02 | B6: elaboratedInto | C6: S의 내용이 T로 구체화·도출·실행된다. | D6: T의 내용은 S에서 도출되는가(S가 바뀌면 T를 다시 써야 하는가)? | E6: L07, L08, L12, L29
A7: RT03 | B7: testedBy | C7: S가 T에 의해 시험·검증된다. | D7: T가 S의 유효성을 평가하는가? | E7: L15
A8: RT04 | B8: updates | C8: S의 결과·승인된 변경이 T의 내용을 개정·갱신한다. | D8: S의 결과가 T의 문서·절차를 바꾸는가? | E8: L16, L22, L25, L26
A9: RT05 | B9: triggers | C9: S의 사건·결과가 T의 수행을 개시한다. | D9: S가 일어나면 T가 시작되는가? | E9: L21, L23, L24
A10: RT06 | B10: contains | C10: T는 S의 하위 프로세스이다. | D10: T가 S의 일부로서 S 안에서 수행되는가? | E10: L13, L14
A11: RT07 | B11: supplies | C11: S가 T에 자원 또는 자원 관련 보고를 제공한다. | D11: T가 S로부터 자원 또는 자원 사용 보고를 받는가? | E11: L10, L30, L31

Sheet 보류연결
A1: 보류·제외한 후보 연결 — 채택하지 않은 이유
A2: 연구자 결정란에 포함/제외를 직접 기록(노란 칸)
A4: ID | B4: 출발 | C4: 도착 | D4: 후보 내용 | E4: 채택하지 않은 이유(인용 근거 부재) | F4: 권고 | G4: 연구자 결정
A5: H01 | B5: INC | C5: PLAN | D5: 사고 대응 경험을 BC 계획·절차 개정에 반영 | E5: Arias에는 연습(EXE)→계획(L16)만 서술되고 사고 대응→계획 환류는 서술이 없음. 사고 결과는 변경관리(L23)를 거쳐 반영되는 경로만 근거가 있음. | F5: 연구자 결정 필요
A6: H02 | B6: RA | C6: CHG | D6: 리스크평가 결과를 변경 판단에 사용 | E6: A26의 "for and from the risk assessment process"는 양방향을 시사하나 방향이 문장에서 분리되지 않음. 현재는 CHG→RA(L21)만 채택. | F6: 연구자 결정 필요
A7: H03 | B7: EXE | C7: AWR | D7: 연습 결과를 교육 내용에 반영 | E7: 두 논문에 서술 없음. L17(PLAN→AWR)과 중복 가능성. | F7: 제외 권고
A8: H04 | B8: GOV | C8: CRM | D8: 거버넌스와 고객관계관리의 관계 | E8: A32는 두 프로세스를 "In addition to"로 병렬 서술할 뿐 연결을 서술하지 않음. | F8: 제외 권고
A9: H05 | B9: CI | C9: PERF | D9: 개선 결과를 성과평가 지표에 반영 | E9: A25는 성과평가→개선 방향만 서술. 개선 후 지표 갱신은 서술 없음. | F9: 제외 권고
A10: H06 | B10: DOC | C10: 전 프로세스 | D10: 문서화된 정보 통제가 모든 프로세스를 지원 | E10: A41은 정보 통제의 내용만 서술하고 프로세스별 연결은 CHG→DOC(L22)만 서술. | F10: 제외 권고

Sheet 객체
A1: 객체 — Arias Table 5의 22개 BCMS 프로세스
A2: 범주·PDCA·재난관리주기: Table 5(p.14) / 전문가 지명률: Table 2–4(pp.11–13, 전문가 39명) / 대표 산출물: 연구자 제안
A4: ID | B4: 프로세스(한글) | C4: Arias 원문 이름 | D4: 범주 | E4: PDCA | F4: 재난관리주기 | G4: 전문가 지명률(%) | H4: Arias 합의 구분(80/20) | I4: 대표 산출물(연구자 제안) | J4: 관련 연결 수
A5: GOV | B5: BC 거버넌스 | C5: Business continuity governance process | D5: 관리 | E5: - | F5: - | G5: 90 | H5: =IF(G5>=80,"범주 1 (채택)",IF(G5>=20,"범주 2 (토론)","범주 3 (기각)")) -> 범주 1 (채택) | I5: 경영진 검토 결과 | J5: =COUNTIF(연결!$D$5:$D$35,A5)+COUNTIF(연결!$E$5:$E$35,A5) -> 2
A6: POL | B6: BC 정책관리 | C6: Business continuity policy management process | D6: 핵심 | E6: Plan | F6: Mitigation | G6: 87 | H6: =IF(G6>=80,"범주 1 (채택)",IF(G6>=20,"범주 2 (토론)","범주 3 (기각)")) -> 범주 1 (채택) | I6: BC 정책 | J6: =COUNTIF(연결!$D$5:$D$35,A6)+COUNTIF(연결!$E$5:$E$35,A6) -> 1
A7: REQ | B7: 요구사항관리 | C7: Requirements management process | D7: 핵심 | E7: Plan | F7: Mitigation | G7: 74 | H7: =IF(G7>=80,"범주 1 (채택)",IF(G7>=20,"범주 2 (토론)","범주 3 (기각)")) -> 범주 2 (토론) | I7: 법규·계약 요구사항 목록 | J7: =COUNTIF(연결!$D$5:$D$35,A7)+COUNTIF(연결!$E$5:$E$35,A7) -> 4
A8: BIA | B8: BIA·중요도 분석 | C8: Business impact assessment and criticality analysis process | D8: 핵심 | E8: Plan | F8: Mitigation | G8: 100 | H8: =IF(G8>=80,"범주 1 (채택)",IF(G8>=20,"범주 2 (토론)","범주 3 (기각)")) -> 범주 1 (채택) | I8: BIA 결과(문서화된 업무연속성 요구사항) | J8: =COUNTIF(연결!$D$5:$D$35,A8)+COUNTIF(연결!$E$5:$E$35,A8) -> 4
A9: RA | B9: 리스크평가 | C9: Risk assessment process (for risks of disruption) | D9: 핵심 | E9: Plan | F9: Mitigation | G9: 90 | H9: =IF(G9>=80,"범주 1 (채택)",IF(G9>=20,"범주 2 (토론)","범주 3 (기각)")) -> 범주 1 (채택) | I9: 리스크 카탈로그 | J9: =COUNTIF(연결!$D$5:$D$35,A9)+COUNTIF(연결!$E$5:$E$35,A9) -> 4
A10: STR | B10: BC 전략·솔루션 결정·선정 | C10: Process of determining and selecting BC strategies and solutions | D10: 핵심 | E10: Plan | F10: Mitigation | G10: 74 | H10: =IF(G10>=80,"범주 1 (채택)",IF(G10>=20,"범주 2 (토론)","범주 3 (기각)")) -> 범주 2 (토론) | I10: 선정된 BC 전략·솔루션 | J10: =COUNTIF(연결!$D$5:$D$35,A10)+COUNTIF(연결!$E$5:$E$35,A10) -> 3
A11: PLAN | B11: BC 계획·절차 개발 | C11: Process of developing BC plans and procedures | D11: 핵심 | E11: Plan | F11: Mitigation | G11: 69 | H11: =IF(G11>=80,"범주 1 (채택)",IF(G11>=20,"범주 2 (토론)","범주 3 (기각)")) -> 범주 2 (토론) | I11: BC 계획·절차 | J11: =COUNTIF(연결!$D$5:$D$35,A11)+COUNTIF(연결!$E$5:$E$35,A11) -> 6
A12: IMP | B12: 솔루션 이행관리 | C12: Solution implementation management process | D12: 핵심 | E12: Do | F12: Preparedness | G12: 69 | H12: =IF(G12>=80,"범주 1 (채택)",IF(G12>=20,"범주 2 (토론)","범주 3 (기각)")) -> 범주 2 (토론) | I12: 구현된 솔루션 | J12: =COUNTIF(연결!$D$5:$D$35,A12)+COUNTIF(연결!$E$5:$E$35,A12) -> 2
A13: INC | B13: 사고·비상 대응 | C13: Incident and emergency handling process | D13: 핵심 | E13: Do | F13: Response | G13: 100 | H13: =IF(G13>=80,"범주 1 (채택)",IF(G13>=20,"범주 2 (토론)","범주 3 (기각)")) -> 범주 1 (채택) | I13: 사고 대응 기록 | J13: =COUNTIF(연결!$D$5:$D$35,A13)+COUNTIF(연결!$E$5:$E$35,A13) -> 5
A14: EXE | B14: BC 계획·절차 훈련·연습 | C14: Process of exercising BC plans and procedures | D14: 핵심 | E14: Do | F14: Preparedness | G14: 100 | H14: =IF(G14>=80,"범주 1 (채택)",IF(G14>=20,"범주 2 (토론)","범주 3 (기각)")) -> 범주 1 (채택) | I14: 연습 결과 | J14: =COUNTIF(연결!$D$5:$D$35,A14)+COUNTIF(연결!$E$5:$E$35,A14) -> 4
A15: AWR | B15: 인식·역량·교육 | C15: Awareness, competence, and training process | D15: 핵심 | E15: Do | F15: Preparedness | G15: 95 | H15: =IF(G15>=80,"범주 1 (채택)",IF(G15>=20,"범주 2 (토론)","범주 3 (기각)")) -> 범주 1 (채택) | I15: 교육 프로그램·기록 | J15: =COUNTIF(연결!$D$5:$D$35,A15)+COUNTIF(연결!$E$5:$E$35,A15) -> 1
A16: SUP | B16: 공급망관리 | C16: Supply chain management process | D16: 핵심 | E16: Do | F16: Preparedness | G16: 90 | H16: =IF(G16>=80,"범주 1 (채택)",IF(G16>=20,"범주 2 (토론)","범주 3 (기각)")) -> 범주 1 (채택) | I16: 공급업체 평가 결과 | J16: =COUNTIF(연결!$D$5:$D$35,A16)+COUNTIF(연결!$E$5:$E$35,A16) -> 2
... A26: CRM | B26: 고객관계관리 | C26: Customer relationship management process | D26: 지원 | E26: - | F26: - | G26: 3 | H26: =IF(G26>=80,"범주 1 (채택)",IF(G26>=20,"범주 2 (토론)","범주 3 (기각)")) -> 범주 3 (기각) | I26: 고객 만족·가치 입증 보고 | J26: =COUNTIF(연결!$D$5:$D$35,A26)+COUNTIF(연결!$E$5:$E$35,A26) -> 1
A28: 주: 지명률 합의 구분은 참고용이다. Arias는 합의에 미달한 프로세스도 ISO 22301 요건(A45)을 이유로 핵심 프로세스로 유지했고, CRM(3%)도 참조모델에 포함해야 한다고 보았다(p.13). "BCMS 계획"은 프로젝트로 분류되어 제외했다(A48).

Sheet 트리플
A1: 온톨로지 트리플(주어–관계–목적어)
A2: 관계 트리플은 S—relation→T. ProcessLink 트리플은 연결을 개체로 보고 R·V·U 문항을 연결(Białas의 data slot 응용, 연구자 설계).
A4: 주어 | B4: 관계 | C4: 목적어 | D4: 연결 ID | E4: 증거유형 | F4: 구분
A5: REQ | B5: informs | C5: BIA | D5: L01 | E5: E1 | F5: 프로세스 관계
A6: REQ | B6: informs | C6: RA | D6: L02 | E6: E1 | F6: 프로세스 관계
A7: BIA | B7: informs | C7: RA | D7: L03 | E7: E1 | F7: 프로세스 관계
A8: REQ | B8: informs | C8: AUD | D8: L04 | E8: E1 | F8: 프로세스 관계
A9: REQ | B9: informs | C9: SUP | D9: L05 | E9: E1 | F9: 프로세스 관계
A10: BIA | B10: informs | C10: STR | D10: L06 | E10: E1 | F10: 프로세스 관계
A11: STR | B11: elaboratedInto | C11: IMP | D11: L07 | E11: E1 | F11: 프로세스 관계
A12: STR | B12: elaboratedInto | C12: PLAN | D12: L08 | E12: E1 | F12: 프로세스 관계
A13: RA | B13: informs | C13: PLAN | D13: L09 | E13: E1 | F13: 프로세스 관계
A14: RES | B14: supplies | C14: IMP | D14: L10 | E14: E2 | F14: 프로세스 관계
A15: BIA | B15: informs | C15: RES | D15: L11 | E15: E3 | F15: 프로세스 관계
... A252: Link_L31 | B252: updated | C252: L31-U | D252: L31 | E252: E1 | F252: ProcessLink 객체

Sheet 관계매트릭스
A1: 관계 매트릭스 — 행(출발 S) → 열(도착 T)
A2: 셀 = 연결 ID, 굵은 글씨 = E1, 이탤릭 = E2, 빨간 글씨 = E3. CORE = 집단 노드(연구자 생성)
B4: GOV | C4: POL | D4: REQ | E4: BIA | F4: RA | G4: STR | H4: PLAN | I4: IMP | J4: INC | K4: EXE | L4: AWR | M4: SUP | N4: AUD | O4: PERF | P4: CI | Q4: CHG | R4: WARN | S4: REC | T4: DOC | U4: RES | V4: COM | W4: CRM | X4: CORE
A5: GOV | C5: L29
A6: POL
A7: REQ | E7: L01 | F7: L02 | M7: L05 | N7: L04
A8: BIA | F8: L03 | G8: L06 | U8: L11
A9: RA | H9: L09
A10: STR | H10: L08 | I10: L07
A11: PLAN | J11: L12 | K11: L15 | L11: L17
A12: IMP
A13: INC | Q13: L23 | R13: L13 | S13: L14
A14: EXE | H14: L16 | Q14: L24
A15: AWR
A16: SUP | P16: L20
A17: AUD | P17: L19
A18: PERF | P18: L18
A19: CI
A20: CHG | F20: L21 | J20: L25 | K20: L26 | T20: L22
A21: WARN
A22: REC
A23: DOC
A24: RES | I24: L10 | W24: L31 | X24: L30
A25: COM | B25: L28
A26: CRM
A27: CORE | V27: L27

Sheet 온톨로지맵
A1: 온톨로지 맵 V2 — 22개 프로세스와 31개 연결
A2: 그림 파일: outputs/BCMS_온톨로지맵_V2.png · 선 모양 = 증거유형(실선 E1 / 파선 E2 / 점선 E3)

Sheet 문항
A1: 문항은행 108문항 (연결 93 + 종합 6 + 검증 9)
A2: 연결 문항은 모두 "연구자 문항화"이며, 연결의 근거는 연결 시트의 인용을 따른다. 전문가 6인의 적합도(1~4)를 L~Q열에 입력.
A4: 문항ID | B4: 파트 | C4: 영역 | D4: 연결ID | E4: 연결(S→T) | F4: 상태 | G4: 문항 | H4: 증거유형 | I4: 역문항 | J4: 응답입력 열 | K4: 근거 구분 | L4: 전문가1 | M4: 전문가2 | N4: 전문가3 | O4: 전문가4 | P4: 전문가5 | Q4: 전문가6 | R4: I-CVI | S4: 판정
A5: L01-R | B5: C 연결 | C5: ① 요구·분석 | D5: L01 | E5: =IFERROR(INDEX(연결!$C$5:$C$35,MATCH(D5,연결!$A$5:$A$35,0)),"") -> REQ 요구사항관리 → BIA BIA·중요도 분석 | F5: 반영 | G5: 요구사항관리에서 정리한 법규·규제·계약상 요구사항이 BIA의 우선순위와 복구목표 설정에 실제로 사용된다. | H5: =IFERROR(INDEX(연결!$G$5:$G$35,MATCH(D5,연결!$A$5:$A$35,0)),"") -> E1 | J5: AH | K5: 연구자 의견(문항화) | R5: =IFERROR(COUNTIF(L5:Q5,">=3")/COUNT(L5:Q5),"") | S5: =IF(R5="","",IF(R5>=검증!$B$4,"채택","수정·토론"))
A6: L01-V | B6: C 연결 | C6: ① 요구·분석 | D6: L01 | E6: =IFERROR(INDEX(연결!$C$5:$C$35,MATCH(D6,연결!$A$5:$A$35,0)),"") -> REQ 요구사항관리 → BIA BIA·중요도 분석 | F6: 확인 | G6: BIA 결과가 요구사항을 빠짐없이 반영했는지 검토 또는 점검 기록으로 확인한다. | H6: =IFERROR(INDEX(연결!$G$5:$G$35,MATCH(D6,연결!$A$5:$A$35,0)),"") -> E1 | J6: AI | K6: 연구자 의견(문항화) | R6: =IFERROR(COUNTIF(L6:Q6,">=3")/COUNT(L6:Q6),"") | S6: =IF(R6="","",IF(R6>=검증!$B$4,"채택","수정·토론"))
A7: L01-U | B7: C 연결 | C7: ① 요구·분석 | D7: L01 | E7: =IFERROR(INDEX(연결!$C$5:$C$35,MATCH(D7,연결!$A$5:$A$35,0)),"") -> REQ 요구사항관리 → BIA BIA·중요도 분석 | F7: 갱신 | G7: 요구사항이 바뀌면 BIA 결과를 다시 검토하고 필요하면 고친다. | H7: =IFERROR(INDEX(연결!$G$5:$G$35,MATCH(D7,연결!$A$5:$A$35,0)),"") -> E1 | J7: AJ | K7: 연구자 의견(문항화) | R7: =IFERROR(COUNTIF(L7:Q7,">=3")/COUNT(L7:Q7),"") | S7: =IF(R7="","",IF(R7>=검증!$B$4,"채택","수정·토론"))
A8: L02-R | B8: C 연결 | C8: ① 요구·분석 | D8: L02 | E8: =IFERROR(INDEX(연결!$C$5:$C$35,MATCH(D8,연결!$A$5:$A$35,0)),"") -> REQ 요구사항관리 → RA 리스크평가 | F8: 반영 | G8: 요구사항이 리스크평가의 범위와 평가 기준에 실제로 사용된다. | H8: =IFERROR(INDEX(연결!$G$5:$G$35,MATCH(D8,연결!$A$5:$A$35,0)),"") -> E1 | J8: AK | K8: 연구자 의견(문항화) | R8: =IFERROR(COUNTIF(L8:Q8,">=3")/COUNT(L8:Q8),"") | S8: =IF(R8="","",IF(R8>=검증!$B$4,"채택","수정·토론"))
A9: L02-V | B9: C 연결 | C9: ① 요구·분석 | D9: L02 | E9: =IFERROR(INDEX(연결!$C$5:$C$35,MATCH(D9,연결!$A$5:$A$35,0)),"") -> REQ 요구사항관리 → RA 리스크평가 | F9: 확인 | G9: 리스크평가가 관련 요구사항을 고려했는지 확인하는 절차가 있다. | H9: =IFERROR(INDEX(연결!$G$5:$G$35,MATCH(D9,연결!$A$5:$A$35,0)),"") -> E1 | J9: AL | K9: 연구자 의견(문항화) | R9: =IFERROR(COUNTIF(L9:Q9,">=3")/COUNT(L9:Q9),"") | S9: =IF(R9="","",IF(R9>=검증!$B$4,"채택","수정·토론"))
A10: L02-U | B10: C 연결 | C10: ① 요구·분석 | D10: L02 | E10: =IFERROR(INDEX(연결!$C$5:$C$35,MATCH(D10,연결!$A$5:$A$35,0)),"") -> REQ 요구사항관리 → RA 리스크평가 | F10: 갱신 | G10: 요구사항이 바뀌면 리스크평가 기준이나 결과를 다시 검토하고 고친다. | H10: =IFERROR(INDEX(연결!$G$5:$G$35,MATCH(D10,연결!$A$5:$A$35,0)),"") -> E1 | J10: AM | K10: 연구자 의견(문항화) | R10: =IFERROR(COUNTIF(L10:Q10,">=3")/COUNT(L10:Q10),"") | S10: =IF(R10="","",IF(R10>=검증!$B$4,"채택","수정·토론"))
A11: L03-R | B11: C 연결 | C11: ① 요구·분석 | D11: L03 | E11: =IFERROR(INDEX(연결!$C$5:$C$35,MATCH(D11,연결!$A$5:$A$35,0)),"") -> BIA BIA·중요도 분석 → RA 리스크평가 | F11: 반영 | G11: 리스크평가는 BIA에서 정한 핵심 제품·서비스·활동의 우선순위를 출발점으로 한다. | H11: =IFERROR(INDEX(연결!$G$5:$G$35,MATCH(D11,연결!$A$5:$A$35,0)),"") -> E1 | J11: AN | K11: 연구자 의견(문항화) | R11: =IFERROR(COUNTIF(L11:Q11,">=3")/COUNT(L11:Q11),"") | S11: =IF(R11="","",IF(R11>=검증!$B$4,"채택","수정·토론"))
A12: L03-V | B12: C 연결 | C12: ① 요구·분석 | D12: L03 | E12: =IFERROR(INDEX(연결!$C$5:$C$35,MATCH(D12,연결!$A$5:$A$35,0)),"") -> BIA BIA·중요도 분석 → RA 리스크평가 | F12: 확인 | G12: 리스크평가 대상이 BIA 결과와 일치하는지 대조하여 확인한다. | H12: =IFERROR(INDEX(연결!$G$5:$G$35,MATCH(D12,연결!$A$5:$A$35,0)),"") -> E1 | J12: AO | K12: 연구자 의견(문항화) | R12: =IFERROR(COUNTIF(L12:Q12,">=3")/COUNT(L12:Q12),"") | S12: =IF(R12="","",IF(R12>=검증!$B$4,"채택","수정·토론"))
A13: L03-U | B13: C 연결 | C13: ① 요구·분석 | D13: L03 | E13: =IFERROR(INDEX(연결!$C$5:$C$35,MATCH(D13,연결!$A$5:$A$35,0)),"") -> BIA BIA·중요도 분석 → RA 리스크평가 | F13: 갱신 | G13: BIA 결과가 바뀌면 리스크평가 결과(리스크 목록)를 다시 검토하고 고친다. | H13: =IFERROR(INDEX(연결!$G$5:$G$35,MATCH(D13,연결!$A$5:$A$35,0)),"") -> E1 | J13: AP | K13: 연구자 의견(문항화) | R13: =IFERROR(COUNTIF(L13:Q13,">=3")/COUNT(L13:Q13),"") | S13: =IF(R13="","",IF(R13>=검증!$B$4,"채택","수정·토론"))
A14: L04-R | B14: C 연결 | C14: ① 요구·분석 | D14: L04 | E14: =IFERROR(INDEX(연결!$C$5:$C$35,MATCH(D14,연결!$A$5:$A$35,0)),"") -> REQ 요구사항관리 → AUD 내부감사 | F14: 반영 | G14: 내부감사의 점검 기준에 BC 관련 요구사항이 포함된다. | H14: =IFERROR(INDEX(연결!$G$5:$G$35,MATCH(D14,연결!$A$5:$A$35,0)),"") -> E1 | J14: AQ | K14: 연구자 의견(문항화) | R14: =IFERROR(COUNTIF(L14:Q14,">=3")/COUNT(L14:Q14),"") | S14: =IF(R14="","",IF(R14>=검증!$B$4,"채택","수정·토론"))
A15: L04-V | B15: C 연결 | C15: ① 요구·분석 | D15: L04 | E15: =IFERROR(INDEX(연결!$C$5:$C$35,MATCH(D15,연결!$A$5:$A$35,0)),"") -> REQ 요구사항관리 → AUD 내부감사 | F15: 확인 | G15: 감사에서 요구사항 충족 여부를 항목별로 확인하고 기록한다. | H15: =IFERROR(INDEX(연결!$G$5:$G$35,MATCH(D15,연결!$A$5:$A$35,0)),"") -> E1 | J15: AR | K15: 연구자 의견(문항화) | R15: =IFERROR(COUNTIF(L15:Q15,">=3")/COUNT(L15:Q15),"") | S15: =IF(R15="","",IF(R15>=검증!$B$4,"채택","수정·토론"))
A16: L04-U | B16: C 연결 | C16: ① 요구·분석 | D16: L04 | E16: =IFERROR(INDEX(연결!$C$5:$C$35,MATCH(D16,연결!$A$5:$A$35,0)),"") -> REQ 요구사항관리 → AUD 내부감사 | F16: 갱신 | G16: 요구사항이 바뀌면 감사 기준과 점검표를 다시 검토하고 고친다. | H16: =IFERROR(INDEX(연결!$G$5:$G$35,MATCH(D16,연결!$A$5:$A$35,0)),"") -> E1 | J16: AS | K16: 연구자 의견(문항화) | R16: =IFERROR(COUNTIF(L16:Q16,">=3")/COUNT(L16:Q16),"") | S16: =IF(R16="","",IF(R16>=검증!$B$4,"채택","수정·토론"))
... A97: L31-U | B97: C 연결 | C97: ⑤ 거버넌스·이해관계자 | D97: L31 | E97: =IFERROR(INDEX(연결!$C$5:$C$35,MATCH(D97,연결!$A$5:$A$35,0)),"") -> RES 자원관리 → CRM 고객관계관리 | F97: 갱신 | G97: 자원 사용 현황이 바뀌면 고객관계관리에 제공하는 보고를 다시 검토하고 고친다. | H97: =IFERROR(INDEX(연결!$G$5:$G$35,MATCH(D97,연결!$A$5:$A$35,0)),"") -> E1 | J97: DV | K97: 연구자 의견(문항화) | R97: =IFERROR(COUNTIF(L97:Q97,">=3")/COUNT(L97:Q97),"") | S97: =IF(R97="","",IF(R97>=검증!$B$4,"채택","수정·토론"))
A98: G01 | B98: D 종합 | C98: 종합 | E98: =IFERROR(INDEX(연결!$C$5:$C$35,MATCH(D98,연결!$A$5:$A$35,0)),"") | F98: 종합 | G98: 우리 조직의 BC 프로세스들은 서로의 산출물을 입력으로 사용하며 연결되어 있다. | H98: =IFERROR(INDEX(연결!$G$5:$G$35,MATCH(D98,연결!$A$5:$A$35,0)),"") | J98: DW | K98: 인용 근거 + 연구자 문항화 · 인용 A01 / B01 | R98: =IFERROR(COUNTIF(L98:Q98,">=3")/COUNT(L98:Q98),"") | S98: =IF(R98="","",IF(R98>=검증!$B$4,"채택","수정·토론"))
A99: G02 | B99: D 종합 | C99: 종합 | E99: =IFERROR(INDEX(연결!$C$5:$C$35,MATCH(D99,연결!$A$5:$A$35,0)),"") | F99: 종합 | G99: 한 BC 프로세스를 바꾸면 영향을 받는 다른 프로세스가 무엇인지 알 수 있다. | H99: =IFERROR(INDEX(연결!$G$5:$G$35,MATCH(D99,연결!$A$5:$A$35,0)),"") | J99: DX | K99: 연구자 의견(문항) / ISO 22301 4.4의 상호작용 고려를 참고 · 인용 A04 | R99: =IFERROR(COUNTIF(L99:Q99,">=3")/COUNT(L99:Q99),"") | S99: =IF(R99="","",IF(R99>=검증!$B$4,"채택","수정·토론"))
A100: G03 | B100: D 종합 | C100: 종합 | E100: =IFERROR(INDEX(연결!$C$5:$C$35,MATCH(D100,연결!$A$5:$A$35,0)),"") | F100: 종합 | G100: 프로세스 간에 "누가 누구에게 무엇을 전달하는지"가 문서로 정리되어 있다. | H100: =IFERROR(INDEX(연결!$G$5:$G$35,MATCH(D100,연결!$A$5:$A$35,0)),"") | J100: DY | K100: 인용 근거 + 연구자 문항화 · 인용 A03 / A02 | R100: =IFERROR(COUNTIF(L100:Q100,">=3")/COUNT(L100:Q100),"") | S100: =IF(R100="","",IF(R100>=검증!$B$4,"채택","수정·토론"))
A101: G04 | B101: D 종합 | C101: 종합 | E101: =IFERROR(INDEX(연결!$C$5:$C$35,MATCH(D101,연결!$A$5:$A$35,0)),"") | F101: 종합 | G101: BC 관리자(또는 그에 준하는 담당자)가 프로세스 간 연결 상태를 총괄하여 점검한다. | H101: =IFERROR(INDEX(연결!$G$5:$G$35,MATCH(D101,연결!$A$5:$A$35,0)),"") | J101: DZ | K101: 인용 근거 + 연구자 문항화 · 인용 A10 | R101: =IFERROR(COUNTIF(L101:Q101,">=3")/COUNT(L101:Q101),"") | S101: =IF(R101="","",IF(R101>=검증!$B$4,"채택","수정·토론"))
A102: G05 | B102: D 종합 | C102: 종합 | E102: =IFERROR(INDEX(연결!$C$5:$C$35,MATCH(D102,연결!$A$5:$A$35,0)),"") | F102: 종합 | G102: 프로세스 간 연결이 끊어졌거나 약한 지점을 파악하여 조치한다. | H102: =IFERROR(INDEX(연결!$G$5:$G$35,MATCH(D102,연결!$A$5:$A$35,0)),"") | J102: EA | K102: 연구자 의견(근거 인용 없음) | R102: =IFERROR(COUNTIF(L102:Q102,">=3")/COUNT(L102:Q102),"") | S102: =IF(R102="","",IF(R102>=검증!$B$4,"채택","수정·토론"))
A103: G06 | B103: D 종합 | C103: 종합 | E103: =IFERROR(INDEX(연결!$C$5:$C$35,MATCH(D103,연결!$A$5:$A$35,0)),"") | F103: 종합 | G103: 프로세스 간 연결은 일회성 프로젝트가 아니라 정기적으로 반복되는 운영 활동으로 유지된다. | H103: =IFERROR(INDEX(연결!$G$5:$G$35,MATCH(D103,연결!$A$5:$A$35,0)),"") | J103: EB | K103: 인용 근거 + 연구자 문항화 · 인용 A09 | R103: =IFERROR(COUNTIF(L103:Q103,">=3")/COUNT(L103:Q103),"") | S103: =IF(R103="","",IF(R103>=검증!$B$4,"채택","수정·토론"))
A104: RV1 | B104: E 검증(역문항) | C104: 검증 | E104: =IFERROR(INDEX(연결!$C$5:$C$35,MATCH(D104,연결!$A$5:$A$35,0)),"") | F104: 역문항(G01 대응) | G104: 우리 조직의 BC 프로세스는 대부분 다른 프로세스와 별개로 독립적으로 수행된다. | H104: =IFERROR(INDEX(연결!$G$5:$G$35,MATCH(D104,연결!$A$5:$A$35,0)),"") | I104: Y | J104: EC | K104: 연구자 의견(검증용 문항) | R104: =IFERROR(COUNTIF(L104:Q104,">=3")/COUNT(L104:Q104),"") | S104: =IF(R104="","",IF(R104>=검증!$B$4,"채택","수정·토론"))
A105: RV2 | B105: E 검증(역문항) | C105: 검증 | E105: =IFERROR(INDEX(연결!$C$5:$C$35,MATCH(D105,연결!$A$5:$A$35,0)),"") | F105: 역문항(L01~L03 대응) | G105: 한 프로세스의 결과물이 만들어진 뒤 다른 프로세스에서 참조되지 않는 경우가 많다. | H105: =IFERROR(INDEX(연결!$G$5:$G$35,MATCH(D105,연결!$A$5:$A$35,0)),"") | I105: Y | J105: ED | K105: 연구자 의견(검증용 문항) | R105: =IFERROR(COUNTIF(L105:Q105,">=3")/COUNT(L105:Q105),"") | S105: =IF(R105="","",IF(R105>=검증!$B$4,"채택","수정·토론"))
A106: RV3 | B106: E 검증(역문항) | C106: 검증 | E106: =IFERROR(INDEX(연결!$C$5:$C$35,MATCH(D106,연결!$A$5:$A$35,0)),"") | F106: 역문항(L22 대응) | G106: 문서가 개정되어도 관련 프로세스 담당자에게는 따로 알리지 않는 경우가 많다. | H106: =IFERROR(INDEX(연결!$G$5:$G$35,MATCH(D106,연결!$A$5:$A$35,0)),"") | I106: Y | J106: EE | K106: 연구자 의견(검증용 문항) | R106: =IFERROR(COUNTIF(L106:Q106,">=3")/COUNT(L106:Q106),"") | S106: =IF(R106="","",IF(R106>=검증!$B$4,"채택","수정·토론"))
A107: RV4 | B107: E 검증(역문항) | C107: 검증 | E107: =IFERROR(INDEX(연결!$C$5:$C$35,MATCH(D107,연결!$A$5:$A$35,0)),"") | F107: 역문항(L16 대응) | G107: 연습 결과가 BC 계획·절차 개정으로 이어지지 않는 경우가 많다. | H107: =IFERROR(INDEX(연결!$G$5:$G$35,MATCH(D107,연결!$A$5:$A$35,0)),"") | I107: Y | J107: EF | K107: 연구자 의견(검증용 문항) | R107: =IFERROR(COUNTIF(L107:Q107,">=3")/COUNT(L107:Q107),"") | S107: =IF(R107="","",IF(R107>=검증!$B$4,"채택","수정·토론"))
A108: AC1 | B108: E 검증(주의확인) | C108: 검증 | E108: =IFERROR(INDEX(연결!$C$5:$C$35,MATCH(D108,연결!$A$5:$A$35,0)),"") | F108: 주의확인 | G108: 이 문항에서는 응답 4번을 선택해 주십시오. | H108: =IFERROR(INDEX(연결!$G$5:$G$35,MATCH(D108,연결!$A$5:$A$35,0)),"") | J108: EG | K108: 연구자 의견(검증용 문항) | R108: =IFERROR(COUNTIF(L108:Q108,">=3")/COUNT(L108:Q108),"") | S108: =IF(R108="","",IF(R108>=검증!$B$4,"채택","수정·토론"))
A109: CR1 | B109: E 검증(준거) | C109: 검증 | E109: =IFERROR(INDEX(연결!$C$5:$C$35,MATCH(D109,연결!$A$5:$A$35,0)),"") | F109: 준거 | G109: 중단 사건이 발생해도 우리 조직의 BCMS가 효과적으로 대응할 수 있다고 확신한다. | H109: =IFERROR(INDEX(연결!$G$5:$G$35,MATCH(D109,연결!$A$5:$A$35,0)),"") | J109: EH | K109: 연구자 의견(검증용 문항) | R109: =IFERROR(COUNTIF(L109:Q109,">=3")/COUNT(L109:Q109),"") | S109: =IF(R109="","",IF(R109>=검증!$B$4,"채택","수정·토론"))
A110: CR2 | B110: E 검증(준거) | C110: 검증 | E110: =IFERROR(INDEX(연결!$C$5:$C$35,MATCH(D110,연결!$A$5:$A$35,0)),"") | F110: 준거 | G110: 최근 사고 또는 연습에서 복구목표를 달성했다. | H110: =IFERROR(INDEX(연결!$G$5:$G$35,MATCH(D110,연결!$A$5:$A$35,0)),"") | J110: EI | K110: 연구자 의견(검증용 문항) | R110: =IFERROR(COUNTIF(L110:Q110,">=3")/COUNT(L110:Q110),"") | S110: =IF(R110="","",IF(R110>=검증!$B$4,"채택","수정·토론"))
A111: CR3 | B111: E 검증(준거) | C111: 검증 | E111: =IFERROR(INDEX(연결!$C$5:$C$35,MATCH(D111,연결!$A$5:$A$35,0)),"") | F111: 준거 | G111: BC 투자의 가치를 경영진·이해관계자에게 설명할 수 있다. | H111: =IFERROR(INDEX(연결!$G$5:$G$35,MATCH(D111,연결!$A$5:$A$35,0)),"") | J111: EJ | K111: 연구자 의견(검증용 문항) · 인용 A32 | R111: =IFERROR(COUNTIF(L111:Q111,">=3")/COUNT(L111:Q111),"") | S111: =IF(R111="","",IF(R111>=검증!$B$4,"채택","수정·토론"))
A112: CR4 | B112: E 검증(준거) | C112: 검증 | E112: =IFERROR(INDEX(연결!$C$5:$C$35,MATCH(D112,연결!$A$5:$A$35,0)),"") | F112: 준거(역) | G112: 감사나 경영진 검토에서 같은 BCMS 지적사항이 반복된다. | H112: =IFERROR(INDEX(연결!$G$5:$G$35,MATCH(D112,연결!$A$5:$A$35,0)),"") | I112: Y | J112: EK | K112: 연구자 의견(검증용 문항) | R112: =IFERROR(COUNTIF(L112:Q112,">=3")/COUNT(L112:Q112),"") | S112: =IF(R112="","",IF(R112>=검증!$B$4,"채택","수정·토론"))

Sheet 보유·응답자정보
A1: Part A 응답자·조직 정보(10) / Part B 프로세스 보유 확인(22)
A2: Part B: 1 운영한다 · 2 부분적으로 운영한다 · 3 운영하지 않는다 · 4 모르겠다. 연결 문항은 출발·도착 프로세스가 모두 1·2일 때만 제시(설문 구현 시 survey/SURVEY_SPEC.md 참조).
A4: ID | B4: 구분 | C4: 항목 | D4: 응답 방식 | E4: 응답입력 열
A5: A01 | B5: Part A | C5: 업종 | D5: 자유 기재 | E5: B
A6: A02 | B6: Part A | C6: 조직 규모(임직원 수) | D6: 1~49 / 50~299 / 300~999 / 1000 이상 | E6: C
A7: A03 | B7: Part A | C7: BCMS 운영 기간 | D7: 1년 미만 / 1~3년 / 3~5년 / 5년 이상 | E7: D
A8: A04 | B8: Part A | C8: ISO 22301 인증 여부 | D8: 보유 / 준비 중 / 없음 | E8: E
A9: A05 | B9: Part A | C9: 응답자 역할 | D9: BC 관리자 / 프로세스 담당자 / 경영진 / 감사·기타 | E9: F
A10: A06 | B10: Part A | C10: BC 관련 업무 경력 | D10: 연수 | E10: G
A11: A07 | B11: Part A | C11: 최근 12개월 실제 중단 사고 경험 | D11: 없음 / 있음(횟수) | E11: H
A12: A08 | B12: Part A | C12: 최근 12개월 연습·훈련 횟수 | D12: 횟수 | E12: I
A13: A09 | B13: Part A | C13: ISMS 등 타 경영시스템과 통합 운영 여부 | D13: 통합 / 부분 / 별도 | E13: J
A14: A10 | B14: Part A | C14: BC 프로세스 문서화 정도 | D14: 전부 / 일부 / 거의 없음 | E14: K
A15: B01 | B15: Part B | C15: GOV BC 거버넌스 | D15: 1 운영 / 2 부분 / 3 미운영 / 4 모름 | E15: L
... A36: B22 | B36: Part B | C36: CRM 고객관계관리 | D36: 1 운영 / 2 부분 / 3 미운영 / 4 모름 | E36: AG

Sheet 응답입력
A1: 응답 입력 (7행부터 최대 50명)
A2: 6행은 예시(집계 제외). 연결·종합·검증 문항: 1~5 또는 9. 보유 확인: 1~4.
A4: 응답자 | B4: Part A | L4: Part B | AH4: Part C·D·E (1~5, 9)
A5: 응답자ID | B5: A01 | C5: A02 | D5: A03 | E5: A04 | F5: A05 | G5: A06 | H5: A07 | I5: A08 | J5: A09 | K5: A10 | L5: B01 | M5: B02 | N5: B03 | O5: B04 | P5: B05 | Q5: B06 | R5: B07 | S5: B08 | T5: B09 | U5: B10 | V5: B11 | W5: B12 | X5: B13 | Y5: B14 | Z5: B15 | AA5: B16 | AB5: B17 | AC5: B18 | AD5: B19 | AE5: B20 | AF5: B21 | AG5: B22 | AH5: L01-R | AI5: L01-V | AJ5: L01-U | AK5: L02-R | AL5: L02-V | AM5: L02-U | AN5: L03-R | AO5: L03-V | AP5: L03-U | AQ5: L04-R | AR5: L04-V | AS5: L04-U | AT5: L05-R | AU5: L05-V | AV5: L05-U | AW5: L06-R | AX5: L06-V | AY5: L06-U | AZ5: L07-R | BA5: L07-V | BB5: L07-U | BC5: L08-R | BD5: L08-V | BE5: L08-U | BF5: L09-R | BG5: L09-V | BH5: L09-U | BI5: L10-R | BJ5: L10-V | BK5: L10-U | BL5: L11-R | BM5: L11-V | BN5: L11-U | BO5: L12-R | BP5: L12-V | BQ5: L12-U | BR5: L13-R | BS5: L13-V | BT5: L13-U | BU5: L14-R | BV5: L14-V | BW5: L14-U | BX5: L15-R | BY5: L15-V | BZ5: L15-U | CA5: L16-R | CB5: L16-V | CC5: L16-U | CD5: L17-R | CE5: L17-V | CF5: L17-U | CG5: L18-R | CH5: L18-V | CI5: L18-U | CJ5: L19-R | CK5: L19-V | CL5: L19-U | CM5: L20-R | CN5: L20-V | CO5: L20-U | CP5: L21-R | CQ5: L21-V | CR5: L21-U | CS5: L22-R | CT5: L22-V | CU5: L22-U | CV5: L23-R | CW5: L23-V | CX5: L23-U | CY5: L24-R | CZ5: L24-V | DA5: L24-U | DB5: L25-R | DC5: L25-V | DD5: L25-U | DE5: L26-R | DF5: L26-V | DG5: L26-U | DH5: L27-R | DI5: L27-V | DJ5: L27-U | DK5: L28-R | DL5: L28-V | DM5: L28-U | DN5: L29-R | DO5: L29-V | DP5: L29-U | DQ5: L30-R | DR5: L30-V | DS5: L30-U | DT5: L31-R | DU5: L31-V | DV5: L31-U | DW5: G01 | DX5: G02 | DY5: G03 | DZ5: G04 | EA5: G05 | EB5: G06 | EC5: RV1 | ED5: RV2 | EE5: RV3 | EF5: RV4 | EG5: AC1 | EH5: CR1 | EI5: CR2 | EJ5: CR3 | EK5: CR4
A6: EX-예시 | B6: 제조업 | C6: 300~999 | D6: 3~5년 | E6: 보유 | F6: BC 관리자 | G6: 8 | H6: 1 | I6: 2 | J6: 부분 | K6: 일부 | L6: 1 | M6: 1 | N6: 1 | O6: 1 | P6: 1 | Q6: 1 | R6: 1 | S6: 1 | T6: 1 | U6: 1 | V6: 1 | W6: 1 | X6: 1 | Y6: 1 | Z6: 1 | AA6: 1 | AB6: 1 | AC6: 1 | AD6: 1 | AE6: 1 | AF6: 1 | AG6: 1 | AH6: 3 | AI6: 9 | AJ6: 4 | AK6: 4 | AL6: 3 | AM6: 4 | AN6: 3 | AO6: 5 | AP6: 4 | AQ6: 3 | AR6: 9 | AS6: 4 | AT6: 4 | AU6: 3 | AV6: 4 | AW6: 3 | AX6: 5 | AY6: 4 | AZ6: 3 | BA6: 9 | BB6: 4 | BC6: 4 | BD6: 3 | BE6: 4 | BF6: 3 | BG6: 5 | BH6: 4 | BI6: 3 | BJ6: 9 | BK6: 4 | BL6: 4 | BM6: 3 | BN6: 4 | BO6: 3 | BP6: 5 | BQ6: 4 | BR6: 3 | BS6: 9 | BT6: 4 | BU6: 4 | BV6: 3 | BW6: 4 | BX6: 3 | BY6: 5 | BZ6: 4 | CA6: 3 | CB6: 9 | CC6: 4 | CD6: 4 | CE6: 3 | CF6: 4 | CG6: 3 | CH6: 5 | CI6: 4 | CJ6: 3 | CK6: 9 | CL6: 4 | CM6: 4 | CN6: 3 | CO6: 4 | CP6: 3 | CQ6: 5 | CR6: 4 | CS6: 3 | CT6: 9 | CU6: 4 | CV6: 4 | CW6: 3 | CX6: 4 | CY6: 3 | CZ6: 5 | DA6: 4 | DB6: 3 | DC6: 9 | DD6: 4 | DE6: 4 | DF6: 3 | DG6: 4 | DH6: 3 | DI6: 5 | DJ6: 4 | DK6: 3 | DL6: 9 | DM6: 4 | DN6: 4 | DO6: 3 | DP6: 4 | DQ6: 3 | DR6: 5 | DS6: 4 | DT6: 3 | DU6: 9 | DV6: 4 | DW6: 4 | DX6: 3 | DY6: 4 | DZ6: 3 | EA6: 5 | EB6: 4 | EC6: 3 | ED6: 9 | EE6: 4 | EF6: 4 | EG6: 3 | EH6: 4 | EI6: 3 | EJ6: 5 | EK6: 4

Sheet 연결점수
A1: 응답자별 연결 점수 (R·V·U 3문항 평균, 9 제외, 최소 2문항 응답 시 산출)
A5: 응답자ID | B5: L01 | C5: L02 | D5: L03 | E5: L04 | F5: L05 | G5: L06 | H5: L07 | I5: L08 | J5: L09 | K5: L10 | L5: L11 | M5: L12 | N5: L13 | O5: L14 | P5: L15 | Q5: L16 | R5: L17 | S5: L18 | T5: L19 | U5: L20 | V5: L21 | W5: L22 | X5: L23 | Y5: L24 | Z5: L25 | AA5: L26 | AB5: L27 | AC5: L28 | AD5: L29 | AE5: L30 | AF5: L31 | AG5: 종합 연결 지수
A6: =IF(응답입력!A7="","",응답입력!A7) | B6: =IF(COUNTIF(응답입력!AH7:AJ7,"<9")>=2,AVERAGEIF(응답입력!AH7:AJ7,"<9"),"") | C6: =IF(COUNTIF(응답입력!AK7:AM7,"<9")>=2,AVERAGEIF(응답입력!AK7:AM7,"<9"),"") | D6: =IF(COUNTIF(응답입력!AN7:AP7,"<9")>=2,AVERAGEIF(응답입력!AN7:AP7,"<9"),"") | E6: =IF(COUNTIF(응답입력!AQ7:AS7,"<9")>=2,AVERAGEIF(응답입력!AQ7:AS7,"<9"),"") | F6: =IF(COUNTIF(응답입력!AT7:AV7,"<9")>=2,AVERAGEIF(응답입력!AT7:AV7,"<9"),"") | G6: =IF(COUNTIF(응답입력!AW7:AY7,"<9")>=2,AVERAGEIF(응답입력!AW7:AY7,"<9"),"") | H6: =IF(COUNTIF(응답입력!AZ7:BB7,"<9")>=2,AVERAGEIF(응답입력!AZ7:BB7,"<9"),"") | I6: =IF(COUNTIF(응답입력!BC7:BE7,"<9")>=2,AVERAGEIF(응답입력!BC7:BE7,"<9"),"") | J6: =IF(COUNTIF(응답입력!BF7:BH7,"<9")>=2,AVERAGEIF(응답입력!BF7:BH7,"<9"),"") | K6: =IF(COUNTIF(응답입력!BI7:BK7,"<9")>=2,AVERAGEIF(응답입력!BI7:BK7,"<9"),"") | L6: =IF(COUNTIF(응답입력!BL7:BN7,"<9")>=2,AVERAGEIF(응답입력!BL7:BN7,"<9"),"") | M6: =IF(COUNTIF(응답입력!BO7:BQ7,"<9")>=2,AVERAGEIF(응답입력!BO7:BQ7,"<9"),"") | N6: =IF(COUNTIF(응답입력!BR7:BT7,"<9")>=2,AVERAGEIF(응답입력!BR7:BT7,"<9"),"") | O6: =IF(COUNTIF(응답입력!BU7:BW7,"<9")>=2,AVERAGEIF(응답입력!BU7:BW7,"<9"),"") | P6: =IF(COUNTIF(응답입력!BX7:BZ7,"<9")>=2,AVERAGEIF(응답입력!BX7:BZ7,"<9"),"") | Q6: =IF(COUNTIF(응답입력!CA7:CC7,"<9")>=2,AVERAGEIF(응답입력!CA7:CC7,"<9"),"") | R6: =IF(COUNTIF(응답입력!CD7:CF7,"<9")>=2,AVERAGEIF(응답입력!CD7:CF7,"<9"),"") | S6: =IF(COUNTIF(응답입력!CG7:CI7,"<9")>=2,AVERAGEIF(응답입력!CG7:CI7,"<9"),"") | T6: =IF(COUNTIF(응답입력!CJ7:CL7,"<9")>=2,AVERAGEIF(응답입력!CJ7:CL7,"<9"),"") | U6: =IF(COUNTIF(응답입력!CM7:CO7,"<9")>=2,AVERAGEIF(응답입력!CM7:CO7,"<9"),"") | V6: =IF(COUNTIF(응답입력!CP7:CR7,"<9")>=2,AVERAGEIF(응답입력!CP7:CR7,"<9"),"") | W6: =IF(COUNTIF(응답입력!CS7:CU7,"<9")>=2,AVERAGEIF(응답입력!CS7:CU7,"<9"),"") | X6: =IF(COUNTIF(응답입력!CV7:CX7,"<9")>=2,AVERAGEIF(응답입력!CV7:CX7,"<9"),"") | Y6: =IF(COUNTIF(응답입력!CY7:DA7,"<9")>=2,AVERAGEIF(응답입력!CY7:DA7,"<9"),"") | Z6: =IF(COUNTIF(응답입력!DB7:DD7,"<9")>=2,AVERAGEIF(응답입력!DB7:DD7,"<9"),"") | AA6: =IF(COUNTIF(응답입력!DE7:DG7,"<9")>=2,AVERAGEIF(응답입력!DE7:DG7,"<9"),"") | AB6: =IF(COUNTIF(응답입력!DH7:DJ7,"<9")>=2,AVERAGEIF(응답입력!DH7:DJ7,"<9"),"") | AC6: =IF(COUNTIF(응답입력!DK7:DM7,"<9")>=2,AVERAGEIF(응답입력!DK7:DM7,"<9"),"") | AD6: =IF(COUNTIF(응답입력!DN7:DP7,"<9")>=2,AVERAGEIF(응답입력!DN7:DP7,"<9"),"") | AE6: =IF(COUNTIF(응답입력!DQ7:DS7,"<9")>=2,AVERAGEIF(응답입력!DQ7:DS7,"<9"),"") | AF6: =IF(COUNTIF(응답입력!DT7:DV7,"<9")>=2,AVERAGEIF(응답입력!DT7:DV7,"<9"),"") | AG6: =IFERROR(AVERAGE(B6:AF6),"")
A7: =IF(응답입력!A8="","",응답입력!A8) | B7: =IF(COUNTIF(응답입력!AH8:AJ8,"<9")>=2,AVERAGEIF(응답입력!AH8:AJ8,"<9"),"") | C7: =IF(COUNTIF(응답입력!AK8:AM8,"<9")>=2,AVERAGEIF(응답입력!AK8:AM8,"<9"),"") | D7: =IF(COUNTIF(응답입력!AN8:AP8,"<9")>=2,AVERAGEIF(응답입력!AN8:AP8,"<9"),"") | E7: =IF(COUNTIF(응답입력!AQ8:AS8,"<9")>=2,AVERAGEIF(응답입력!AQ8:AS8,"<9"),"") | F7: =IF(COUNTIF(응답입력!AT8:AV8,"<9")>=2,AVERAGEIF(응답입력!AT8:AV8,"<9"),"") | G7: =IF(COUNTIF(응답입력!AW8:AY8,"<9")>=2,AVERAGEIF(응답입력!AW8:AY8,"<9"),"") | H7: =IF(COUNTIF(응답입력!AZ8:BB8,"<9")>=2,AVERAGEIF(응답입력!AZ8:BB8,"<9"),"") | I7: =IF(COUNTIF(응답입력!BC8:BE8,"<9")>=2,AVERAGEIF(응답입력!BC8:BE8,"<9"),"") | J7: =IF(COUNTIF(응답입력!BF8:BH8,"<9")>=2,AVERAGEIF(응답입력!BF8:BH8,"<9"),"") | K7: =IF(COUNTIF(응답입력!BI8:BK8,"<9")>=2,AVERAGEIF(응답입력!BI8:BK8,"<9"),"") | L7: =IF(COUNTIF(응답입력!BL8:BN8,"<9")>=2,AVERAGEIF(응답입력!BL8:BN8,"<9"),"") | M7: =IF(COUNTIF(응답입력!BO8:BQ8,"<9")>=2,AVERAGEIF(응답입력!BO8:BQ8,"<9"),"") | N7: =IF(COUNTIF(응답입력!BR8:BT8,"<9")>=2,AVERAGEIF(응답입력!BR8:BT8,"<9"),"") | O7: =IF(COUNTIF(응답입력!BU8:BW8,"<9")>=2,AVERAGEIF(응답입력!BU8:BW8,"<9"),"") | P7: =IF(COUNTIF(응답입력!BX8:BZ8,"<9")>=2,AVERAGEIF(응답입력!BX8:BZ8,"<9"),"") | Q7: =IF(COUNTIF(응답입력!CA8:CC8,"<9")>=2,AVERAGEIF(응답입력!CA8:CC8,"<9"),"") | R7: =IF(COUNTIF(응답입력!CD8:CF8,"<9")>=2,AVERAGEIF(응답입력!CD8:CF8,"<9"),"") | S7: =IF(COUNTIF(응답입력!CG8:CI8,"<9")>=2,AVERAGEIF(응답입력!CG8:CI8,"<9"),"") | T7: =IF(COUNTIF(응답입력!CJ8:CL8,"<9")>=2,AVERAGEIF(응답입력!CJ8:CL8,"<9"),"") | U7: =IF(COUNTIF(응답입력!CM8:CO8,"<9")>=2,AVERAGEIF(응답입력!CM8:CO8,"<9"),"") | V7: =IF(COUNTIF(응답입력!CP8:CR8,"<9")>=2,AVERAGEIF(응답입력!CP8:CR8,"<9"),"") | W7: =IF(COUNTIF(응답입력!CS8:CU8,"<9")>=2,AVERAGEIF(응답입력!CS8:CU8,"<9"),"") | X7: =IF(COUNTIF(응답입력!CV8:CX8,"<9")>=2,AVERAGEIF(응답입력!CV8:CX8,"<9"),"") | Y7: =IF(COUNTIF(응답입력!CY8:DA8,"<9")>=2,AVERAGEIF(응답입력!CY8:DA8,"<9"),"") | Z7: =IF(COUNTIF(응답입력!DB8:DD8,"<9")>=2,AVERAGEIF(응답입력!DB8:DD8,"<9"),"") | AA7: =IF(COUNTIF(응답입력!DE8:DG8,"<9")>=2,AVERAGEIF(응답입력!DE8:DG8,"<9"),"") | AB7: =IF(COUNTIF(응답입력!DH8:DJ8,"<9")>=2,AVERAGEIF(응답입력!DH8:DJ8,"<9"),"") | AC7: =IF(COUNTIF(응답입력!DK8:DM8,"<9")>=2,AVERAGEIF(응답입력!DK8:DM8,"<9"),"") | AD7: =IF(COUNTIF(응답입력!DN8:DP8,"<9")>=2,AVERAGEIF(응답입력!DN8:DP8,"<9"),"") | AE7: =IF(COUNTIF(응답입력!DQ8:DS8,"<9")>=2,AVERAGEIF(응답입력!DQ8:DS8,"<9"),"") | AF7: =IF(COUNTIF(응답입력!DT8:DV8,"<9")>=2,AVERAGEIF(응답입력!DT8:DV8,"<9"),"") | AG7: =IFERROR(AVERAGE(B7:AF7),"")
A8: =IF(응답입력!A9="","",응답입력!A9) | B8: =IF(COUNTIF(응답입력!AH9:AJ9,"<9")>=2,AVERAGEIF(응답입력!AH9:AJ9,"<9"),"") | C8: =IF(COUNTIF(응답입력!AK9:AM9,"<9")>=2,AVERAGEIF(응답입력!AK9:AM9,"<9"),"") | D8: =IF(COUNTIF(응답입력!AN9:AP9,"<9")>=2,AVERAGEIF(응답입력!AN9:AP9,"<9"),"") | E8: =IF(COUNTIF(응답입력!AQ9:AS9,"<9")>=2,AVERAGEIF(응답입력!AQ9:AS9,"<9"),"") | F8: =IF(COUNTIF(응답입력!AT9:AV9,"<9")>=2,AVERAGEIF(응답입력!AT9:AV9,"<9"),"") | G8: =IF(COUNTIF(응답입력!AW9:AY9,"<9")>=2,AVERAGEIF(응답입력!AW9:AY9,"<9"),"") | H8: =IF(COUNTIF(응답입력!AZ9:BB9,"<9")>=2,AVERAGEIF(응답입력!AZ9:BB9,"<9"),"") | I8: =IF(COUNTIF(응답입력!BC9:BE9,"<9")>=2,AVERAGEIF(응답입력!BC9:BE9,"<9"),"") | J8: =IF(COUNTIF(응답입력!BF9:BH9,"<9")>=2,AVERAGEIF(응답입력!BF9:BH9,"<9"),"") | K8: =IF(COUNTIF(응답입력!BI9:BK9,"<9")>=2,AVERAGEIF(응답입력!BI9:BK9,"<9"),"") | L8: =IF(COUNTIF(응답입력!BL9:BN9,"<9")>=2,AVERAGEIF(응답입력!BL9:BN9,"<9"),"") | M8: =IF(COUNTIF(응답입력!BO9:BQ9,"<9")>=2,AVERAGEIF(응답입력!BO9:BQ9,"<9"),"") | N8: =IF(COUNTIF(응답입력!BR9:BT9,"<9")>=2,AVERAGEIF(응답입력!BR9:BT9,"<9"),"") | O8: =IF(COUNTIF(응답입력!BU9:BW9,"<9")>=2,AVERAGEIF(응답입력!BU9:BW9,"<9"),"") | P8: =IF(COUNTIF(응답입력!BX9:BZ9,"<9")>=2,AVERAGEIF(응답입력!BX9:BZ9,"<9"),"") | Q8: =IF(COUNTIF(응답입력!CA9:CC9,"<9")>=2,AVERAGEIF(응답입력!CA9:CC9,"<9"),"") | R8: =IF(COUNTIF(응답입력!CD9:CF9,"<9")>=2,AVERAGEIF(응답입력!CD9:CF9,"<9"),"") | S8: =IF(COUNTIF(응답입력!CG9:CI9,"<9")>=2,AVERAGEIF(응답입력!CG9:CI9,"<9"),"") | T8: =IF(COUNTIF(응답입력!CJ9:CL9,"<9")>=2,AVERAGEIF(응답입력!CJ9:CL9,"<9"),"") | U8: =IF(COUNTIF(응답입력!CM9:CO9,"<9")>=2,AVERAGEIF(응답입력!CM9:CO9,"<9"),"") | V8: =IF(COUNTIF(응답입력!CP9:CR9,"<9")>=2,AVERAGEIF(응답입력!CP9:CR9,"<9"),"") | W8: =IF(COUNTIF(응답입력!CS9:CU9,"<9")>=2,AVERAGEIF(응답입력!CS9:CU9,"<9"),"") | X8: =IF(COUNTIF(응답입력!CV9:CX9,"<9")>=2,AVERAGEIF(응답입력!CV9:CX9,"<9"),"") | Y8: =IF(COUNTIF(응답입력!CY9:DA9,"<9")>=2,AVERAGEIF(응답입력!CY9:DA9,"<9"),"") | Z8: =IF(COUNTIF(응답입력!DB9:DD9,"<9")>=2,AVERAGEIF(응답입력!DB9:DD9,"<9"),"") | AA8: =IF(COUNTIF(응답입력!DE9:DG9,"<9")>=2,AVERAGEIF(응답입력!DE9:DG9,"<9"),"") | AB8: =IF(COUNTIF(응답입력!DH9:DJ9,"<9")>=2,AVERAGEIF(응답입력!DH9:DJ9,"<9"),"") | AC8: =IF(COUNTIF(응답입력!DK9:DM9,"<9")>=2,AVERAGEIF(응답입력!DK9:DM9,"<9"),"") | AD8: =IF(COUNTIF(응답입력!DN9:DP9,"<9")>=2,AVERAGEIF(응답입력!DN9:DP9,"<9"),"") | AE8: =IF(COUNTIF(응답입력!DQ9:DS9,"<9")>=2,AVERAGEIF(응답입력!DQ9:DS9,"<9"),"") | AF8: =IF(COUNTIF(응답입력!DT9:DV9,"<9")>=2,AVERAGEIF(응답입력!DT9:DV9,"<9"),"") | AG8: =IFERROR(AVERAGE(B8:AF8),"")
