Workbook

Sheet 안내
A1: BCMS 프로세스 간 연계성 측정 — 문항은행 + 온톨로지 맵
A2: 근거: Arias-Aranda et al.(2026) Appl. Sci. 16, 3219 · Białas(2010) BCMO · 상세 설명은 docs/BCMS_연계성_예비문항.md
A4: 목적 | B4: 온톨로지는 "무엇과 무엇의 연결을 측정하는가"를 정하고, 설문은 "그 연결이 조직에서 어느 정도 유지되는가"를 측정한다.
A5: 4단계 | B5: ① Arias 프로세스 설명에서 연결 근거 찾기 → ② Białas 방식으로 객체·관계 정의 → ③ 연결의 반영·확인·갱신 상태를 문항으로 표현 → ④ 문항이 연계성을 재는지 검증
A6: 시트 구성 | B6: 온톨로지맵(그림) · 객체(22) · 연결(25) · 트리플(주어-관계-목적어) · 관계매트릭스 · 문항(90) · 보유·응답자정보 · 응답입력 · 연결점수 · 점수요약 · 검증
A7: 사용 순서 | B7: ① 문항 시트에서 문항 확인 → ② 전문가 6인이 문항 시트 L~Q열에 적합도(1~4) 입력, I-CVI·판정 자동 계산 → ③ 설문 응답을 응답입력 시트 7행부터 입력 → ④ 연결점수·점수요약·검증 시트에서 결과 확인
A8: 입력 칸 표시 | B8: 노란 바탕 + 파란 글씨 = 직접 입력하는 칸. 검은 글씨 = 수식 또는 고정 내용(수정 불필요).
A9: 예시 행 | B9: 응답입력 시트 6행은 형식을 보여 주는 예시이며 모든 집계에서 제외됩니다(집계는 7~56행). 지우지 않아도 됩니다.
A10: 응답 척도 | B10: 1 전혀 그렇지 않다 · 2 그렇지 않다 · 3 보통이다 · 4 그렇다 · 5 매우 그렇다 · 9 해당 없음/모르겠음(점수에서 제외)
A11: 상태 정의 | B11: 반영(R)=A의 산출물이 B의 활동·결정에 실제로 들어감 · 확인(V)=그 반영이 맞는지 점검함 · 갱신(U)=A 또는 B가 바뀌면 연결을 함께 고침
A12: 중요한 한계 | B12: 25개 연결은 Arias의 서술에서 추출한 가설이며(Arias는 연결 자체를 검증하지 않음) 전문가 검증 전 단계입니다. 관계 이름·반영/확인/갱신 구분·단계 가설은 두 논문에 없는 본 연구 설계입니다. Białas(2010)는 BS 25999 기반 프로토타입이며 방법만 차용했습니다.
A13: 통계 한계 | B13: Cronbach α·요인분석은 엑셀 수식으로 제공하지 않습니다(통계 프로그램 사용). 이 파일은 연결·상태 평균, 역문항 일관성 상관, 단계 가설 확인까지 제공합니다.

Sheet 온톨로지맵
A1: 온톨로지 맵 — 22개 프로세스와 25개 연결
A2: 그림 파일: docs/BCMS_온톨로지맵.png · 연결 ID는 연결 시트, 관계 목록은 트리플·관계매트릭스 시트 참조

Sheet 객체
A1: 객체(클래스) — Arias Table 5의 22개 BCMS 프로세스
A2: 범주·PDCA·재난관리주기: Arias Table 5 / 지명률: Arias Table 2–4(전문가 39명) / 대표 산출물: Białas의 artefact 개념을 적용한 제안
A4: ID | B4: 프로세스 | C4: 범주 | D4: PDCA | E4: 재난관리주기 | F4: 전문가 지명률(%) | G4: Arias 합의 구분(80%/20%) | H4: 대표 산출물(제안) | I4: 관련 연결 수
A5: GOV | B5: BC 거버넌스 | C5: 관리 | D5: - | E5: - | F5: 90 | G5: =IF(F5>=80,"Category 1 채택",IF(F5>=20,"Category 2 토론","Category 3 기각")) -> Category 1 채택 | H5: 경영진 검토 결과·BCMS 목표(Arias p.14,16) | I5: =COUNTIF(연결!$C$5:$C$29,"*"&A5&"*") -> 2
A6: POL | B6: BC 정책관리 | C6: 핵심 | D6: Plan | E6: Mitigation | F6: 87 | G6: =IF(F6>=80,"Category 1 채택",IF(F6>=20,"Category 2 토론","Category 3 기각")) -> Category 1 채택 | H6: BC 정책(Białas hasBCpolicy) | I6: =COUNTIF(연결!$C$5:$C$29,"*"&A6&"*") -> 1
A7: REQ | B7: 요구사항관리 | C7: 핵심 | D7: Plan | E7: Mitigation | F7: 74 | G7: =IF(F7>=80,"Category 1 채택",IF(F7>=20,"Category 2 토론","Category 3 기각")) -> Category 2 토론 | H7: 법규·계약 요구사항 목록 | I7: =COUNTIF(연결!$C$5:$C$29,"*"&A7&"*") -> 4
A8: BIA | B8: BIA·중요도 분석 | C8: 핵심 | D8: Plan | E8: Mitigation | F8: 100 | G8: =IF(F8>=80,"Category 1 채택",IF(F8>=20,"Category 2 토론","Category 3 기각")) -> Category 1 채택 | H8: BIA 보고서(RTO 등, Białas BIAreport) | I8: =COUNTIF(연결!$C$5:$C$29,"*"&A8&"*") -> 4
A9: RA | B9: 리스크평가 | C9: 핵심 | D9: Plan | E9: Mitigation | F9: 90 | G9: =IF(F9>=80,"Category 1 채택",IF(F9>=20,"Category 2 토론","Category 3 기각")) -> Category 1 채택 | H9: 리스크 카탈로그 | I9: =COUNTIF(연결!$C$5:$C$29,"*"&A9&"*") -> 4
A10: STR | B10: BC 전략·솔루션 결정·선정 | C10: 핵심 | D10: Plan | E10: Mitigation | F10: 74 | G10: =IF(F10>=80,"Category 1 채택",IF(F10>=20,"Category 2 토론","Category 3 기각")) -> Category 2 토론 | H10: 선정된 BC 전략·솔루션 | I10: =COUNTIF(연결!$C$5:$C$29,"*"&A10&"*") -> 3
A11: PLAN | B11: BC 계획·절차 개발 | C11: 핵심 | D11: Plan | E11: Mitigation | F11: 69 | G11: =IF(F11>=80,"Category 1 채택",IF(F11>=20,"Category 2 토론","Category 3 기각")) -> Category 2 토론 | H11: BC 계획·절차(Białas hasBCplan) | I11: =COUNTIF(연결!$C$5:$C$29,"*"&A11&"*") -> 5
A12: IMP | B12: 솔루션 이행관리 | C12: 핵심 | D12: Do | E12: Preparedness | F12: 69 | G12: =IF(F12>=80,"Category 1 채택",IF(F12>=20,"Category 2 토론","Category 3 기각")) -> Category 2 토론 | H12: 구현된 솔루션·이행 기록 | I12: =COUNTIF(연결!$C$5:$C$29,"*"&A12&"*") -> 1
A13: INC | B13: 사고·비상 대응 | C13: 핵심 | D13: Do | E13: Response | F13: 100 | G13: =IF(F13>=80,"Category 1 채택",IF(F13>=20,"Category 2 토론","Category 3 기각")) -> Category 1 채택 | H13: 사고 대응 기록 | I13: =COUNTIF(연결!$C$5:$C$29,"*"&A13&"*") -> 4
A14: EXE | B14: BC 계획·절차 훈련·연습 | C14: 핵심 | D14: Do | E14: Preparedness | F14: 100 | G14: =IF(F14>=80,"Category 1 채택",IF(F14>=20,"Category 2 토론","Category 3 기각")) -> Category 1 채택 | H14: 연습 시나리오·결과 | I14: =COUNTIF(연결!$C$5:$C$29,"*"&A14&"*") -> 3
A15: AWR | B15: 인식·역량·교육 | C15: 핵심 | D15: Do | E15: Preparedness | F15: 95 | G15: =IF(F15>=80,"Category 1 채택",IF(F15>=20,"Category 2 토론","Category 3 기각")) -> Category 1 채택 | H15: 교육 프로그램·기록(Białas trainingProgs, trainingTrail) | I15: =COUNTIF(연결!$C$5:$C$29,"*"&A15&"*") -> 1
A16: SUP | B16: 공급망관리 | C16: 핵심 | D16: Do | E16: Preparedness | F16: 90 | G16: =IF(F16>=80,"Category 1 채택",IF(F16>=20,"Category 2 토론","Category 3 기각")) -> Category 1 채택 | H16: 공급업체 평가 결과(Białas hasSuppOutsource) | I16: =COUNTIF(연결!$C$5:$C$29,"*"&A16&"*") -> 2
... A26: CRM | B26: 고객관계관리 | C26: 지원 | D26: - | E26: - | F26: 3 | G26: =IF(F26>=80,"Category 1 채택",IF(F26>=20,"Category 2 토론","Category 3 기각")) -> Category 3 기각 | H26: 고객 만족·BC 투자 가치 보고 | I26: =COUNTIF(연결!$C$5:$C$29,"*"&A26&"*") -> 1
A28: 주: 지명률은 논문 표의 값을 옮긴 것이며 Arias는 CRM(3%)도 참조모델에 포함하도록 판단했고, 요구사항·전략·이행·계획·협의(69~74%)도 ISO 22301 요건으로 핵심 프로세스로 유지했다(Arias pp.12–13). 따라서 "합의 구분"은 참고 정보이며 포함 여부를 결정하지 않는다.

Sheet 연결
A1: 연결(관계) 25개 — 근거·등급·competency question
A2: 등급 A=Arias가 입력·산출 관계를 직접 서술, B=간접 추론(검증 우선). 쪽수는 Arias 저널 쪽수.
A4: ID | B4: 영역 | C4: 연결 (A→B) | D4: 관계(object slot) | E4: 근거(논문) | F4: 등급 | G4: Competency question | H4: 문항 수 | I4: 점검
A5: L01 | B5: ① 요구·분석 | C5: REQ → BIA | D5: informs | E5: "These requirements inform processes such as BIA…" (Arias p.15) | F5: A | G5: BIA에 반영된 법규·계약 요구사항은 무엇인가? | H5: =COUNTIF(문항!$D$5:$D$94,A5) -> 3 | I5: =IF(H5=3,"OK","확인") -> OK
A6: L02 | B6: ① 요구·분석 | C6: REQ → RA | D6: informs | E6: 같은 문장 (p.15) | F6: A | G6: 리스크평가가 고려한 요구사항은 무엇인가? | H6: =COUNTIF(문항!$D$5:$D$94,A6) -> 3 | I6: =IF(H6=3,"OK","확인") -> OK
A7: L03 | B7: ① 요구·분석 | C7: BIA → RA | D7: informs | E7: "risk assessment… relies on the outcomes of the BIA as its foundation" (p.15) | F7: A | G7: 리스크평가 대상 중 BIA에서 온 것은 무엇인가? | H7: =COUNTIF(문항!$D$5:$D$94,A7) -> 3 | I7: =IF(H7=3,"OK","확인") -> OK
A8: L04 | B8: ① 요구·분석 | C8: REQ → AUD | D8: informs | E8: 같은 문장: "internal audits" (p.15) | F8: A | G8: 감사 점검항목 중 요구사항에서 온 것은? | H8: =COUNTIF(문항!$D$5:$D$94,A8) -> 3 | I8: =IF(H8=3,"OK","확인") -> OK
A9: L05 | B9: ① 요구·분석 | C9: REQ → SUP | D9: informs | E9: 같은 문장: "supply chain management" (p.15) | F9: A | G9: 공급업체 계약에 반영된 BC 요구사항은? | H9: =COUNTIF(문항!$D$5:$D$94,A9) -> 3 | I9: =IF(H9=3,"OK","확인") -> OK
A10: L06 | B10: ② 전략·계획·이행 | C10: BIA → STR | D10: informs | E10: "approved BC requirements guide the determination and selection of… strategies" (p.15) | F10: A | G10: 이 전략은 어떤 BIA 결과에 근거하는가? | H10: =COUNTIF(문항!$D$5:$D$94,A10) -> 3 | I10: =IF(H10=3,"OK","확인") -> OK
A11: L07 | B11: ② 전략·계획·이행 | C11: STR → IMP | D11: derivesFrom | E11: IMP는 "strategies, solutions… are executed as planned" (p.15) | F11: A | G11: 선정된 솔루션 중 아직 이행되지 않은 것은? | H11: =COUNTIF(문항!$D$5:$D$94,A11) -> 3 | I11: =IF(H11=3,"OK","확인") -> OK
A12: L08 | B12: ② 전략·계획·이행 | C12: STR → PLAN | D12: derivesFrom | E12: "plans and procedures, derived from the identified BC strategies and solutions" (p.15) | F12: A | G12: 이 계획은 어느 전략·솔루션을 활성화하는가? | H12: =COUNTIF(문항!$D$5:$D$94,A12) -> 3 | I12: =IF(H12=3,"OK","확인") -> OK
A13: L09 | B13: ② 전략·계획·이행 | C13: RA → PLAN | D13: informs | E13: 리스크 카탈로그가 "input for… development of BC plans and procedures" (p.15) | F13: A | G13: 계획이 다루는 리스크 시나리오는? | H13: =COUNTIF(문항!$D$5:$D$94,A13) -> 3 | I13: =IF(H13=3,"OK","확인") -> OK
A14: L10 | B14: ② 전략·계획·이행 | C14: BIA → RES | D14: informs | E14: Białas: `BIAreport.resour4Resumption`(복구 필요 자원) + Arias: RES는 "resources necessary for executing strategies" 제공 (p.16) | F14: B | G14: 서비스 복구에 필요한 자원은 무엇이며 확보되었는가? (Białas Fig.4와 동일 유형) | H14: =COUNTIF(문항!$D$5:$D$94,A14) -> 3 | I14: =IF(H14=3,"OK","확인") -> OK
A15: L11 | B15: ③ 대응·복구·훈련 | C15: PLAN ↔ INC | D15: derivesFrom / feedsBack | E15: 솔루션 활성화는 "execution of BC plans and procedures"로 촉발 (p.15), 사고대응 개선은 CHG 경로로 환류 (p.16) | F15: A | G15: 지난 사고에서 어느 계획을 썼고 무엇이 개정되었나? | H15: =COUNTIF(문항!$D$5:$D$94,A15) -> 3 | I15: =IF(H15=3,"OK","확인") -> OK
A16: L12 | B16: ③ 대응·복구·훈련 | C16: INC → WARN | D16: informs | E16: INC는 "two primary subprocesses: warning and communication… and recovery" (p.15) | F16: A | G16: 사고 시 누구에게 경보가 갔는가? | H16: =COUNTIF(문항!$D$5:$D$94,A16) -> 3 | I16: =IF(H16=3,"OK","확인") -> OK
... A29: L25 | B29: ⑤ 거버넌스·이해관계자 | C29: RES → 핵심 프로세스/CRM | D29: informs | E29: RES 산출물: "reports on resource utilization for core BCMS processes and the customer relationship management process" (p.16) | F29: A | G29: 자원 사용 보고를 받아 쓰는 프로세스는? | H29: =COUNTIF(문항!$D$5:$D$94,A29) -> 3 | I29: =IF(H29=3,"OK","확인") -> OK

Sheet 트리플
A1: 온톨로지 트리플(주어–관계–목적어)
A2: 연결 관계 트리플 + ProcessLink 객체 트리플. derivesFrom은 "나중 것이 앞 것에서 도출" 방향으로 기록.
A4: 주어 | B4: 관계 | C4: 목적어 | D4: 연결 ID | E4: 등급 | F4: 구분
A5: REQ | B5: informs | C5: BIA | D5: L01 | E5: A | F5: 프로세스 관계
A6: REQ | B6: informs | C6: RA | D6: L02 | E6: A | F6: 프로세스 관계
A7: BIA | B7: informs | C7: RA | D7: L03 | E7: A | F7: 프로세스 관계
A8: REQ | B8: informs | C8: AUD | D8: L04 | E8: A | F8: 프로세스 관계
A9: REQ | B9: informs | C9: SUP | D9: L05 | E9: A | F9: 프로세스 관계
A10: BIA | B10: informs | C10: STR | D10: L06 | E10: A | F10: 프로세스 관계
A11: IMP | B11: derivesFrom | C11: STR | D11: L07 | E11: A | F11: 프로세스 관계
A12: PLAN | B12: derivesFrom | C12: STR | D12: L08 | E12: A | F12: 프로세스 관계
A13: RA | B13: informs | C13: PLAN | D13: L09 | E13: A | F13: 프로세스 관계
A14: BIA | B14: informs | C14: RES | D14: L10 | E14: B | F14: 프로세스 관계
A15: INC | B15: derivesFrom | C15: PLAN | D15: L11 | E15: A | F15: 프로세스 관계
... A187: Link_L25 | B187: updated | C187: L25-U | D187: L25 | E187: A | F187: ProcessLink 객체

Sheet 관계매트릭스
A1: 관계 매트릭스 — 행(정보 제공) → 열(정보 사용)
A2: 셀 값 = 연결 ID. 트리플 시트의 프로세스 관계에서 파생(정적 값). CORE=핵심 BCMS 프로세스 전반
B4: GOV | C4: POL | D4: REQ | E4: BIA | F4: RA | G4: STR | H4: PLAN | I4: IMP | J4: INC | K4: EXE | L4: AWR | M4: SUP | N4: AUD | O4: PERF | P4: CI | Q4: CHG | R4: WARN | S4: REC | T4: DOC | U4: RES | V4: COM | W4: CRM | X4: CORE
A5: GOV | C5: L24
A6: POL
A7: REQ | E7: L01 | F7: L02 | M7: L05 | N7: L04
A8: BIA | F8: L03 | G8: L06 | U8: L10
A9: RA | H9: L09 | Q9: L19
A10: STR | H10: L08 | I10: L07
A11: PLAN | J11: L11 | K11: L14 | L11: L15
A12: IMP
A13: INC | H13: L11 | Q13: L21 | R13: L12 | S13: L13
A14: EXE | H14: L14 | L14: L15 | Q14: L21
A15: AWR
A16: SUP | P16: L18
A17: AUD | P17: L17
A18: PERF | P18: L16
A19: CI
A20: CHG | F20: L19 | J20: L21 | K20: L21 | T20: L20
A21: WARN
A22: REC
A23: DOC
A24: RES | W24: L25 | X24: L25
A25: COM | B25: L23
A26: CRM
A27: CORE | V27: L22

Sheet 문항
A1: 문항은행 90문항 (연결 75 + 종합 6 + 검증 9)
A2: 전문가 패널 6인의 적합도(1 전혀 아님~4 매우 적합)를 L~Q열에 입력하면 I-CVI와 판정이 계산됩니다.
A4: 문항ID | B4: 파트 | C4: 영역 | D4: 연결 ID | E4: 연결 (A→B) | F4: 상태 | G4: 문항 | H4: 근거 등급 | I4: 척도 | J4: 응답입력 열 | K4: 추적성 점검 | L4: 전문가1 | M4: 전문가2 | N4: 전문가3 | O4: 전문가4 | P4: 전문가5 | Q4: 전문가6 | R4: I-CVI | S4: 판정
A5: L01-R | B5: C 연결 | C5: ① 요구·분석 | D5: L01 | E5: =IFERROR(INDEX(연결!$C$5:$C$29,MATCH(D5,연결!$A$5:$A$29,0)),"") -> REQ → BIA | F5: 반영 | G5: 우리 조직에서는 법규·규제·계약상 요구사항이 BIA의 우선순위와 복구목표 설정에 실제로 반영된다. | H5: =IFERROR(INDEX(연결!$F$5:$F$29,MATCH(D5,연결!$A$5:$A$29,0)),"") -> A | I5: 1–5 + 9(해당없음) | J5: AH | K5: =IF(COUNTIF($A$5:$A$94,A5)<>1,"ID 중복",IF(B5="C 연결",IF(COUNTIF(연결!$A$5:$A$29,D5)=1,"OK","연결 없음"),"OK")) -> OK | R5: =IFERROR(COUNTIF(L5:Q5,">=3")/COUNT(L5:Q5),"") | S5: =IF(R5="","",IF(R5>=검증!$B$4,"채택","수정·토론"))
A6: L01-V | B6: C 연결 | C6: ① 요구·분석 | D6: L01 | E6: =IFERROR(INDEX(연결!$C$5:$C$29,MATCH(D6,연결!$A$5:$A$29,0)),"") -> REQ → BIA | F6: 확인 | G6: 우리 조직에서는 BIA 결과에 요구사항이 빠짐없이 반영되었는지 검토 또는 점검 기록으로 확인한다. | H6: =IFERROR(INDEX(연결!$F$5:$F$29,MATCH(D6,연결!$A$5:$A$29,0)),"") -> A | I6: 1–5 + 9(해당없음) | J6: AI | K6: =IF(COUNTIF($A$5:$A$94,A6)<>1,"ID 중복",IF(B6="C 연결",IF(COUNTIF(연결!$A$5:$A$29,D6)=1,"OK","연결 없음"),"OK")) -> OK | R6: =IFERROR(COUNTIF(L6:Q6,">=3")/COUNT(L6:Q6),"") | S6: =IF(R6="","",IF(R6>=검증!$B$4,"채택","수정·토론"))
A7: L01-U | B7: C 연결 | C7: ① 요구·분석 | D7: L01 | E7: =IFERROR(INDEX(연결!$C$5:$C$29,MATCH(D7,연결!$A$5:$A$29,0)),"") -> REQ → BIA | F7: 갱신 | G7: 우리 조직에서는 요구사항이 바뀌면(신규 법규·계약 등) BIA 결과를 다시 검토하여 고친다. | H7: =IFERROR(INDEX(연결!$F$5:$F$29,MATCH(D7,연결!$A$5:$A$29,0)),"") -> A | I7: 1–5 + 9(해당없음) | J7: AJ | K7: =IF(COUNTIF($A$5:$A$94,A7)<>1,"ID 중복",IF(B7="C 연결",IF(COUNTIF(연결!$A$5:$A$29,D7)=1,"OK","연결 없음"),"OK")) -> OK | R7: =IFERROR(COUNTIF(L7:Q7,">=3")/COUNT(L7:Q7),"") | S7: =IF(R7="","",IF(R7>=검증!$B$4,"채택","수정·토론"))
A8: L02-R | B8: C 연결 | C8: ① 요구·분석 | D8: L02 | E8: =IFERROR(INDEX(연결!$C$5:$C$29,MATCH(D8,연결!$A$5:$A$29,0)),"") -> REQ → RA | F8: 반영 | G8: 우리 조직에서는 요구사항이 리스크평가의 대상 범위와 평가 기준에 반영된다. | H8: =IFERROR(INDEX(연결!$F$5:$F$29,MATCH(D8,연결!$A$5:$A$29,0)),"") -> A | I8: 1–5 + 9(해당없음) | J8: AK | K8: =IF(COUNTIF($A$5:$A$94,A8)<>1,"ID 중복",IF(B8="C 연결",IF(COUNTIF(연결!$A$5:$A$29,D8)=1,"OK","연결 없음"),"OK")) -> OK | R8: =IFERROR(COUNTIF(L8:Q8,">=3")/COUNT(L8:Q8),"") | S8: =IF(R8="","",IF(R8>=검증!$B$4,"채택","수정·토론"))
A9: L02-V | B9: C 연결 | C9: ① 요구·분석 | D9: L02 | E9: =IFERROR(INDEX(연결!$C$5:$C$29,MATCH(D9,연결!$A$5:$A$29,0)),"") -> REQ → RA | F9: 확인 | G9: 우리 조직에서는 리스크평가가 관련 요구사항을 고려했는지 확인하는 절차가 있다. | H9: =IFERROR(INDEX(연결!$F$5:$F$29,MATCH(D9,연결!$A$5:$A$29,0)),"") -> A | I9: 1–5 + 9(해당없음) | J9: AL | K9: =IF(COUNTIF($A$5:$A$94,A9)<>1,"ID 중복",IF(B9="C 연결",IF(COUNTIF(연결!$A$5:$A$29,D9)=1,"OK","연결 없음"),"OK")) -> OK | R9: =IFERROR(COUNTIF(L9:Q9,">=3")/COUNT(L9:Q9),"") | S9: =IF(R9="","",IF(R9>=검증!$B$4,"채택","수정·토론"))
A10: L02-U | B10: C 연결 | C10: ① 요구·분석 | D10: L02 | E10: =IFERROR(INDEX(연결!$C$5:$C$29,MATCH(D10,연결!$A$5:$A$29,0)),"") -> REQ → RA | F10: 갱신 | G10: 우리 조직에서는 요구사항이 바뀌면 리스크평가 기준이나 결과를 함께 고친다. | H10: =IFERROR(INDEX(연결!$F$5:$F$29,MATCH(D10,연결!$A$5:$A$29,0)),"") -> A | I10: 1–5 + 9(해당없음) | J10: AM | K10: =IF(COUNTIF($A$5:$A$94,A10)<>1,"ID 중복",IF(B10="C 연결",IF(COUNTIF(연결!$A$5:$A$29,D10)=1,"OK","연결 없음"),"OK")) -> OK | R10: =IFERROR(COUNTIF(L10:Q10,">=3")/COUNT(L10:Q10),"") | S10: =IF(R10="","",IF(R10>=검증!$B$4,"채택","수정·토론"))
A11: L03-R | B11: C 연결 | C11: ① 요구·분석 | D11: L03 | E11: =IFERROR(INDEX(연결!$C$5:$C$29,MATCH(D11,연결!$A$5:$A$29,0)),"") -> BIA → RA | F11: 반영 | G11: 우리 조직에서는 리스크평가가 BIA에서 정한 핵심 제품·서비스·활동의 우선순위를 출발점으로 삼는다. | H11: =IFERROR(INDEX(연결!$F$5:$F$29,MATCH(D11,연결!$A$5:$A$29,0)),"") -> A | I11: 1–5 + 9(해당없음) | J11: AN | K11: =IF(COUNTIF($A$5:$A$94,A11)<>1,"ID 중복",IF(B11="C 연결",IF(COUNTIF(연결!$A$5:$A$29,D11)=1,"OK","연결 없음"),"OK")) -> OK | R11: =IFERROR(COUNTIF(L11:Q11,">=3")/COUNT(L11:Q11),"") | S11: =IF(R11="","",IF(R11>=검증!$B$4,"채택","수정·토론"))
A12: L03-V | B12: C 연결 | C12: ① 요구·분석 | D12: L03 | E12: =IFERROR(INDEX(연결!$C$5:$C$29,MATCH(D12,연결!$A$5:$A$29,0)),"") -> BIA → RA | F12: 확인 | G12: 우리 조직에서는 리스크평가 대상이 BIA 결과와 일치하는지 서로 대조하여 확인한다. | H12: =IFERROR(INDEX(연결!$F$5:$F$29,MATCH(D12,연결!$A$5:$A$29,0)),"") -> A | I12: 1–5 + 9(해당없음) | J12: AO | K12: =IF(COUNTIF($A$5:$A$94,A12)<>1,"ID 중복",IF(B12="C 연결",IF(COUNTIF(연결!$A$5:$A$29,D12)=1,"OK","연결 없음"),"OK")) -> OK | R12: =IFERROR(COUNTIF(L12:Q12,">=3")/COUNT(L12:Q12),"") | S12: =IF(R12="","",IF(R12>=검증!$B$4,"채택","수정·토론"))
A13: L03-U | B13: C 연결 | C13: ① 요구·분석 | D13: L03 | E13: =IFERROR(INDEX(연결!$C$5:$C$29,MATCH(D13,연결!$A$5:$A$29,0)),"") -> BIA → RA | F13: 갱신 | G13: 우리 조직에서는 BIA 결과가 바뀌면 리스크 목록(리스크 카탈로그)도 함께 고친다. | H13: =IFERROR(INDEX(연결!$F$5:$F$29,MATCH(D13,연결!$A$5:$A$29,0)),"") -> A | I13: 1–5 + 9(해당없음) | J13: AP | K13: =IF(COUNTIF($A$5:$A$94,A13)<>1,"ID 중복",IF(B13="C 연결",IF(COUNTIF(연결!$A$5:$A$29,D13)=1,"OK","연결 없음"),"OK")) -> OK | R13: =IFERROR(COUNTIF(L13:Q13,">=3")/COUNT(L13:Q13),"") | S13: =IF(R13="","",IF(R13>=검증!$B$4,"채택","수정·토론"))
A14: L04-R | B14: C 연결 | C14: ① 요구·분석 | D14: L04 | E14: =IFERROR(INDEX(연결!$C$5:$C$29,MATCH(D14,연결!$A$5:$A$29,0)),"") -> REQ → AUD | F14: 반영 | G14: 우리 조직에서는 내부감사의 점검 기준에 BC 관련 요구사항이 포함되어 있다. | H14: =IFERROR(INDEX(연결!$F$5:$F$29,MATCH(D14,연결!$A$5:$A$29,0)),"") -> A | I14: 1–5 + 9(해당없음) | J14: AQ | K14: =IF(COUNTIF($A$5:$A$94,A14)<>1,"ID 중복",IF(B14="C 연결",IF(COUNTIF(연결!$A$5:$A$29,D14)=1,"OK","연결 없음"),"OK")) -> OK | R14: =IFERROR(COUNTIF(L14:Q14,">=3")/COUNT(L14:Q14),"") | S14: =IF(R14="","",IF(R14>=검증!$B$4,"채택","수정·토론"))
A15: L04-V | B15: C 연결 | C15: ① 요구·분석 | D15: L04 | E15: =IFERROR(INDEX(연결!$C$5:$C$29,MATCH(D15,연결!$A$5:$A$29,0)),"") -> REQ → AUD | F15: 확인 | G15: 우리 조직에서는 감사 때 요구사항 충족 여부를 항목별로 확인하고 기록한다. | H15: =IFERROR(INDEX(연결!$F$5:$F$29,MATCH(D15,연결!$A$5:$A$29,0)),"") -> A | I15: 1–5 + 9(해당없음) | J15: AR | K15: =IF(COUNTIF($A$5:$A$94,A15)<>1,"ID 중복",IF(B15="C 연결",IF(COUNTIF(연결!$A$5:$A$29,D15)=1,"OK","연결 없음"),"OK")) -> OK | R15: =IFERROR(COUNTIF(L15:Q15,">=3")/COUNT(L15:Q15),"") | S15: =IF(R15="","",IF(R15>=검증!$B$4,"채택","수정·토론"))
A16: L04-U | B16: C 연결 | C16: ① 요구·분석 | D16: L04 | E16: =IFERROR(INDEX(연결!$C$5:$C$29,MATCH(D16,연결!$A$5:$A$29,0)),"") -> REQ → AUD | F16: 갱신 | G16: 우리 조직에서는 요구사항이 바뀌면 감사 기준과 점검표를 고친다. | H16: =IFERROR(INDEX(연결!$F$5:$F$29,MATCH(D16,연결!$A$5:$A$29,0)),"") -> A | I16: 1–5 + 9(해당없음) | J16: AS | K16: =IF(COUNTIF($A$5:$A$94,A16)<>1,"ID 중복",IF(B16="C 연결",IF(COUNTIF(연결!$A$5:$A$29,D16)=1,"OK","연결 없음"),"OK")) -> OK | R16: =IFERROR(COUNTIF(L16:Q16,">=3")/COUNT(L16:Q16),"") | S16: =IF(R16="","",IF(R16>=검증!$B$4,"채택","수정·토론"))
... A79: L25-U | B79: C 연결 | C79: ⑤ 거버넌스·이해관계자 | D79: L25 | E79: =IFERROR(INDEX(연결!$C$5:$C$29,MATCH(D79,연결!$A$5:$A$29,0)),"") -> RES → 핵심 프로세스/CRM | F79: 갱신 | G79: 우리 조직에서는 자원 사용 보고 결과에 따라 자원 배분을 고친다. | H79: =IFERROR(INDEX(연결!$F$5:$F$29,MATCH(D79,연결!$A$5:$A$29,0)),"") -> A | I79: 1–5 + 9(해당없음) | J79: DD | K79: =IF(COUNTIF($A$5:$A$94,A79)<>1,"ID 중복",IF(B79="C 연결",IF(COUNTIF(연결!$A$5:$A$29,D79)=1,"OK","연결 없음"),"OK")) -> OK | R79: =IFERROR(COUNTIF(L79:Q79,">=3")/COUNT(L79:Q79),"") | S79: =IF(R79="","",IF(R79>=검증!$B$4,"채택","수정·토론"))
A80: G01 | B80: D 종합 | C80: 종합 | E80: =IFERROR(INDEX(연결!$C$5:$C$29,MATCH(D80,연결!$A$5:$A$29,0)),"") | F80: 종합 | G80: 우리 조직의 BC 프로세스들은 서로의 산출물을 입력으로 사용하며 연결되어 있다. | H80: =IFERROR(INDEX(연결!$F$5:$F$29,MATCH(D80,연결!$A$5:$A$29,0)),"") | I80: 1–5 + 9(해당없음) | J80: DE | K80: =IF(COUNTIF($A$5:$A$94,A80)<>1,"ID 중복",IF(B80="C 연결",IF(COUNTIF(연결!$A$5:$A$29,D80)=1,"OK","연결 없음"),"OK")) -> OK | R80: =IFERROR(COUNTIF(L80:Q80,">=3")/COUNT(L80:Q80),"") | S80: =IF(R80="","",IF(R80>=검증!$B$4,"채택","수정·토론"))
A81: G02 | B81: D 종합 | C81: 종합 | E81: =IFERROR(INDEX(연결!$C$5:$C$29,MATCH(D81,연결!$A$5:$A$29,0)),"") | F81: 종합 | G81: 한 BC 프로세스를 바꾸면 영향을 받는 다른 프로세스가 무엇인지 알 수 있다. | H81: =IFERROR(INDEX(연결!$F$5:$F$29,MATCH(D81,연결!$A$5:$A$29,0)),"") | I81: 1–5 + 9(해당없음) | J81: DF | K81: =IF(COUNTIF($A$5:$A$94,A81)<>1,"ID 중복",IF(B81="C 연결",IF(COUNTIF(연결!$A$5:$A$29,D81)=1,"OK","연결 없음"),"OK")) -> OK | R81: =IFERROR(COUNTIF(L81:Q81,">=3")/COUNT(L81:Q81),"") | S81: =IF(R81="","",IF(R81>=검증!$B$4,"채택","수정·토론"))
A82: G03 | B82: D 종합 | C82: 종합 | E82: =IFERROR(INDEX(연결!$C$5:$C$29,MATCH(D82,연결!$A$5:$A$29,0)),"") | F82: 종합 | G82: 프로세스 간에 "누가 누구에게 무엇을 전달하는지"가 문서로 정리되어 있다. | H82: =IFERROR(INDEX(연결!$F$5:$F$29,MATCH(D82,연결!$A$5:$A$29,0)),"") | I82: 1–5 + 9(해당없음) | J82: DG | K82: =IF(COUNTIF($A$5:$A$94,A82)<>1,"ID 중복",IF(B82="C 연결",IF(COUNTIF(연결!$A$5:$A$29,D82)=1,"OK","연결 없음"),"OK")) -> OK | R82: =IFERROR(COUNTIF(L82:Q82,">=3")/COUNT(L82:Q82),"") | S82: =IF(R82="","",IF(R82>=검증!$B$4,"채택","수정·토론"))
A83: G04 | B83: D 종합 | C83: 종합 | E83: =IFERROR(INDEX(연결!$C$5:$C$29,MATCH(D83,연결!$A$5:$A$29,0)),"") | F83: 종합 | G83: BC 관리자(또는 그에 준하는 담당자)가 프로세스 간 연결 상태를 총괄하여 점검한다. | H83: =IFERROR(INDEX(연결!$F$5:$F$29,MATCH(D83,연결!$A$5:$A$29,0)),"") | I83: 1–5 + 9(해당없음) | J83: DH | K83: =IF(COUNTIF($A$5:$A$94,A83)<>1,"ID 중복",IF(B83="C 연결",IF(COUNTIF(연결!$A$5:$A$29,D83)=1,"OK","연결 없음"),"OK")) -> OK | R83: =IFERROR(COUNTIF(L83:Q83,">=3")/COUNT(L83:Q83),"") | S83: =IF(R83="","",IF(R83>=검증!$B$4,"채택","수정·토론"))
A84: G05 | B84: D 종합 | C84: 종합 | E84: =IFERROR(INDEX(연결!$C$5:$C$29,MATCH(D84,연결!$A$5:$A$29,0)),"") | F84: 종합 | G84: 프로세스 간 연결이 끊어졌거나 약한 지점을 파악하여 조치한다. | H84: =IFERROR(INDEX(연결!$F$5:$F$29,MATCH(D84,연결!$A$5:$A$29,0)),"") | I84: 1–5 + 9(해당없음) | J84: DI | K84: =IF(COUNTIF($A$5:$A$94,A84)<>1,"ID 중복",IF(B84="C 연결",IF(COUNTIF(연결!$A$5:$A$29,D84)=1,"OK","연결 없음"),"OK")) -> OK | R84: =IFERROR(COUNTIF(L84:Q84,">=3")/COUNT(L84:Q84),"") | S84: =IF(R84="","",IF(R84>=검증!$B$4,"채택","수정·토론"))
A85: G06 | B85: D 종합 | C85: 종합 | E85: =IFERROR(INDEX(연결!$C$5:$C$29,MATCH(D85,연결!$A$5:$A$29,0)),"") | F85: 종합 | G85: 프로세스 간 연결은 일회성 프로젝트가 아니라 정기적으로 반복되는 운영 활동으로 유지된다. | H85: =IFERROR(INDEX(연결!$F$5:$F$29,MATCH(D85,연결!$A$5:$A$29,0)),"") | I85: 1–5 + 9(해당없음) | J85: DJ | K85: =IF(COUNTIF($A$5:$A$94,A85)<>1,"ID 중복",IF(B85="C 연결",IF(COUNTIF(연결!$A$5:$A$29,D85)=1,"OK","연결 없음"),"OK")) -> OK | R85: =IFERROR(COUNTIF(L85:Q85,">=3")/COUNT(L85:Q85),"") | S85: =IF(R85="","",IF(R85>=검증!$B$4,"채택","수정·토론"))
A86: RV1 | B86: E 검증(역문항) | C86: 검증 | E86: =IFERROR(INDEX(연결!$C$5:$C$29,MATCH(D86,연결!$A$5:$A$29,0)),"") | F86: 역문항(↔G01) | G86: 우리 조직의 BC 프로세스는 대부분 다른 프로세스와 별개로 독립적으로 수행된다. | H86: =IFERROR(INDEX(연결!$F$5:$F$29,MATCH(D86,연결!$A$5:$A$29,0)),"") | I86: 1–5 + 9(해당없음) | J86: DK | K86: =IF(COUNTIF($A$5:$A$94,A86)<>1,"ID 중복",IF(B86="C 연결",IF(COUNTIF(연결!$A$5:$A$29,D86)=1,"OK","연결 없음"),"OK")) -> OK | R86: =IFERROR(COUNTIF(L86:Q86,">=3")/COUNT(L86:Q86),"") | S86: =IF(R86="","",IF(R86>=검증!$B$4,"채택","수정·토론"))
A87: RV2 | B87: E 검증(역문항) | C87: 검증 | E87: =IFERROR(INDEX(연결!$C$5:$C$29,MATCH(D87,연결!$A$5:$A$29,0)),"") | F87: 역문항(↔L01~L03) | G87: 한 프로세스의 결과물이 만들어진 뒤 다른 프로세스에서 참조되지 않는 경우가 많다. | H87: =IFERROR(INDEX(연결!$F$5:$F$29,MATCH(D87,연결!$A$5:$A$29,0)),"") | I87: 1–5 + 9(해당없음) | J87: DL | K87: =IF(COUNTIF($A$5:$A$94,A87)<>1,"ID 중복",IF(B87="C 연결",IF(COUNTIF(연결!$A$5:$A$29,D87)=1,"OK","연결 없음"),"OK")) -> OK | R87: =IFERROR(COUNTIF(L87:Q87,">=3")/COUNT(L87:Q87),"") | S87: =IF(R87="","",IF(R87>=검증!$B$4,"채택","수정·토론"))
A88: RV3 | B88: E 검증(역문항) | C88: 검증 | E88: =IFERROR(INDEX(연결!$C$5:$C$29,MATCH(D88,연결!$A$5:$A$29,0)),"") | F88: 역문항(↔L20) | G88: 문서가 개정되어도 관련 프로세스 담당자에게는 따로 알리지 않는 경우가 많다. | H88: =IFERROR(INDEX(연결!$F$5:$F$29,MATCH(D88,연결!$A$5:$A$29,0)),"") | I88: 1–5 + 9(해당없음) | J88: DM | K88: =IF(COUNTIF($A$5:$A$94,A88)<>1,"ID 중복",IF(B88="C 연결",IF(COUNTIF(연결!$A$5:$A$29,D88)=1,"OK","연결 없음"),"OK")) -> OK | R88: =IFERROR(COUNTIF(L88:Q88,">=3")/COUNT(L88:Q88),"") | S88: =IF(R88="","",IF(R88>=검증!$B$4,"채택","수정·토론"))
A89: RV4 | B89: E 검증(역문항) | C89: 검증 | E89: =IFERROR(INDEX(연결!$C$5:$C$29,MATCH(D89,연결!$A$5:$A$29,0)),"") | F89: 역문항(↔L14) | G89: 연습 결과가 BC 계획·절차 개정으로 이어지지 않는 경우가 많다. | H89: =IFERROR(INDEX(연결!$F$5:$F$29,MATCH(D89,연결!$A$5:$A$29,0)),"") | I89: 1–5 + 9(해당없음) | J89: DN | K89: =IF(COUNTIF($A$5:$A$94,A89)<>1,"ID 중복",IF(B89="C 연결",IF(COUNTIF(연결!$A$5:$A$29,D89)=1,"OK","연결 없음"),"OK")) -> OK | R89: =IFERROR(COUNTIF(L89:Q89,">=3")/COUNT(L89:Q89),"") | S89: =IF(R89="","",IF(R89>=검증!$B$4,"채택","수정·토론"))
A90: AC1 | B90: E 검증(주의확인) | C90: 검증 | E90: =IFERROR(INDEX(연결!$C$5:$C$29,MATCH(D90,연결!$A$5:$A$29,0)),"") | F90: 주의확인 | G90: 이 문항에서는 응답 4번을 선택해 주십시오. | H90: =IFERROR(INDEX(연결!$F$5:$F$29,MATCH(D90,연결!$A$5:$A$29,0)),"") | I90: 1–5 + 9(해당없음) | J90: DO | K90: =IF(COUNTIF($A$5:$A$94,A90)<>1,"ID 중복",IF(B90="C 연결",IF(COUNTIF(연결!$A$5:$A$29,D90)=1,"OK","연결 없음"),"OK")) -> OK | R90: =IFERROR(COUNTIF(L90:Q90,">=3")/COUNT(L90:Q90),"") | S90: =IF(R90="","",IF(R90>=검증!$B$4,"채택","수정·토론"))
A91: CR1 | B91: E 검증(준거) | C91: 검증 | E91: =IFERROR(INDEX(연결!$C$5:$C$29,MATCH(D91,연결!$A$5:$A$29,0)),"") | F91: 준거 | G91: 중단 사건이 발생해도 우리 조직의 BCMS가 효과적으로 대응할 수 있다고 확신한다. | H91: =IFERROR(INDEX(연결!$F$5:$F$29,MATCH(D91,연결!$A$5:$A$29,0)),"") | I91: 1–5 + 9(해당없음) | J91: DP | K91: =IF(COUNTIF($A$5:$A$94,A91)<>1,"ID 중복",IF(B91="C 연결",IF(COUNTIF(연결!$A$5:$A$29,D91)=1,"OK","연결 없음"),"OK")) -> OK | R91: =IFERROR(COUNTIF(L91:Q91,">=3")/COUNT(L91:Q91),"") | S91: =IF(R91="","",IF(R91>=검증!$B$4,"채택","수정·토론"))
... A94: CR4 | B94: E 검증(준거) | C94: 검증 | E94: =IFERROR(INDEX(연결!$C$5:$C$29,MATCH(D94,연결!$A$5:$A$29,0)),"") | F94: 준거(역) | G94: 감사나 경영진 검토에서 같은 BCMS 지적사항이 반복된다. | H94: =IFERROR(INDEX(연결!$F$5:$F$29,MATCH(D94,연결!$A$5:$A$29,0)),"") | I94: 1–5 + 9(해당없음) | J94: DS | K94: =IF(COUNTIF($A$5:$A$94,A94)<>1,"ID 중복",IF(B94="C 연결",IF(COUNTIF(연결!$A$5:$A$29,D94)=1,"OK","연결 없음"),"OK")) -> OK | R94: =IFERROR(COUNTIF(L94:Q94,">=3")/COUNT(L94:Q94),"") | S94: =IF(R94="","",IF(R94>=검증!$B$4,"채택","수정·토론"))

Sheet 보유·응답자정보
A1: Part A 응답자·조직 정보(10) / Part B 프로세스 보유 확인(22)
A2: Part B: 1 운영한다 · 2 부분적으로 운영한다 · 3 운영하지 않는다 · 4 모르겠다. 연결 문항은 양쪽 프로세스가 1·2일 때만 응답하도록 안내.
A4: ID | B4: 구분 | C4: 항목 | D4: 응답 방식 | E4: 응답입력 열
A5: A01 | B5: Part A | C5: 업종 | D5: 자유 기재 | E5: B
A6: A02 | B6: Part A | C6: 조직 규모(임직원 수) | D6: 1~49 / 50~299 / 300~999 / 1000 이상 | E6: C
A7: A03 | B7: Part A | C7: BCMS 운영 기간 | D7: 1년 미만 / 1~3년 / 3~5년 / 5년 이상 | E7: D
A8: A04 | B8: Part A | C8: ISO 22301 인증 여부 | D8: 보유 / 준비 중 / 없음 | E8: E
A9: A05 | B9: Part A | C9: 응답자 역할 | D9: BC 관리자 / 프로세스 담당자 / 경영진 / 감사·기타 | E9: F
A10: A06 | B10: Part A | C10: BC 관련 업무 경력 | D10: 연수 | E10: G
A11: A07 | B11: Part A | C11: 최근 12개월 실제 중단 사고 경험 | D11: 없음 / 있음(횟수) | E11: H
A12: A08 | B12: Part A | C12: 최근 12개월 연습·훈련 횟수 | D12: 횟수 | E12: I
A13: A09 | B13: Part A | C13: ISMS 등 타 경영시스템과 통합 운영 여부 | D13: 통합 / 부분 / 별도 | E13: J
A14: A10 | B14: Part A | C14: BC 프로세스 문서화 정도 | D14: 전부 / 일부 / 거의 없음 | E14: K
A15: B01 | B15: Part B | C15: BC 거버넌스 | D15: 1 운영 / 2 부분 / 3 미운영 / 4 모름 | E15: L
... A36: B22 | B36: Part B | C36: 고객관계관리 | D36: 1 운영 / 2 부분 / 3 미운영 / 4 모름 | E36: AG

Sheet 응답입력
A1: 응답 입력 (7행부터 최대 50명)
A2: 6행은 예시(집계 제외). 연결 문항: 1~5 또는 9. 보유 확인: 1~4.
A4: 응답자 | B4: Part A | L4: Part B | AH4: Part C 연결 문항 | DE4: Part D 종합 | DK4: Part E 검증
A5: 응답자ID | B5: A01 | C5: A02 | D5: A03 | E5: A04 | F5: A05 | G5: A06 | H5: A07 | I5: A08 | J5: A09 | K5: A10 | L5: B01 | M5: B02 | N5: B03 | O5: B04 | P5: B05 | Q5: B06 | R5: B07 | S5: B08 | T5: B09 | U5: B10 | V5: B11 | W5: B12 | X5: B13 | Y5: B14 | Z5: B15 | AA5: B16 | AB5: B17 | AC5: B18 | AD5: B19 | AE5: B20 | AF5: B21 | AG5: B22 | AH5: L01-R | AI5: L01-V | AJ5: L01-U | AK5: L02-R | AL5: L02-V | AM5: L02-U | AN5: L03-R | AO5: L03-V | AP5: L03-U | AQ5: L04-R | AR5: L04-V | AS5: L04-U | AT5: L05-R | AU5: L05-V | AV5: L05-U | AW5: L06-R | AX5: L06-V | AY5: L06-U | AZ5: L07-R | BA5: L07-V | BB5: L07-U | BC5: L08-R | BD5: L08-V | BE5: L08-U | BF5: L09-R | BG5: L09-V | BH5: L09-U | BI5: L10-R | BJ5: L10-V | BK5: L10-U | BL5: L11-R | BM5: L11-V | BN5: L11-U | BO5: L12-R | BP5: L12-V | BQ5: L12-U | BR5: L13-R | BS5: L13-V | BT5: L13-U | BU5: L14-R | BV5: L14-V | BW5: L14-U | BX5: L15-R | BY5: L15-V | BZ5: L15-U | CA5: L16-R | CB5: L16-V | CC5: L16-U | CD5: L17-R | CE5: L17-V | CF5: L17-U | CG5: L18-R | CH5: L18-V | CI5: L18-U | CJ5: L19-R | CK5: L19-V | CL5: L19-U | CM5: L20-R | CN5: L20-V | CO5: L20-U | CP5: L21-R | CQ5: L21-V | CR5: L21-U | CS5: L22-R | CT5: L22-V | CU5: L22-U | CV5: L23-R | CW5: L23-V | CX5: L23-U | CY5: L24-R | CZ5: L24-V | DA5: L24-U | DB5: L25-R | DC5: L25-V | DD5: L25-U | DE5: G01 | DF5: G02 | DG5: G03 | DH5: G04 | DI5: G05 | DJ5: G06 | DK5: RV1 | DL5: RV2 | DM5: RV3 | DN5: RV4 | DO5: AC1 | DP5: CR1 | DQ5: CR2 | DR5: CR3 | DS5: CR4
A6: EX-예시 | B6: 제조업 | C6: 300~999 | D6: 3~5년 | E6: 보유 | F6: BC 관리자 | G6: 8 | H6: 1 | I6: 2 | J6: 부분 | K6: 일부 | L6: 1 | M6: 1 | N6: 1 | O6: 1 | P6: 1 | Q6: 1 | R6: 1 | S6: 1 | T6: 1 | U6: 1 | V6: 1 | W6: 1 | X6: 1 | Y6: 1 | Z6: 1 | AA6: 1 | AB6: 1 | AC6: 1 | AD6: 1 | AE6: 1 | AF6: 1 | AG6: 1 | AH6: 3 | AI6: 9 | AJ6: 4 | AK6: 4 | AL6: 3 | AM6: 4 | AN6: 3 | AO6: 5 | AP6: 4 | AQ6: 3 | AR6: 9 | AS6: 4 | AT6: 4 | AU6: 3 | AV6: 4 | AW6: 3 | AX6: 5 | AY6: 4 | AZ6: 3 | BA6: 9 | BB6: 4 | BC6: 4 | BD6: 3 | BE6: 4 | BF6: 3 | BG6: 5 | BH6: 4 | BI6: 3 | BJ6: 9 | BK6: 4 | BL6: 4 | BM6: 3 | BN6: 4 | BO6: 3 | BP6: 5 | BQ6: 4 | BR6: 3 | BS6: 9 | BT6: 4 | BU6: 4 | BV6: 3 | BW6: 4 | BX6: 3 | BY6: 5 | BZ6: 4 | CA6: 3 | CB6: 9 | CC6: 4 | CD6: 4 | CE6: 3 | CF6: 4 | CG6: 3 | CH6: 5 | CI6: 4 | CJ6: 3 | CK6: 9 | CL6: 4 | CM6: 4 | CN6: 3 | CO6: 4 | CP6: 3 | CQ6: 5 | CR6: 4 | CS6: 3 | CT6: 9 | CU6: 4 | CV6: 4 | CW6: 3 | CX6: 4 | CY6: 3 | CZ6: 5 | DA6: 4 | DB6: 3 | DC6: 9 | DD6: 4 | DE6: 4 | DF6: 3 | DG6: 4 | DH6: 3 | DI6: 5 | DJ6: 4 | DK6: 3 | DL6: 9 | DM6: 4 | DN6: 4 | DO6: 3 | DP6: 4 | DQ6: 3 | DR6: 5 | DS6: 4

Sheet 연결점수
A1: 응답자별 연결 점수 (= 반영·확인·갱신 3문항 평균, 9 제외, 최소 2문항 응답 시 산출)
A5: 응답자ID | B5: L01 | C5: L02 | D5: L03 | E5: L04 | F5: L05 | G5: L06 | H5: L07 | I5: L08 | J5: L09 | K5: L10 | L5: L11 | M5: L12 | N5: L13 | O5: L14 | P5: L15 | Q5: L16 | R5: L17 | S5: L18 | T5: L19 | U5: L20 | V5: L21 | W5: L22 | X5: L23 | Y5: L24 | Z5: L25 | AA5: 종합 연결 지수
A6: =IF(응답입력!A7="","",응답입력!A7) | B6: =IF(COUNTIF(응답입력!AH7:AJ7,"<9")>=2,AVERAGEIF(응답입력!AH7:AJ7,"<9"),"") | C6: =IF(COUNTIF(응답입력!AK7:AM7,"<9")>=2,AVERAGEIF(응답입력!AK7:AM7,"<9"),"") | D6: =IF(COUNTIF(응답입력!AN7:AP7,"<9")>=2,AVERAGEIF(응답입력!AN7:AP7,"<9"),"") | E6: =IF(COUNTIF(응답입력!AQ7:AS7,"<9")>=2,AVERAGEIF(응답입력!AQ7:AS7,"<9"),"") | F6: =IF(COUNTIF(응답입력!AT7:AV7,"<9")>=2,AVERAGEIF(응답입력!AT7:AV7,"<9"),"") | G6: =IF(COUNTIF(응답입력!AW7:AY7,"<9")>=2,AVERAGEIF(응답입력!AW7:AY7,"<9"),"") | H6: =IF(COUNTIF(응답입력!AZ7:BB7,"<9")>=2,AVERAGEIF(응답입력!AZ7:BB7,"<9"),"") | I6: =IF(COUNTIF(응답입력!BC7:BE7,"<9")>=2,AVERAGEIF(응답입력!BC7:BE7,"<9"),"") | J6: =IF(COUNTIF(응답입력!BF7:BH7,"<9")>=2,AVERAGEIF(응답입력!BF7:BH7,"<9"),"") | K6: =IF(COUNTIF(응답입력!BI7:BK7,"<9")>=2,AVERAGEIF(응답입력!BI7:BK7,"<9"),"") | L6: =IF(COUNTIF(응답입력!BL7:BN7,"<9")>=2,AVERAGEIF(응답입력!BL7:BN7,"<9"),"") | M6: =IF(COUNTIF(응답입력!BO7:BQ7,"<9")>=2,AVERAGEIF(응답입력!BO7:BQ7,"<9"),"") | N6: =IF(COUNTIF(응답입력!BR7:BT7,"<9")>=2,AVERAGEIF(응답입력!BR7:BT7,"<9"),"") | O6: =IF(COUNTIF(응답입력!BU7:BW7,"<9")>=2,AVERAGEIF(응답입력!BU7:BW7,"<9"),"") | P6: =IF(COUNTIF(응답입력!BX7:BZ7,"<9")>=2,AVERAGEIF(응답입력!BX7:BZ7,"<9"),"") | Q6: =IF(COUNTIF(응답입력!CA7:CC7,"<9")>=2,AVERAGEIF(응답입력!CA7:CC7,"<9"),"") | R6: =IF(COUNTIF(응답입력!CD7:CF7,"<9")>=2,AVERAGEIF(응답입력!CD7:CF7,"<9"),"") | S6: =IF(COUNTIF(응답입력!CG7:CI7,"<9")>=2,AVERAGEIF(응답입력!CG7:CI7,"<9"),"") | T6: =IF(COUNTIF(응답입력!CJ7:CL7,"<9")>=2,AVERAGEIF(응답입력!CJ7:CL7,"<9"),"") | U6: =IF(COUNTIF(응답입력!CM7:CO7,"<9")>=2,AVERAGEIF(응답입력!CM7:CO7,"<9"),"") | V6: =IF(COUNTIF(응답입력!CP7:CR7,"<9")>=2,AVERAGEIF(응답입력!CP7:CR7,"<9"),"") | W6: =IF(COUNTIF(응답입력!CS7:CU7,"<9")>=2,AVERAGEIF(응답입력!CS7:CU7,"<9"),"") | X6: =IF(COUNTIF(응답입력!CV7:CX7,"<9")>=2,AVERAGEIF(응답입력!CV7:CX7,"<9"),"") | Y6: =IF(COUNTIF(응답입력!CY7:DA7,"<9")>=2,AVERAGEIF(응답입력!CY7:DA7,"<9"),"") | Z6: =IF(COUNTIF(응답입력!DB7:DD7,"<9")>=2,AVERAGEIF(응답입력!DB7:DD7,"<9"),"") | AA6: =IFERROR(AVERAGE(B6:Z6),"")
A7: =IF(응답입력!A8="","",응답입력!A8) | B7: =IF(COUNTIF(응답입력!AH8:AJ8,"<9")>=2,AVERAGEIF(응답입력!AH8:AJ8,"<9"),"") | C7: =IF(COUNTIF(응답입력!AK8:AM8,"<9")>=2,AVERAGEIF(응답입력!AK8:AM8,"<9"),"") | D7: =IF(COUNTIF(응답입력!AN8:AP8,"<9")>=2,AVERAGEIF(응답입력!AN8:AP8,"<9"),"") | E7: =IF(COUNTIF(응답입력!AQ8:AS8,"<9")>=2,AVERAGEIF(응답입력!AQ8:AS8,"<9"),"") | F7: =IF(COUNTIF(응답입력!AT8:AV8,"<9")>=2,AVERAGEIF(응답입력!AT8:AV8,"<9"),"") | G7: =IF(COUNTIF(응답입력!AW8:AY8,"<9")>=2,AVERAGEIF(응답입력!AW8:AY8,"<9"),"") | H7: =IF(COUNTIF(응답입력!AZ8:BB8,"<9")>=2,AVERAGEIF(응답입력!AZ8:BB8,"<9"),"") | I7: =IF(COUNTIF(응답입력!BC8:BE8,"<9")>=2,AVERAGEIF(응답입력!BC8:BE8,"<9"),"") | J7: =IF(COUNTIF(응답입력!BF8:BH8,"<9")>=2,AVERAGEIF(응답입력!BF8:BH8,"<9"),"") | K7: =IF(COUNTIF(응답입력!BI8:BK8,"<9")>=2,AVERAGEIF(응답입력!BI8:BK8,"<9"),"") | L7: =IF(COUNTIF(응답입력!BL8:BN8,"<9")>=2,AVERAGEIF(응답입력!BL8:BN8,"<9"),"") | M7: =IF(COUNTIF(응답입력!BO8:BQ8,"<9")>=2,AVERAGEIF(응답입력!BO8:BQ8,"<9"),"") | N7: =IF(COUNTIF(응답입력!BR8:BT8,"<9")>=2,AVERAGEIF(응답입력!BR8:BT8,"<9"),"") | O7: =IF(COUNTIF(응답입력!BU8:BW8,"<9")>=2,AVERAGEIF(응답입력!BU8:BW8,"<9"),"") | P7: =IF(COUNTIF(응답입력!BX8:BZ8,"<9")>=2,AVERAGEIF(응답입력!BX8:BZ8,"<9"),"") | Q7: =IF(COUNTIF(응답입력!CA8:CC8,"<9")>=2,AVERAGEIF(응답입력!CA8:CC8,"<9"),"") | R7: =IF(COUNTIF(응답입력!CD8:CF8,"<9")>=2,AVERAGEIF(응답입력!CD8:CF8,"<9"),"") | S7: =IF(COUNTIF(응답입력!CG8:CI8,"<9")>=2,AVERAGEIF(응답입력!CG8:CI8,"<9"),"") | T7: =IF(COUNTIF(응답입력!CJ8:CL8,"<9")>=2,AVERAGEIF(응답입력!CJ8:CL8,"<9"),"") | U7: =IF(COUNTIF(응답입력!CM8:CO8,"<9")>=2,AVERAGEIF(응답입력!CM8:CO8,"<9"),"") | V7: =IF(COUNTIF(응답입력!CP8:CR8,"<9")>=2,AVERAGEIF(응답입력!CP8:CR8,"<9"),"") | W7: =IF(COUNTIF(응답입력!CS8:CU8,"<9")>=2,AVERAGEIF(응답입력!CS8:CU8,"<9"),"") | X7: =IF(COUNTIF(응답입력!CV8:CX8,"<9")>=2,AVERAGEIF(응답입력!CV8:CX8,"<9"),"") | Y7: =IF(COUNTIF(응답입력!CY8:DA8,"<9")>=2,AVERAGEIF(응답입력!CY8:DA8,"<9"),"") | Z7: =IF(COUNTIF(응답입력!DB8:DD8,"<9")>=2,AVERAGEIF(응답입력!DB8:DD8,"<9"),"") | AA7: =IFERROR(AVERAGE(B7:Z7),"")
A8: =IF(응답입력!A9="","",응답입력!A9) | B8: =IF(COUNTIF(응답입력!AH9:AJ9,"<9")>=2,AVERAGEIF(응답입력!AH9:AJ9,"<9"),"") | C8: =IF(COUNTIF(응답입력!AK9:AM9,"<9")>=2,AVERAGEIF(응답입력!AK9:AM9,"<9"),"") | D8: =IF(COUNTIF(응답입력!AN9:AP9,"<9")>=2,AVERAGEIF(응답입력!AN9:AP9,"<9"),"") | E8: =IF(COUNTIF(응답입력!AQ9:AS9,"<9")>=2,AVERAGEIF(응답입력!AQ9:AS9,"<9"),"") | F8: =IF(COUNTIF(응답입력!AT9:AV9,"<9")>=2,AVERAGEIF(응답입력!AT9:AV9,"<9"),"") | G8: =IF(COUNTIF(응답입력!AW9:AY9,"<9")>=2,AVERAGEIF(응답입력!AW9:AY9,"<9"),"") | H8: =IF(COUNTIF(응답입력!AZ9:BB9,"<9")>=2,AVERAGEIF(응답입력!AZ9:BB9,"<9"),"") | I8: =IF(COUNTIF(응답입력!BC9:BE9,"<9")>=2,AVERAGEIF(응답입력!BC9:BE9,"<9"),"") | J8: =IF(COUNTIF(응답입력!BF9:BH9,"<9")>=2,AVERAGEIF(응답입력!BF9:BH9,"<9"),"") | K8: =IF(COUNTIF(응답입력!BI9:BK9,"<9")>=2,AVERAGEIF(응답입력!BI9:BK9,"<9"),"") | L8: =IF(COUNTIF(응답입력!BL9:BN9,"<9")>=2,AVERAGEIF(응답입력!BL9:BN9,"<9"),"") | M8: =IF(COUNTIF(응답입력!BO9:BQ9,"<9")>=2,AVERAGEIF(응답입력!BO9:BQ9,"<9"),"") | N8: =IF(COUNTIF(응답입력!BR9:BT9,"<9")>=2,AVERAGEIF(응답입력!BR9:BT9,"<9"),"") | O8: =IF(COUNTIF(응답입력!BU9:BW9,"<9")>=2,AVERAGEIF(응답입력!BU9:BW9,"<9"),"") | P8: =IF(COUNTIF(응답입력!BX9:BZ9,"<9")>=2,AVERAGEIF(응답입력!BX9:BZ9,"<9"),"") | Q8: =IF(COUNTIF(응답입력!CA9:CC9,"<9")>=2,AVERAGEIF(응답입력!CA9:CC9,"<9"),"") | R8: =IF(COUNTIF(응답입력!CD9:CF9,"<9")>=2,AVERAGEIF(응답입력!CD9:CF9,"<9"),"") | S8: =IF(COUNTIF(응답입력!CG9:CI9,"<9")>=2,AVERAGEIF(응답입력!CG9:CI9,"<9"),"") | T8: =IF(COUNTIF(응답입력!CJ9:CL9,"<9")>=2,AVERAGEIF(응답입력!CJ9:CL9,"<9"),"") | U8: =IF(COUNTIF(응답입력!CM9:CO9,"<9")>=2,AVERAGEIF(응답입력!CM9:CO9,"<9"),"") | V8: =IF(COUNTIF(응답입력!CP9:CR9,"<9")>=2,AVERAGEIF(응답입력!CP9:CR9,"<9"),"") | W8: =IF(COUNTIF(응답입력!CS9:CU9,"<9")>=2,AVERAGEIF(응답입력!CS9:CU9,"<9"),"") | X8: =IF(COUNTIF(응답입력!CV9:CX9,"<9")>=2,AVERAGEIF(응답입력!CV9:CX9,"<9"),"") | Y8: =IF(COUNTIF(응답입력!CY9:DA9,"<9")>=2,AVERAGEIF(응답입력!CY9:DA9,"<9"),"") | Z8: =IF(COUNTIF(응답입력!DB9:DD9,"<9")>=2,AVERAGEIF(응답입력!DB9:DD9,"<9"),"") | AA8: =IFERROR(AVERAGE(B8:Z8),"")
A9: =IF(응답입력!A10="","",응답입력!A10) | B9: =IF(COUNTIF(응답입력!AH10:AJ10,"<9")>=2,AVERAGEIF(응답입력!AH10:AJ10,"<9"),"") | C9: =IF(COUNTIF(응답입력!AK10:AM10,"<9")>=2,AVERAGEIF(응답입력!AK10:AM10,"<9"),"") | D9: =IF(COUNTIF(응답입력!AN10:AP10,"<9")>=2,AVERAGEIF(응답입력!AN10:AP10,"<9"),"") | E9: =IF(COUNTIF(응답입력!AQ10:AS10,"<9")>=2,AVERAGEIF(응답입력!AQ10:AS10,"<9"),"") | F9: =IF(COUNTIF(응답입력!AT10:AV10,"<9")>=2,AVERAGEIF(응답입력!AT10:AV10,"<9"),"") | G9: =IF(COUNTIF(응답입력!AW10:AY10,"<9")>=2,AVERAGEIF(응답입력!AW10:AY10,"<9"),"") | H9: =IF(COUNTIF(응답입력!AZ10:BB10,"<9")>=2,AVERAGEIF(응답입력!AZ10:BB10,"<9"),"") | I9: =IF(COUNTIF(응답입력!BC10:BE10,"<9")>=2,AVERAGEIF(응답입력!BC10:BE10,"<9"),"") | J9: =IF(COUNTIF(응답입력!BF10:BH10,"<9")>=2,AVERAGEIF(응답입력!BF10:BH10,"<9"),"") | K9: =IF(COUNTIF(응답입력!BI10:BK10,"<9")>=2,AVERAGEIF(응답입력!BI10:BK10,"<9"),"") | L9: =IF(COUNTIF(응답입력!BL10:BN10,"<9")>=2,AVERAGEIF(응답입력!BL10:BN10,"<9"),"") | M9: =IF(COUNTIF(응답입력!BO10:BQ10,"<9")>=2,AVERAGEIF(응답입력!BO10:BQ10,"<9"),"") | N9: =IF(COUNTIF(응답입력!BR10:BT10,"<9")>=2,AVERAGEIF(응답입력!BR10:BT10,"<9"),"") | O9: =IF(COUNTIF(응답입력!BU10:BW10,"<9")>=2,AVERAGEIF(응답입력!BU10:BW10,"<9"),"") | P9: =IF(COUNTIF(응답입력!BX10:BZ10,"<9")>=2,AVERAGEIF(응답입력!BX10:BZ10,"<9"),"") | Q9: =IF(COUNTIF(응답입력!CA10:CC10,"<9")>=2,AVERAGEIF(응답입력!CA10:CC10,"<9"),"") | R9: =IF(COUNTIF(응답입력!CD10:CF10,"<9")>=2,AVERAGEIF(응답입력!CD10:CF10,"<9"),"") | S9: =IF(COUNTIF(응답입력!CG10:CI10,"<9")>=2,AVERAGEIF(응답입력!CG10:CI10,"<9"),"") | T9: =IF(COUNTIF(응답입력!CJ10:CL10,"<9")>=2,AVERAGEIF(응답입력!CJ10:CL10,"<9"),"") | U9: =IF(COUNTIF(응답입력!CM10:CO10,"<9")>=2,AVERAGEIF(응답입력!CM10:CO10,"<9"),"") | V9: =IF(COUNTIF(응답입력!CP10:CR10,"<9")>=2,AVERAGEIF(응답입력!CP10:CR10,"<9"),"") | W9: =IF(COUNTIF(응답입력!CS10:CU10,"<9")>=2,AVERAGEIF(응답입력!CS10:CU10,"<9"),"") | X9: =IF(COUNTIF(응답입력!CV10:CX10,"<9")>=2,AVERAGEIF(응답입력!CV10:CX10,"<9"),"") | Y9: =IF(COUNTIF(응답입력!CY10:DA10,"<9")>=2,AVERAGEIF(응답입력!CY10:DA10,"<9"),"") | Z9: =IF(COUNTIF(응답입력!DB10:DD10,"<9")>=2,AVERAGEIF(응답입력!DB10:DD10,"<9"),"") | AA9: =IFERROR(AVERAGE(B9:Z9),"")
A10: =IF(응답입력!A11="","",응답입력!A11) | B10: =IF(COUNTIF(응답입력!AH11:AJ11,"<9")>=2,AVERAGEIF(응답입력!AH11:AJ11,"<9"),"") | C10: =IF(COUNTIF(응답입력!AK11:AM11,"<9")>=2,AVERAGEIF(응답입력!AK11:AM11,"<9"),"") | D10: =IF(COUNTIF(응답입력!AN11:AP11,"<9")>=2,AVERAGEIF(응답입력!AN11:AP11,"<9"),"") | E10: =IF(COUNTIF(응답입력!AQ11:AS11,"<9")>=2,AVERAGEIF(응답입력!AQ11:AS11,"<9"),"") | F10: =IF(COUNTIF(응답입력!AT11:AV11,"<9")>=2,AVERAGEIF(응답입력!AT11:AV11,"<9"),"") | G10: =IF(COUNTIF(응답입력!AW11:AY11,"<9")>=2,AVERAGEIF(응답입력!AW11:AY11,"<9"),"") | H10: =IF(COUNTIF(응답입력!AZ11:BB11,"<9")>=2,AVERAGEIF(응답입력!AZ11:BB11,"<9"),"") | I10: =IF(COUNTIF(응답입력!BC11:BE11,"<9")>=2,AVERAGEIF(응답입력!BC11:BE11,"<9"),"") | J10: =IF(COUNTIF(응답입력!BF11:BH11,"<9")>=2,AVERAGEIF(응답입력!BF11:BH11,"<9"),"") | K10: =IF(COUNTIF(응답입력!BI11:BK11,"<9")>=2,AVERAGEIF(응답입력!BI11:BK11,"<9"),"") | L10: =IF(COUNTIF(응답입력!BL11:BN11,"<9")>=2,AVERAGEIF(응답입력!BL11:BN11,"<9"),"") | M10: =IF(COUNTIF(응답입력!BO11:BQ11,"<9")>=2,AVERAGEIF(응답입력!BO11:BQ11,"<9"),"") | N10: =IF(COUNTIF(응답입력!BR11:BT11,"<9")>=2,AVERAGEIF(응답입력!BR11:BT11,"<9"),"") | O10: =IF(COUNTIF(응답입력!BU11:BW11,"<9")>=2,AVERAGEIF(응답입력!BU11:BW11,"<9"),"") | P10: =IF(COUNTIF(응답입력!BX11:BZ11,"<9")>=2,AVERAGEIF(응답입력!BX11:BZ11,"<9"),"") | Q10: =IF(COUNTIF(응답입력!CA11:CC11,"<9")>=2,AVERAGEIF(응답입력!CA11:CC11,"<9"),"") | R10: =IF(COUNTIF(응답입력!CD11:CF11,"<9")>=2,AVERAGEIF(응답입력!CD11:CF11,"<9"),"") | S10: =IF(COUNTIF(응답입력!CG11:CI11,"<9")>=2,AVERAGEIF(응답입력!CG11:CI11,"<9"),"") | T10: =IF(COUNTIF(응답입력!CJ11:CL11,"<9")>=2,AVERAGEIF(응답입력!CJ11:CL11,"<9"),"") | U10: =IF(COUNTIF(응답입력!CM11:CO11,"<9")>=2,AVERAGEIF(응답입력!CM11:CO11,"<9"),"") | V10: =IF(COUNTIF(응답입력!CP11:CR11,"<9")>=2,AVERAGEIF(응답입력!CP11:CR11,"<9"),"") | W10: =IF(COUNTIF(응답입력!CS11:CU11,"<9")>=2,AVERAGEIF(응답입력!CS11:CU11,"<9"),"") | X10: =IF(COUNTIF(응답입력!CV11:CX11,"<9")>=2,AVERAGEIF(응답입력!CV11:CX11,"<9"),"") | Y10: =IF(COUNTIF(응답입력!CY11:DA11,"<9")>=2,AVERAGEIF(응답입력!CY11:DA11,"<9"),"") | Z10: =IF(COUNTIF(응답입력!DB11:DD11,"<9")>=2,AVERAGEIF(응답입력!DB11:DD11,"<9"),"") | AA10: =IFERROR(AVERAGE(B10:Z10),"")
A11: =IF(응답입력!A12="","",응답입력!A12) | B11: =IF(COUNTIF(응답입력!AH12:AJ12,"<9")>=2,AVERAGEIF(응답입력!AH12:AJ12,"<9"),"") | C11: =IF(COUNTIF(응답입력!AK12:AM12,"<9")>=2,AVERAGEIF(응답입력!AK12:AM12,"<9"),"") | D11: =IF(COUNTIF(응답입력!AN12:AP12,"<9")>=2,AVERAGEIF(응답입력!AN12:AP12,"<9"),"") | E11: =IF(COUNTIF(응답입력!AQ12:AS12,"<9")>=2,AVERAGEIF(응답입력!AQ12:AS12,"<9"),"") | F11: =IF(COUNTIF(응답입력!AT12:AV12,"<9")>=2,AVERAGEIF(응답입력!AT12:AV12,"<9"),"") | G11: =IF(COUNTIF(응답입력!AW12:AY12,"<9")>=2,AVERAGEIF(응답입력!AW12:AY12,"<9"),"") | H11: =IF(COUNTIF(응답입력!AZ12:BB12,"<9")>=2,AVERAGEIF(응답입력!AZ12:BB12,"<9"),"") | I11: =IF(COUNTIF(응답입력!BC12:BE12,"<9")>=2,AVERAGEIF(응답입력!BC12:BE12,"<9"),"") | J11: =IF(COUNTIF(응답입력!BF12:BH12,"<9")>=2,AVERAGEIF(응답입력!BF12:BH12,"<9"),"") | K11: =IF(COUNTIF(응답입력!BI12:BK12,"<9")>=2,AVERAGEIF(응답입력!BI12:BK12,"<9"),"") | L11: =IF(COUNTIF(응답입력!BL12:BN12,"<9")>=2,AVERAGEIF(응답입력!BL12:BN12,"<9"),"") | M11: =IF(COUNTIF(응답입력!BO12:BQ12,"<9")>=2,AVERAGEIF(응답입력!BO12:BQ12,"<9"),"") | N11: =IF(COUNTIF(응답입력!BR12:BT12,"<9")>=2,AVERAGEIF(응답입력!BR12:BT12,"<9"),"") | O11: =IF(COUNTIF(응답입력!BU12:BW12,"<9")>=2,AVERAGEIF(응답입력!BU12:BW12,"<9"),"") | P11: =IF(COUNTIF(응답입력!BX12:BZ12,"<9")>=2,AVERAGEIF(응답입력!BX12:BZ12,"<9"),"") | Q11: =IF(COUNTIF(응답입력!CA12:CC12,"<9")>=2,AVERAGEIF(응답입력!CA12:CC12,"<9"),"") | R11: =IF(COUNTIF(응답입력!CD12:CF12,"<9")>=2,AVERAGEIF(응답입력!CD12:CF12,"<9"),"") | S11: =IF(COUNTIF(응답입력!CG12:CI12,"<9")>=2,AVERAGEIF(응답입력!CG12:CI12,"<9"),"") | T11: =IF(COUNTIF(응답입력!CJ12:CL12,"<9")>=2,AVERAGEIF(응답입력!CJ12:CL12,"<9"),"") | U11: =IF(COUNTIF(응답입력!CM12:CO12,"<9")>=2,AVERAGEIF(응답입력!CM12:CO12,"<9"),"") | V11: =IF(COUNTIF(응답입력!CP12:CR12,"<9")>=2,AVERAGEIF(응답입력!CP12:CR12,"<9"),"") | W11: =IF(COUNTIF(응답입력!CS12:CU12,"<9")>=2,AVERAGEIF(응답입력!CS12:CU12,"<9"),"") | X11: =IF(COUNTIF(응답입력!CV12:CX12,"<9")>=2,AVERAGEIF(응답입력!CV12:CX12,"<9"),"") | Y11: =IF(COUNTIF(응답입력!CY12:DA12,"<9")>=2,AVERAGEIF(응답입력!CY12:DA12,"<9"),"") | Z11: =IF(COUNTIF(응답입력!DB12:DD12,"<9")>=2,AVERAGEIF(응답입력!DB12:DD12,"<9"),"") | AA11: =IFERROR(AVERAGE(B11:Z11),"")
A12: =IF(응답입력!A13="","",응답입력!A13) | B12: =IF(COUNTIF(응답입력!AH13:AJ13,"<9")>=2,AVERAGEIF(응답입력!AH13:AJ13,"<9"),"") | C12: =IF(COUNTIF(응답입력!AK13:AM13,"<9")>=2,AVERAGEIF(응답입력!AK13:AM13,"<9"),"") | D12: =IF(COUNTIF(응답입력!AN13:AP13,"<9")>=2,AVERAGEIF(응답입력!AN13:AP13,"<9"),"") | E12: =IF(COUNTIF(응답입력!AQ13:AS13,"<9")>=2,AVERAGEIF(응답입력!AQ13:AS13,"<9"),"") | F12: =IF(COUNTIF(응답입력!AT13:AV13,"<9")>=2,AVERAGEIF(응답입력!AT13:AV13,"<9"),"") | G12: =IF(COUNTIF(응답입력!AW13:AY13,"<9")>=2,AVERAGEIF(응답입력!AW13:AY13,"<9"),"") | H12: =IF(COUNTIF(응답입력!AZ13:BB13,"<9")>=2,AVERAGEIF(응답입력!AZ13:BB13,"<9"),"") | I12: =IF(COUNTIF(응답입력!BC13:BE13,"<9")>=2,AVERAGEIF(응답입력!BC13:BE13,"<9"),"") | J12: =IF(COUNTIF(응답입력!BF13:BH13,"<9")>=2,AVERAGEIF(응답입력!BF13:BH13,"<9"),"") | K12: =IF(COUNTIF(응답입력!BI13:BK13,"<9")>=2,AVERAGEIF(응답입력!BI13:BK13,"<9"),"") | L12: =IF(COUNTIF(응답입력!BL13:BN13,"<9")>=2,AVERAGEIF(응답입력!BL13:BN13,"<9"),"") | M12: =IF(COUNTIF(응답입력!BO13:BQ13,"<9")>=2,AVERAGEIF(응답입력!BO13:BQ13,"<9"),"") | N12: =IF(COUNTIF(응답입력!BR13:BT13,"<9")>=2,AVERAGEIF(응답입력!BR13:BT13,"<9"),"") | O12: =IF(COUNTIF(응답입력!BU13:BW13,"<9")>=2,AVERAGEIF(응답입력!BU13:BW13,"<9"),"") | P12: =IF(COUNTIF(응답입력!BX13:BZ13,"<9")>=2,AVERAGEIF(응답입력!BX13:BZ13,"<9"),"") | Q12: =IF(COUNTIF(응답입력!CA13:CC13,"<9")>=2,AVERAGEIF(응답입력!CA13:CC13,"<9"),"") | R12: =IF(COUNTIF(응답입력!CD13:CF13,"<9")>=2,AVERAGEIF(응답입력!CD13:CF13,"<9"),"") | S12: =IF(COUNTIF(응답입력!CG13:CI13,"<9")>=2,AVERAGEIF(응답입력!CG13:CI13,"<9"),"") | T12: =IF(COUNTIF(응답입력!CJ13:CL13,"<9")>=2,AVERAGEIF(응답입력!CJ13:CL13,"<9"),"") | U12: =IF(COUNTIF(응답입력!CM13:CO13,"<9")>=2,AVERAGEIF(응답입력!CM13:CO13,"<9"),"") | V12: =IF(COUNTIF(응답입력!CP13:CR13,"<9")>=2,AVERAGEIF(응답입력!CP13:CR13,"<9"),"") | W12: =IF(COUNTIF(응답입력!CS13:CU13,"<9")>=2,AVERAGEIF(응답입력!CS13:CU13,"<9"),"") | X12: =IF(COUNTIF(응답입력!CV13:CX13,"<9")>=2,AVERAGEIF(응답입력!CV13:CX13,"<9"),"") | Y12: =IF(COUNTIF(응답입력!CY13:DA13,"<9")>=2,AVERAGEIF(응답입력!CY13:DA13,"<9"),"") | Z12: =IF(COUNTIF(응답입력!DB13:DD13,"<9")>=2,AVERAGEIF(응답입력!DB13:DD13,"<9"),"") | AA12: =IFERROR(AVERAGE(B12:Z12),"")
A13: =IF(응답입력!A14="","",응답입력!A14) | B13: =IF(COUNTIF(응답입력!AH14:AJ14,"<9")>=2,AVERAGEIF(응답입력!AH14:AJ14,"<9"),"") | C13: =IF(COUNTIF(응답입력!AK14:AM14,"<9")>=2,AVERAGEIF(응답입력!AK14:AM14,"<9"),"") | D13: =IF(COUNTIF(응답입력!AN14:AP14,"<9")>=2,AVERAGEIF(응답입력!AN14:AP14,"<9"),"") | E13: =IF(COUNTIF(응답입력!AQ14:AS14,"<9")>=2,AVERAGEIF(응답입력!AQ14:AS14,"<9"),"") | F13: =IF(COUNTIF(응답입력!AT14:AV14,"<9")>=2,AVERAGEIF(응답입력!AT14:AV14,"<9"),"") | G13: =IF(COUNTIF(응답입력!AW14:AY14,"<9")>=2,AVERAGEIF(응답입력!AW14:AY14,"<9"),"") | H13: =IF(COUNTIF(응답입력!AZ14:BB14,"<9")>=2,AVERAGEIF(응답입력!AZ14:BB14,"<9"),"") | I13: =IF(COUNTIF(응답입력!BC14:BE14,"<9")>=2,AVERAGEIF(응답입력!BC14:BE14,"<9"),"") | J13: =IF(COUNTIF(응답입력!BF14:BH14,"<9")>=2,AVERAGEIF(응답입력!BF14:BH14,"<9"),"") | K13: =IF(COUNTIF(응답입력!BI14:BK14,"<9")>=2,AVERAGEIF(응답입력!BI14:BK14,"<9"),"") | L13: =IF(COUNTIF(응답입력!BL14:BN14,"<9")>=2,AVERAGEIF(응답입력!BL14:BN14,"<9"),"") | M13: =IF(COUNTIF(응답입력!BO14:BQ14,"<9")>=2,AVERAGEIF(응답입력!BO14:BQ14,"<9"),"") | N13: =IF(COUNTIF(응답입력!BR14:BT14,"<9")>=2,AVERAGEIF(응답입력!BR14:BT14,"<9"),"") | O13: =IF(COUNTIF(응답입력!BU14:BW14,"<9")>=2,AVERAGEIF(응답입력!BU14:BW14,"<9"),"") | P13: =IF(COUNTIF(응답입력!BX14:BZ14,"<9")>=2,AVERAGEIF(응답입력!BX14:BZ14,"<9"),"") | Q13: =IF(COUNTIF(응답입력!CA14:CC14,"<9")>=2,AVERAGEIF(응답입력!CA14:CC14,"<9"),"") | R13: =IF(COUNTIF(응답입력!CD14:CF14,"<9")>=2,AVERAGEIF(응답입력!CD14:CF14,"<9"),"") | S13: =IF(COUNTIF(응답입력!CG14:CI14,"<9")>=2,AVERAGEIF(응답입력!CG14:CI14,"<9"),"") | T13: =IF(COUNTIF(응답입력!CJ14:CL14,"<9")>=2,AVERAGEIF(응답입력!CJ14:CL14,"<9"),"") | U13: =IF(COUNTIF(응답입력!CM14:CO14,"<9")>=2,AVERAGEIF(응답입력!CM14:CO14,"<9"),"") | V13: =IF(COUNTIF(응답입력!CP14:CR14,"<9")>=2,AVERAGEIF(응답입력!CP14:CR14,"<9"),"") | W13: =IF(COUNTIF(응답입력!CS14:CU14,"<9")>=2,AVERAGEIF(응답입력!CS14:CU14,"<9"),"") | X13: =IF(COUNTIF(응답입력!CV14:CX14,"<9")>=2,AVERAGEIF(응답입력!CV14:CX14,"<9"),"") | Y13: =IF(COUNTIF(응답입력!CY14:DA14,"<9")>=2,AVERAGEIF(응답입력!CY14:DA14,"<9"),"") | Z13: =IF(COUNTIF(응답입력!DB14:DD14,"<9")>=2,AVERAGEIF(응답입력!DB14:DD14,"<9"),"") | AA13: =IFERROR(AVERAGE(B13:Z13),"")
A14: =IF(응답입력!A15="","",응답입력!A15) | B14: =IF(COUNTIF(응답입력!AH15:AJ15,"<9")>=2,AVERAGEIF(응답입력!AH15:AJ15,"<9"),"") | C14: =IF(COUNTIF(응답입력!AK15:AM15,"<9")>=2,AVERAGEIF(응답입력!AK15:AM15,"<9"),"") | D14: =IF(COUNTIF(응답입력!AN15:AP15,"<9")>=2,AVERAGEIF(응답입력!AN15:AP15,"<9"),"") | E14: =IF(COUNTIF(응답입력!AQ15:AS15,"<9")>=2,AVERAGEIF(응답입력!AQ15:AS15,"<9"),"") | F14: =IF(COUNTIF(응답입력!AT15:AV15,"<9")>=2,AVERAGEIF(응답입력!AT15:AV15,"<9"),"") | G14: =IF(COUNTIF(응답입력!AW15:AY15,"<9")>=2,AVERAGEIF(응답입력!AW15:AY15,"<9"),"") | H14: =IF(COUNTIF(응답입력!AZ15:BB15,"<9")>=2,AVERAGEIF(응답입력!AZ15:BB15,"<9"),"") | I14: =IF(COUNTIF(응답입력!BC15:BE15,"<9")>=2,AVERAGEIF(응답입력!BC15:BE15,"<9"),"") | J14: =IF(COUNTIF(응답입력!BF15:BH15,"<9")>=2,AVERAGEIF(응답입력!BF15:BH15,"<9"),"") | K14: =IF(COUNTIF(응답입력!BI15:BK15,"<9")>=2,AVERAGEIF(응답입력!BI15:BK15,"<9"),"") | L14: =IF(COUNTIF(응답입력!BL15:BN15,"<9")>=2,AVERAGEIF(응답입력!BL15:BN15,"<9"),"") | M14: =IF(COUNTIF(응답입력!BO15:BQ15,"<9")>=2,AVERAGEIF(응답입력!BO15:BQ15,"<9"),"") | N14: =IF(COUNTIF(응답입력!BR15:BT15,"<9")>=2,AVERAGEIF(응답입력!BR15:BT15,"<9"),"") | O14: =IF(COUNTIF(응답입력!BU15:BW15,"<9")>=2,AVERAGEIF(응답입력!BU15:BW15,"<9"),"") | P14: =IF(COUNTIF(응답입력!BX15:BZ15,"<9")>=2,AVERAGEIF(응답입력!BX15:BZ15,"<9"),"") | Q14: =IF(COUNTIF(응답입력!CA15:CC15,"<9")>=2,AVERAGEIF(응답입력!CA15:CC15,"<9"),"") | R14: =IF(COUNTIF(응답입력!CD15:CF15,"<9")>=2,AVERAGEIF(응답입력!CD15:CF15,"<9"),"") | S14: =IF(COUNTIF(응답입력!CG15:CI15,"<9")>=2,AVERAGEIF(응답입력!CG15:CI15,"<9"),"") | T14: =IF(COUNTIF(응답입력!CJ15:CL15,"<9")>=2,AVERAGEIF(응답입력!CJ15:CL15,"<9"),"") | U14: =IF(COUNTIF(응답입력!CM15:CO15,"<9")>=2,AVERAGEIF(응답입력!CM15:CO15,"<9"),"") | V14: =IF(COUNTIF(응답입력!CP15:CR15,"<9")>=2,AVERAGEIF(응답입력!CP15:CR15,"<9"),"") | W14: =IF(COUNTIF(응답입력!CS15:CU15,"<9")>=2,AVERAGEIF(응답입력!CS15:CU15,"<9"),"") | X14: =IF(COUNTIF(응답입력!CV15:CX15,"<9")>=2,AVERAGEIF(응답입력!CV15:CX15,"<9"),"") | Y14: =IF(COUNTIF(응답입력!CY15:DA15,"<9")>=2,AVERAGEIF(응답입력!CY15:DA15,"<9"),"") | Z14: =IF(COUNTIF(응답입력!DB15:DD15,"<9")>=2,AVERAGEIF(응답입력!DB15:DD15,"<9"),"") | AA14: =IFERROR(AVERAGE(B14:Z14),"")
A15: =IF(응답입력!A16="","",응답입력!A16) | B15: =IF(COUNTIF(응답입력!AH16:AJ16,"<9")>=2,AVERAGEIF(응답입력!AH16:AJ16,"<9"),"") | C15: =IF(COUNTIF(응답입력!AK16:AM16,"<9")>=2,AVERAGEIF(응답입력!AK16:AM16,"<9"),"") | D15: =IF(COUNTIF(응답입력!AN16:AP16,"<9")>=2,AVERAGEIF(응답입력!AN16:AP16,"<9"),"") | E15: =IF(COUNTIF(응답입력!AQ16:AS16,"<9")>=2,AVERAGEIF(응답입력!AQ16:AS16,"<9"),"") | F15: =IF(COUNTIF(응답입력!AT16:AV16,"<9")>=2,AVERAGEIF(응답입력!AT16:AV16,"<9"),"") | G15: =IF(COUNTIF(응답입력!AW16:AY16,"<9")>=2,AVERAGEIF(응답입력!AW16:AY16,"<9"),"") | H15: =IF(COUNTIF(응답입력!AZ16:BB16,"<9")>=2,AVERAGEIF(응답입력!AZ16:BB16,"<9"),"") | I15: =IF(COUNTIF(응답입력!BC16:BE16,"<9")>=2,AVERAGEIF(응답입력!BC16:BE16,"<9"),"") | J15: =IF(COUNTIF(응답입력!BF16:BH16,"<9")>=2,AVERAGEIF(응답입력!BF16:BH16,"<9"),"") | K15: =IF(COUNTIF(응답입력!BI16:BK16,"<9")>=2,AVERAGEIF(응답입력!BI16:BK16,"<9"),"") | L15: =IF(COUNTIF(응답입력!BL16:BN16,"<9")>=2,AVERAGEIF(응답입력!BL16:BN16,"<9"),"") | M15: =IF(COUNTIF(응답입력!BO16:BQ16,"<9")>=2,AVERAGEIF(응답입력!BO16:BQ16,"<9"),"") | N15: =IF(COUNTIF(응답입력!BR16:BT16,"<9")>=2,AVERAGEIF(응답입력!BR16:BT16,"<9"),"") | O15: =IF(COUNTIF(응답입력!BU16:BW16,"<9")>=2,AVERAGEIF(응답입력!BU16:BW16,"<9"),"") | P15: =IF(COUNTIF(응답입력!BX16:BZ16,"<9")>=2,AVERAGEIF(응답입력!BX16:BZ16,"<9"),"") | Q15: =IF(COUNTIF(응답입력!CA16:CC16,"<9")>=2,AVERAGEIF(응답입력!CA16:CC16,"<9"),"") | R15: =IF(COUNTIF(응답입력!CD16:CF16,"<9")>=2,AVERAGEIF(응답입력!CD16:CF16,"<9"),"") | S15: =IF(COUNTIF(응답입력!CG16:CI16,"<9")>=2,AVERAGEIF(응답입력!CG16:CI16,"<9"),"") | T15: =IF(COUNTIF(응답입력!CJ16:CL16,"<9")>=2,AVERAGEIF(응답입력!CJ16:CL16,"<9"),"") | U15: =IF(COUNTIF(응답입력!CM16:CO16,"<9")>=2,AVERAGEIF(응답입력!CM16:CO16,"<9"),"") | V15: =IF(COUNTIF(응답입력!CP16:CR16,"<9")>=2,AVERAGEIF(응답입력!CP16:CR16,"<9"),"") | W15: =IF(COUNTIF(응답입력!CS16:CU16,"<9")>=2,AVERAGEIF(응답입력!CS16:CU16,"<9"),"") | X15: =IF(COUNTIF(응답입력!CV16:CX16,"<9")>=2,AVERAGEIF(응답입력!CV16:CX16,"<9"),"") | Y15: =IF(COUNTIF(응답입력!CY16:DA16,"<9")>=2,AVERAGEIF(응답입력!CY16:DA16,"<9"),"") | Z15: =IF(COUNTIF(응답입력!DB16:DD16,"<9")>=2,AVERAGEIF(응답입력!DB16:DD16,"<9"),"") | AA15: =IFERROR(AVERAGE(B15:Z15),"")
A16: =IF(응답입력!A17="","",응답입력!A17) | B16: =IF(COUNTIF(응답입력!AH17:AJ17,"<9")>=2,AVERAGEIF(응답입력!AH17:AJ17,"<9"),"") | C16: =IF(COUNTIF(응답입력!AK17:AM17,"<9")>=2,AVERAGEIF(응답입력!AK17:AM17,"<9"),"") | D16: =IF(COUNTIF(응답입력!AN17:AP17,"<9")>=2,AVERAGEIF(응답입력!AN17:AP17,"<9"),"") | E16: =IF(COUNTIF(응답입력!AQ17:AS17,"<9")>=2,AVERAGEIF(응답입력!AQ17:AS17,"<9"),"") | F16: =IF(COUNTIF(응답입력!AT17:AV17,"<9")>=2,AVERAGEIF(응답입력!AT17:AV17,"<9"),"") | G16: =IF(COUNTIF(응답입력!AW17:AY17,"<9")>=2,AVERAGEIF(응답입력!AW17:AY17,"<9"),"") | H16: =IF(COUNTIF(응답입력!AZ17:BB17,"<9")>=2,AVERAGEIF(응답입력!AZ17:BB17,"<9"),"") | I16: =IF(COUNTIF(응답입력!BC17:BE17,"<9")>=2,AVERAGEIF(응답입력!BC17:BE17,"<9"),"") | J16: =IF(COUNTIF(응답입력!BF17:BH17,"<9")>=2,AVERAGEIF(응답입력!BF17:BH17,"<9"),"") | K16: =IF(COUNTIF(응답입력!BI17:BK17,"<9")>=2,AVERAGEIF(응답입력!BI17:BK17,"<9"),"") | L16: =IF(COUNTIF(응답입력!BL17:BN17,"<9")>=2,AVERAGEIF(응답입력!BL17:BN17,"<9"),"") | M16: =IF(COUNTIF(응답입력!BO17:BQ17,"<9")>=2,AVERAGEIF(응답입력!BO17:BQ17,"<9"),"") | N16: =IF(COUNTIF(응답입력!BR17:BT17,"<9")>=2,AVERAGEIF(응답입력!BR17:BT17,"<9"),"") | O16: =IF(COUNTIF(응답입력!BU17:BW17,"<9")>=2,AVERAGEIF(응답입력!BU17:BW17,"<9"),"") | P16: =IF(COUNTIF(응답입력!BX17:BZ17,"<9")>=2,AVERAGEIF(응답입력!BX17:BZ17,"<9"),"") | Q16: =IF(COUNTIF(응답입력!CA17:CC17,"<9")>=2,AVERAGEIF(응답입력!CA17:CC17,"<9"),"") | R16: =IF(COUNTIF(응답입력!CD17:CF17,"<9")>=2,AVERAGEIF(응답입력!CD17:CF17,"<9"),"") | S16: =IF(COUNTIF(응답입력!CG17:CI17,"<9")>=2,AVERAGEIF(응답입력!CG17:CI17,"<9"),"") | T16: =IF(COUNTIF(응답입력!CJ17:CL17,"<9")>=2,AVERAGEIF(응답입력!CJ17:CL17,"<9"),"") | U16: =IF(COUNTIF(응답입력!CM17:CO17,"<9")>=2,AVERAGEIF(응답입력!CM17:CO17,"<9"),"") | V16: =IF(COUNTIF(응답입력!CP17:CR17,"<9")>=2,AVERAGEIF(응답입력!CP17:CR17,"<9"),"") | W16: =IF(COUNTIF(응답입력!CS17:CU17,"<9")>=2,AVERAGEIF(응답입력!CS17:CU17,"<9"),"") | X16: =IF(COUNTIF(응답입력!CV17:CX17,"<9")>=2,AVERAGEIF(응답입력!CV17:CX17,"<9"),"") | Y16: =IF(COUNTIF(응답입력!CY17:DA17,"<9")>=2,AVERAGEIF(응답입력!CY17:DA17,"<9"),"") | Z16: =IF(COUNTIF(응답입력!DB17:DD17,"<9")>=2,AVERAGEIF(응답입력!DB17:DD17,"<9"),"") | AA16: =IFERROR(AVERAGE(B16:Z16),"")
A17: =IF(응답입력!A18="","",응답입력!A18) | B17: =IF(COUNTIF(응답입력!AH18:AJ18,"<9")>=2,AVERAGEIF(응답입력!AH18:AJ18,"<9"),"") | C17: =IF(COUNTIF(응답입력!AK18:AM18,"<9")>=2,AVERAGEIF(응답입력!AK18:AM18,"<9"),"") | D17: =IF(COUNTIF(응답입력!AN18:AP18,"<9")>=2,AVERAGEIF(응답입력!AN18:AP18,"<9"),"") | E17: =IF(COUNTIF(응답입력!AQ18:AS18,"<9")>=2,AVERAGEIF(응답입력!AQ18:AS18,"<9"),"") | F17: =IF(COUNTIF(응답입력!AT18:AV18,"<9")>=2,AVERAGEIF(응답입력!AT18:AV18,"<9"),"") | G17: =IF(COUNTIF(응답입력!AW18:AY18,"<9")>=2,AVERAGEIF(응답입력!AW18:AY18,"<9"),"") | H17: =IF(COUNTIF(응답입력!AZ18:BB18,"<9")>=2,AVERAGEIF(응답입력!AZ18:BB18,"<9"),"") | I17: =IF(COUNTIF(응답입력!BC18:BE18,"<9")>=2,AVERAGEIF(응답입력!BC18:BE18,"<9"),"") | J17: =IF(COUNTIF(응답입력!BF18:BH18,"<9")>=2,AVERAGEIF(응답입력!BF18:BH18,"<9"),"") | K17: =IF(COUNTIF(응답입력!BI18:BK18,"<9")>=2,AVERAGEIF(응답입력!BI18:BK18,"<9"),"") | L17: =IF(COUNTIF(응답입력!BL18:BN18,"<9")>=2,AVERAGEIF(응답입력!BL18:BN18,"<9"),"") | M17: =IF(COUNTIF(응답입력!BO18:BQ18,"<9")>=2,AVERAGEIF(응답입력!BO18:BQ18,"<9"),"") | N17: =IF(COUNTIF(응답입력!BR18:BT18,"<9")>=2,AVERAGEIF(응답입력!BR18:BT18,"<9"),"") | O17: =IF(COUNTIF(응답입력!BU18:BW18,"<9")>=2,AVERAGEIF(응답입력!BU18:BW18,"<9"),"") | P17: =IF(COUNTIF(응답입력!BX18:BZ18,"<9")>=2,AVERAGEIF(응답입력!BX18:BZ18,"<9"),"") | Q17: =IF(COUNTIF(응답입력!CA18:CC18,"<9")>=2,AVERAGEIF(응답입력!CA18:CC18,"<9"),"") | R17: =IF(COUNTIF(응답입력!CD18:CF18,"<9")>=2,AVERAGEIF(응답입력!CD18:CF18,"<9"),"") | S17: =IF(COUNTIF(응답입력!CG18:CI18,"<9")>=2,AVERAGEIF(응답입력!CG18:CI18,"<9"),"") | T17: =IF(COUNTIF(응답입력!CJ18:CL18,"<9")>=2,AVERAGEIF(응답입력!CJ18:CL18,"<9"),"") | U17: =IF(COUNTIF(응답입력!CM18:CO18,"<9")>=2,AVERAGEIF(응답입력!CM18:CO18,"<9"),"") | V17: =IF(COUNTIF(응답입력!CP18:CR18,"<9")>=2,AVERAGEIF(응답입력!CP18:CR18,"<9"),"") | W17: =IF(COUNTIF(응답입력!CS18:CU18,"<9")>=2,AVERAGEIF(응답입력!CS18:CU18,"<9"),"") | X17: =IF(COUNTIF(응답입력!CV18:CX18,"<9")>=2,AVERAGEIF(응답입력!CV18:CX18,"<9"),"") | Y17: =IF(COUNTIF(응답입력!CY18:DA18,"<9")>=2,AVERAGEIF(응답입력!CY18:DA18,"<9"),"") | Z17: =IF(COUNTIF(응답입력!DB18:DD18,"<9")>=2,AVERAGEIF(응답입력!DB18:DD18,"<9"),"") | AA17: =IFERROR(AVERAGE(B17:Z17),"")
... A55: =IF(응답입력!A56="","",응답입력!A56) | B55: =IF(COUNTIF(응답입력!AH56:AJ56,"<9")>=2,AVERAGEIF(응답입력!AH56:AJ56,"<9"),"") | C55: =IF(COUNTIF(응답입력!AK56:AM56,"<9")>=2,AVERAGEIF(응답입력!AK56:AM56,"<9"),"") | D55: =IF(COUNTIF(응답입력!AN56:AP56,"<9")>=2,AVERAGEIF(응답입력!AN56:AP56,"<9"),"") | E55: =IF(COUNTIF(응답입력!AQ56:AS56,"<9")>=2,AVERAGEIF(응답입력!AQ56:AS56,"<9"),"") | F55: =IF(COUNTIF(응답입력!AT56:AV56,"<9")>=2,AVERAGEIF(응답입력!AT56:AV56,"<9"),"") | G55: =IF(COUNTIF(응답입력!AW56:AY56,"<9")>=2,AVERAGEIF(응답입력!AW56:AY56,"<9"),"") | H55: =IF(COUNTIF(응답입력!AZ56:BB56,"<9")>=2,AVERAGEIF(응답입력!AZ56:BB56,"<9"),"") | I55: =IF(COUNTIF(응답입력!BC56:BE56,"<9")>=2,AVERAGEIF(응답입력!BC56:BE56,"<9"),"") | J55: =IF(COUNTIF(응답입력!BF56:BH56,"<9")>=2,AVERAGEIF(응답입력!BF56:BH56,"<9"),"") | K55: =IF(COUNTIF(응답입력!BI56:BK56,"<9")>=2,AVERAGEIF(응답입력!BI56:BK56,"<9"),"") | L55: =IF(COUNTIF(응답입력!BL56:BN56,"<9")>=2,AVERAGEIF(응답입력!BL56:BN56,"<9"),"") | M55: =IF(COUNTIF(응답입력!BO56:BQ56,"<9")>=2,AVERAGEIF(응답입력!BO56:BQ56,"<9"),"") | N55: =IF(COUNTIF(응답입력!BR56:BT56,"<9")>=2,AVERAGEIF(응답입력!BR56:BT56,"<9"),"") | O55: =IF(COUNTIF(응답입력!BU56:BW56,"<9")>=2,AVERAGEIF(응답입력!BU56:BW56,"<9"),"") | P55: =IF(COUNTIF(응답입력!BX56:BZ56,"<9")>=2,AVERAGEIF(응답입력!BX56:BZ56,"<9"),"") | Q55: =IF(COUNTIF(응답입력!CA56:CC56,"<9")>=2,AVERAGEIF(응답입력!CA56:CC56,"<9"),"") | R55: =IF(COUNTIF(응답입력!CD56:CF56,"<9")>=2,AVERAGEIF(응답입력!CD56:CF56,"<9"),"") | S55: =IF(COUNTIF(응답입력!CG56:CI56,"<9")>=2,AVERAGEIF(응답입력!CG56:CI56,"<9"),"") | T55: =IF(COUNTIF(응답입력!CJ56:CL56,"<9")>=2,AVERAGEIF(응답입력!CJ56:CL56,"<9"),"") | U55: =IF(COUNTIF(응답입력!CM56:CO56,"<9")>=2,AVERAGEIF(응답입력!CM56:CO56,"<9"),"") | V55: =IF(COUNTIF(응답입력!CP56:CR56,"<9")>=2,AVERAGEIF(응답입력!CP56:CR56,"<9"),"") | W55: =IF(COUNTIF(응답입력!CS56:CU56,"<9")>=2,AVERAGEIF(응답입력!CS56:CU56,"<9"),"") | X55: =IF(COUNTIF(응답입력!CV56:CX56,"<9")>=2,AVERAGEIF(응답입력!CV56:CX56,"<9"),"") | Y55: =IF(COUNTIF(응답입력!CY56:DA56,"<9")>=2,AVERAGEIF(응답입력!CY56:DA56,"<9"),"") | Z55: =IF(COUNTIF(응답입력!DB56:DD56,"<9")>=2,AVERAGEIF(응답입력!DB56:DD56,"<9"),"") | AA55: =IFERROR(AVERAGE(B55:Z55),"")

Sheet 점수요약
A1: 점수 요약 — 연결·영역·상태별 평균 (응답입력 7~56행, 9 제외)
A4: ID | B4: 연결 (A→B) | C4: 영역 | D4: 반영(R) 평균 | E4: 확인(V) 평균 | F4: 갱신(U) 평균 | G4: 연결 점수 | H4: 응답 수 | I4: R−U 격차 | J4: 해석
A5: L01 | B5: REQ → BIA | C5: ① 요구·분석 | D5: =IFERROR(AVERAGEIF(응답입력!$AH$7:$AH$56,"<9"),"") | E5: =IFERROR(AVERAGEIF(응답입력!$AI$7:$AI$56,"<9"),"") | F5: =IFERROR(AVERAGEIF(응답입력!$AJ$7:$AJ$56,"<9"),"") | G5: =IFERROR(AVERAGE(D5:F5),"") | H5: =COUNTIF(응답입력!$AH$7:$AH$56,"<9")+COUNTIF(응답입력!$AI$7:$AI$56,"<9")+COUNTIF(응답입력!$AJ$7:$AJ$56,"<9") -> 0 | I5: =IF(AND(ISNUMBER(D5),ISNUMBER(F5)),D5-F5,"") | J5: =IF(I5="","",IF(I5>=1,"방치 의심(반영≫갱신)",IF(I5<=-0.5,"점검 필요(갱신>반영)","균형")))
A6: L02 | B6: REQ → RA | C6: ① 요구·분석 | D6: =IFERROR(AVERAGEIF(응답입력!$AK$7:$AK$56,"<9"),"") | E6: =IFERROR(AVERAGEIF(응답입력!$AL$7:$AL$56,"<9"),"") | F6: =IFERROR(AVERAGEIF(응답입력!$AM$7:$AM$56,"<9"),"") | G6: =IFERROR(AVERAGE(D6:F6),"") | H6: =COUNTIF(응답입력!$AK$7:$AK$56,"<9")+COUNTIF(응답입력!$AL$7:$AL$56,"<9")+COUNTIF(응답입력!$AM$7:$AM$56,"<9") -> 0 | I6: =IF(AND(ISNUMBER(D6),ISNUMBER(F6)),D6-F6,"") | J6: =IF(I6="","",IF(I6>=1,"방치 의심(반영≫갱신)",IF(I6<=-0.5,"점검 필요(갱신>반영)","균형")))
A7: L03 | B7: BIA → RA | C7: ① 요구·분석 | D7: =IFERROR(AVERAGEIF(응답입력!$AN$7:$AN$56,"<9"),"") | E7: =IFERROR(AVERAGEIF(응답입력!$AO$7:$AO$56,"<9"),"") | F7: =IFERROR(AVERAGEIF(응답입력!$AP$7:$AP$56,"<9"),"") | G7: =IFERROR(AVERAGE(D7:F7),"") | H7: =COUNTIF(응답입력!$AN$7:$AN$56,"<9")+COUNTIF(응답입력!$AO$7:$AO$56,"<9")+COUNTIF(응답입력!$AP$7:$AP$56,"<9") -> 0 | I7: =IF(AND(ISNUMBER(D7),ISNUMBER(F7)),D7-F7,"") | J7: =IF(I7="","",IF(I7>=1,"방치 의심(반영≫갱신)",IF(I7<=-0.5,"점검 필요(갱신>반영)","균형")))
A8: L04 | B8: REQ → AUD | C8: ① 요구·분석 | D8: =IFERROR(AVERAGEIF(응답입력!$AQ$7:$AQ$56,"<9"),"") | E8: =IFERROR(AVERAGEIF(응답입력!$AR$7:$AR$56,"<9"),"") | F8: =IFERROR(AVERAGEIF(응답입력!$AS$7:$AS$56,"<9"),"") | G8: =IFERROR(AVERAGE(D8:F8),"") | H8: =COUNTIF(응답입력!$AQ$7:$AQ$56,"<9")+COUNTIF(응답입력!$AR$7:$AR$56,"<9")+COUNTIF(응답입력!$AS$7:$AS$56,"<9") -> 0 | I8: =IF(AND(ISNUMBER(D8),ISNUMBER(F8)),D8-F8,"") | J8: =IF(I8="","",IF(I8>=1,"방치 의심(반영≫갱신)",IF(I8<=-0.5,"점검 필요(갱신>반영)","균형")))
A9: L05 | B9: REQ → SUP | C9: ① 요구·분석 | D9: =IFERROR(AVERAGEIF(응답입력!$AT$7:$AT$56,"<9"),"") | E9: =IFERROR(AVERAGEIF(응답입력!$AU$7:$AU$56,"<9"),"") | F9: =IFERROR(AVERAGEIF(응답입력!$AV$7:$AV$56,"<9"),"") | G9: =IFERROR(AVERAGE(D9:F9),"") | H9: =COUNTIF(응답입력!$AT$7:$AT$56,"<9")+COUNTIF(응답입력!$AU$7:$AU$56,"<9")+COUNTIF(응답입력!$AV$7:$AV$56,"<9") -> 0 | I9: =IF(AND(ISNUMBER(D9),ISNUMBER(F9)),D9-F9,"") | J9: =IF(I9="","",IF(I9>=1,"방치 의심(반영≫갱신)",IF(I9<=-0.5,"점검 필요(갱신>반영)","균형")))
A10: L06 | B10: BIA → STR | C10: ② 전략·계획·이행 | D10: =IFERROR(AVERAGEIF(응답입력!$AW$7:$AW$56,"<9"),"") | E10: =IFERROR(AVERAGEIF(응답입력!$AX$7:$AX$56,"<9"),"") | F10: =IFERROR(AVERAGEIF(응답입력!$AY$7:$AY$56,"<9"),"") | G10: =IFERROR(AVERAGE(D10:F10),"") | H10: =COUNTIF(응답입력!$AW$7:$AW$56,"<9")+COUNTIF(응답입력!$AX$7:$AX$56,"<9")+COUNTIF(응답입력!$AY$7:$AY$56,"<9") -> 0 | I10: =IF(AND(ISNUMBER(D10),ISNUMBER(F10)),D10-F10,"") | J10: =IF(I10="","",IF(I10>=1,"방치 의심(반영≫갱신)",IF(I10<=-0.5,"점검 필요(갱신>반영)","균형")))
A11: L07 | B11: STR → IMP | C11: ② 전략·계획·이행 | D11: =IFERROR(AVERAGEIF(응답입력!$AZ$7:$AZ$56,"<9"),"") | E11: =IFERROR(AVERAGEIF(응답입력!$BA$7:$BA$56,"<9"),"") | F11: =IFERROR(AVERAGEIF(응답입력!$BB$7:$BB$56,"<9"),"") | G11: =IFERROR(AVERAGE(D11:F11),"") | H11: =COUNTIF(응답입력!$AZ$7:$AZ$56,"<9")+COUNTIF(응답입력!$BA$7:$BA$56,"<9")+COUNTIF(응답입력!$BB$7:$BB$56,"<9") -> 0 | I11: =IF(AND(ISNUMBER(D11),ISNUMBER(F11)),D11-F11,"") | J11: =IF(I11="","",IF(I11>=1,"방치 의심(반영≫갱신)",IF(I11<=-0.5,"점검 필요(갱신>반영)","균형")))
A12: L08 | B12: STR → PLAN | C12: ② 전략·계획·이행 | D12: =IFERROR(AVERAGEIF(응답입력!$BC$7:$BC$56,"<9"),"") | E12: =IFERROR(AVERAGEIF(응답입력!$BD$7:$BD$56,"<9"),"") | F12: =IFERROR(AVERAGEIF(응답입력!$BE$7:$BE$56,"<9"),"") | G12: =IFERROR(AVERAGE(D12:F12),"") | H12: =COUNTIF(응답입력!$BC$7:$BC$56,"<9")+COUNTIF(응답입력!$BD$7:$BD$56,"<9")+COUNTIF(응답입력!$BE$7:$BE$56,"<9") -> 0 | I12: =IF(AND(ISNUMBER(D12),ISNUMBER(F12)),D12-F12,"") | J12: =IF(I12="","",IF(I12>=1,"방치 의심(반영≫갱신)",IF(I12<=-0.5,"점검 필요(갱신>반영)","균형")))
A13: L09 | B13: RA → PLAN | C13: ② 전략·계획·이행 | D13: =IFERROR(AVERAGEIF(응답입력!$BF$7:$BF$56,"<9"),"") | E13: =IFERROR(AVERAGEIF(응답입력!$BG$7:$BG$56,"<9"),"") | F13: =IFERROR(AVERAGEIF(응답입력!$BH$7:$BH$56,"<9"),"") | G13: =IFERROR(AVERAGE(D13:F13),"") | H13: =COUNTIF(응답입력!$BF$7:$BF$56,"<9")+COUNTIF(응답입력!$BG$7:$BG$56,"<9")+COUNTIF(응답입력!$BH$7:$BH$56,"<9") -> 0 | I13: =IF(AND(ISNUMBER(D13),ISNUMBER(F13)),D13-F13,"") | J13: =IF(I13="","",IF(I13>=1,"방치 의심(반영≫갱신)",IF(I13<=-0.5,"점검 필요(갱신>반영)","균형")))
A14: L10 | B14: BIA → RES | C14: ② 전략·계획·이행 | D14: =IFERROR(AVERAGEIF(응답입력!$BI$7:$BI$56,"<9"),"") | E14: =IFERROR(AVERAGEIF(응답입력!$BJ$7:$BJ$56,"<9"),"") | F14: =IFERROR(AVERAGEIF(응답입력!$BK$7:$BK$56,"<9"),"") | G14: =IFERROR(AVERAGE(D14:F14),"") | H14: =COUNTIF(응답입력!$BI$7:$BI$56,"<9")+COUNTIF(응답입력!$BJ$7:$BJ$56,"<9")+COUNTIF(응답입력!$BK$7:$BK$56,"<9") -> 0 | I14: =IF(AND(ISNUMBER(D14),ISNUMBER(F14)),D14-F14,"") | J14: =IF(I14="","",IF(I14>=1,"방치 의심(반영≫갱신)",IF(I14<=-0.5,"점검 필요(갱신>반영)","균형")))
A15: L11 | B15: PLAN ↔ INC | C15: ③ 대응·복구·훈련 | D15: =IFERROR(AVERAGEIF(응답입력!$BL$7:$BL$56,"<9"),"") | E15: =IFERROR(AVERAGEIF(응답입력!$BM$7:$BM$56,"<9"),"") | F15: =IFERROR(AVERAGEIF(응답입력!$BN$7:$BN$56,"<9"),"") | G15: =IFERROR(AVERAGE(D15:F15),"") | H15: =COUNTIF(응답입력!$BL$7:$BL$56,"<9")+COUNTIF(응답입력!$BM$7:$BM$56,"<9")+COUNTIF(응답입력!$BN$7:$BN$56,"<9") -> 0 | I15: =IF(AND(ISNUMBER(D15),ISNUMBER(F15)),D15-F15,"") | J15: =IF(I15="","",IF(I15>=1,"방치 의심(반영≫갱신)",IF(I15<=-0.5,"점검 필요(갱신>반영)","균형")))
A16: L12 | B16: INC → WARN | C16: ③ 대응·복구·훈련 | D16: =IFERROR(AVERAGEIF(응답입력!$BO$7:$BO$56,"<9"),"") | E16: =IFERROR(AVERAGEIF(응답입력!$BP$7:$BP$56,"<9"),"") | F16: =IFERROR(AVERAGEIF(응답입력!$BQ$7:$BQ$56,"<9"),"") | G16: =IFERROR(AVERAGE(D16:F16),"") | H16: =COUNTIF(응답입력!$BO$7:$BO$56,"<9")+COUNTIF(응답입력!$BP$7:$BP$56,"<9")+COUNTIF(응답입력!$BQ$7:$BQ$56,"<9") -> 0 | I16: =IF(AND(ISNUMBER(D16),ISNUMBER(F16)),D16-F16,"") | J16: =IF(I16="","",IF(I16>=1,"방치 의심(반영≫갱신)",IF(I16<=-0.5,"점검 필요(갱신>반영)","균형")))
